Workbook
Name CASE: [1]코드!$K$35:$K$41
Name DBMS: [1]코드!$G$35:$G$49
Name EndUser: [1]코드!$D$35:$D$39
Name HW: [1]코드!$I$35:$I$59
Name Language: [1]코드!$J$35:$J$61
Name LType: [1]코드!$M$35:$M$37
Name MW: [1]코드!$H$35:$H$49
Name OS: [1]코드!$F$35:$F$42
Name Platform: [1]코드!$L$35:$L$37
Name 개발형태: [1]코드!$C$2:$C$7
Name 계약방식: [1]코드!$A$2:$A$10
Name 계약형태: [1]코드!$H$2:$H$4
Name 낙찰구분: [1]코드!$B$2:$B$5
Name 방법론: [1]코드!$E$35:$E$51
Name 사업부: [1]코드!$J$2:$J$7
Name 서비스영역: [1]코드!$K$2:$K$13
Name 업종: [1]코드!$D$2:$D$9
Name 업종상세: [1]코드!$E$2:$E$32
Name 적용사이트: [1]코드!$C$35:$C$38
Name 전략프로젝트: [1]코드!$G$2:$G$3
Name 표1: #REF!
Name 표1: #REF!
Name 표1: #REF!
Name 표1: #REF!
Name 표1: #REF!
Name 표2: #REF!
Name 표2: #REF!
Name 표2: #REF!
Name 표2: #REF!
Name 표2: #REF!
Name 프로덕트유형: [1]코드!$B$35:$B$39
Name 프로덕트타입: [1]코드!$A$35:$A$49
Name 프로젝트단계: [1]코드!$F$2:$F$7

Sheet 표지
B25: 프로젝트 | D25: ABC-MART 온라인 쇼핑몰 2.0 구축
B26: 작성자 | D26: 박지숙 | F26: 작성일 | H26: 43629
B27: 승인자 | F27: 승인일

Sheet 개정이력
A6: 제.개정 이력
A8: 버전 | B8: 제.개정일자 | C8: 제.개정내용 | G8: 작성자
A9: 0.1 | B9: 43606 | C9: 초안 작성 | G9: 조영진
A10: 0.2 | B10: 43620 | C10: 1차 검토사항 보완/수정 | G10: 박지숙
A11: 0.3 | B11: 43621 | C11: 2차 검토사항 보완/수정 | G11: 조영진
A12: 0.4 | B12: 43623 | C12: 3차 검토사항 보완/수정, AS 시나리오 추가 작성 | G12: 박지숙
A13: 0.5 | B13: 43626 | C13: 4차 검토사항 보완/수정 | G13: 조영진
A14: 0.6 | B14: 43627 | C14: 5차 검토사항 보완/수정, 테스트Data 추가 작성 | G14: 박지숙
A15: 0.7 | B15: 43628 | C15: 6차 검토사항 보완/수정, AS 시나리오 추가 | G15: 조영진
A16: 0.71 | B16: 43629 | C16: 인수인계용 버전 Release | G16: 조영진

Sheet 헤더
A1: 통합테스트 시나리오 및 결과서
B2: 프로젝트 | C2: ABC-MART 온라인 쇼핑몰 2.0 구축 | E2: 단계 | F2: 테스트
B3: 작성자 | C3: 박지숙 | E3: 작성일 | F3: 43629
A5: 통합테스트 시나리오 및 결과서
B6: 프로젝트 | C6: ABC-MART 온라인 쇼핑몰 2.0 구축 | E6: 단계 | F6: 테스트
B7: 작성자 | C7: 조영진 | E7: 작성일 | F7: 43629

Sheet 결과
B3: ... Sheet
B5: SYS | C5: 시나리오 수 | D5: Pass | E5: Fail | F5: Block | G5: N/A | H5: Total | I5: 진척율 | J5: 수행율 | K5: 성공율 | L5: 결함율 | M5: 수행불가율
B6: PO | H6: =SUM(표3_5[[#This Row],[Pass]:[N/A]]) -> 0 | I6: =IFERROR(표3_5[[#This Row],[Total]]/표3_5[[#This Row],[시나리오 수]],0) -> 0 | J6: =IFERROR(SUM(표3_5[[#This Row],[Pass]:[Fail]])/표3_5[[#This Row],[시나리오 수]],0) -> 0 | K6: =IFERROR(표3_5[[#This Row],[Pass]]/SUM(표3_5[[#This Row],[Pass]:[Fail]]),0) -> 0 | L6: =IFERROR((표3_5[[#This Row],[Fail]]/SUM(표3_5[[#This Row],[Pass]:[Fail]])),0) -> 0 | M6: =IFERROR((표3_5[[#This Row],[N/A]]/표3_5[[#This Row],[시나리오 수]]),0) -> 0
B7: MO | H7: =SUM(표3_5[[#This Row],[Pass]:[N/A]]) -> 0 | I7: =IFERROR(표3_5[[#This Row],[Total]]/표3_5[[#This Row],[시나리오 수]],0) -> 0 | J7: =IFERROR(SUM(표3_5[[#This Row],[Pass]:[Fail]])/표3_5[[#This Row],[시나리오 수]],0) -> 0 | K7: =IFERROR(표3_5[[#This Row],[Pass]]/SUM(표3_5[[#This Row],[Pass]:[Fail]]),0) -> 0 | L7: =IFERROR((표3_5[[#This Row],[Fail]]/SUM(표3_5[[#This Row],[Pass]:[Fail]])),0) -> 0 | M7: =IFERROR((표3_5[[#This Row],[N/A]]/표3_5[[#This Row],[시나리오 수]]),0) -> 0
B8: BO | H8: =SUM(표3_5[[#This Row],[Pass]:[N/A]]) -> 0 | I8: =IFERROR(표3_5[[#This Row],[Total]]/표3_5[[#This Row],[시나리오 수]],0) -> 0 | J8: =IFERROR(SUM(표3_5[[#This Row],[Pass]:[Fail]])/표3_5[[#This Row],[시나리오 수]],0) -> 0 | K8: =IFERROR(표3_5[[#This Row],[Pass]]/SUM(표3_5[[#This Row],[Pass]:[Fail]]),0) -> 0 | L8: =IFERROR((표3_5[[#This Row],[Fail]]/SUM(표3_5[[#This Row],[Pass]:[Fail]])),0) -> 0 | M8: =IFERROR((표3_5[[#This Row],[N/A]]/표3_5[[#This Row],[시나리오 수]]),0) -> 0
B9: PO | H9: =SUM(표3_5[[#This Row],[Pass]:[N/A]]) -> 0 | I9: =IFERROR(표3_5[[#This Row],[Total]]/표3_5[[#This Row],[시나리오 수]],0) -> 0 | J9: =IFERROR(SUM(표3_5[[#This Row],[Pass]:[Fail]])/표3_5[[#This Row],[시나리오 수]],0) -> 0 | L9: =IFERROR((표3_5[[#This Row],[Fail]]/SUM(표3_5[[#This Row],[Pass]:[Fail]])),0) -> 0 | M9: =IFERROR((표3_5[[#This Row],[N/A]]/표3_5[[#This Row],[시나리오 수]]),0) -> 0
B10: Total | C10: =SUM(C6:C9) -> 0 | D10: =SUM(D6:D9) -> 0 | E10: =SUM(E6:E9) -> 0 | F10: =SUM(F6:F9) -> 0 | G10: =SUM(G6:G9) -> 0 | H10: =SUM(H6:H9) -> 0 | I10: =IFERROR(표3_5[[#This Row],[Total]]/표3_5[[#This Row],[시나리오 수]],0) -> 0 | J10: =IFERROR(SUM(표3_5[[#This Row],[Pass]:[Fail]])/표3_5[[#This Row],[시나리오 수]],0) -> 0 | K10: =IFERROR(표3_5[[#This Row],[Pass]]/SUM(표3_5[[#This Row],[Pass]:[Fail]]),0) -> 0 | L10: =IFERROR((표3_5[[#This Row],[Fail]]/SUM(표3_5[[#This Row],[Pass]:[Fail]])),0) -> 0 | M10: =IFERROR((표3_5[[#This Row],[N/A]]/표3_5[[#This Row],[시나리오 수]]),0) -> 0
B12: ... Sheet
B14: SYS | C14: 시나리오 수 | D14: Pass | E14: Fail | F14: Block | G14: N/A | H14: Total | I14: 진척율 | J14: 수행율 | K14: 성공율 | L14: 결함율 | M14: 수행불가율
B15: PO | H15: =SUM(표3_58[[#This Row],[Pass]:[N/A]]) -> 0 | I15: =IFERROR(표3_58[[#This Row],[Total]]/표3_58[[#This Row],[시나리오 수]],0) -> 0 | J15: =IFERROR(SUM(표3_58[[#This Row],[Pass]:[Fail]])/표3_58[[#This Row],[시나리오 수]],0) -> 0 | K15: =IFERROR(표3_58[[#This Row],[Pass]]/SUM(표3_58[[#This Row],[Pass]:[Fail]]),0) -> 0 | L15: =IFERROR((표3_58[[#This Row],[Fail]]/SUM(표3_58[[#This Row],[Pass]:[Fail]])),0) -> 0 | M15: =IFERROR((표3_58[[#This Row],[N/A]]/표3_58[[#This Row],[시나리오 수]]),0) -> 0
B16: MO | H16: =SUM(표3_58[[#This Row],[Pass]:[N/A]]) -> 0 | I16: =IFERROR(표3_58[[#This Row],[Total]]/표3_58[[#This Row],[시나리오 수]],0) -> 0 | J16: =IFERROR(SUM(표3_58[[#This Row],[Pass]:[Fail]])/표3_58[[#This Row],[시나리오 수]],0) -> 0 | K16: =IFERROR(표3_58[[#This Row],[Pass]]/SUM(표3_58[[#This Row],[Pass]:[Fail]]),0) -> 0 | L16: =IFERROR((표3_58[[#This Row],[Fail]]/SUM(표3_58[[#This Row],[Pass]:[Fail]])),0) -> 0 | M16: =IFERROR((표3_58[[#This Row],[N/A]]/표3_58[[#This Row],[시나리오 수]]),0) -> 0
B17: BO | H17: =SUM(표3_58[[#This Row],[Pass]:[N/A]]) -> 0 | I17: =IFERROR(표3_58[[#This Row],[Total]]/표3_58[[#This Row],[시나리오 수]],0) -> 0 | J17: =IFERROR(SUM(표3_58[[#This Row],[Pass]:[Fail]])/표3_58[[#This Row],[시나리오 수]],0) -> 0 | K17: =IFERROR(표3_58[[#This Row],[Pass]]/SUM(표3_58[[#This Row],[Pass]:[Fail]]),0) -> 0 | L17: =IFERROR((표3_58[[#This Row],[Fail]]/SUM(표3_58[[#This Row],[Pass]:[Fail]])),0) -> 0 | M17: =IFERROR((표3_58[[#This Row],[N/A]]/표3_58[[#This Row],[시나리오 수]]),0) -> 0
B18: PO | H18: =SUM(표3_58[[#This Row],[Pass]:[N/A]]) -> 0 | I18: =IFERROR(표3_58[[#This Row],[Total]]/표3_58[[#This Row],[시나리오 수]],0) -> 0 | J18: =IFERROR(SUM(표3_58[[#This Row],[Pass]:[Fail]])/표3_58[[#This Row],[시나리오 수]],0) -> 0 | L18: =IFERROR((표3_58[[#This Row],[Fail]]/SUM(표3_58[[#This Row],[Pass]:[Fail]])),0) -> 0 | M18: =IFERROR((표3_58[[#This Row],[N/A]]/표3_58[[#This Row],[시나리오 수]]),0) -> 0
B19: Total | C19: =SUM(C15:C18) -> 0 | D19: =SUM(D15:D18) -> 0 | E19: =SUM(E15:E18) -> 0 | F19: =SUM(F15:F18) -> 0 | G19: =SUM(G15:G18) -> 0 | H19: =SUM(H15:H18) -> 0 | I19: =IFERROR(표3_58[[#This Row],[Total]]/표3_58[[#This Row],[시나리오 수]],0) -> 0 | J19: =IFERROR(SUM(표3_58[[#This Row],[Pass]:[Fail]])/표3_58[[#This Row],[시나리오 수]],0) -> 0 | K19: =IFERROR(표3_58[[#This Row],[Pass]]/SUM(표3_58[[#This Row],[Pass]:[Fail]]),0) -> 0 | L19: =IFERROR((표3_58[[#This Row],[Fail]]/SUM(표3_58[[#This Row],[Pass]:[Fail]])),0) -> 0 | M19: =IFERROR((표3_58[[#This Row],[N/A]]/표3_58[[#This Row],[시나리오 수]]),0) -> 0
B21: 테스트 수행 현황
B23: Sheet명 | C23: 시나리오 수 | D23: Pass | E23: Fail | F23: Block | G23: N/A | H23: Total | I23: 진척율 | J23: 수행율 | K23: 성공율 | L23: 결함율 | M23: 수행불가율
B24: 주문 클레임 | H24: =SUM(표3_6[[#This Row],[Pass]:[N/A]]) -> 0 | I24: =IFERROR(표3_6[[#This Row],[Total]]/표3_6[[#This Row],[시나리오 수]],0) -> 0 | J24: =IFERROR(SUM(표3_6[[#This Row],[Pass]:[Fail]])/표3_6[[#This Row],[시나리오 수]],0) -> 0 | K24: =IFERROR(표3_6[[#This Row],[Pass]]/SUM(표3_6[[#This Row],[Pass]:[Fail]]),0) -> 0 | L24: =IFERROR((표3_6[[#This Row],[Fail]]/SUM(표3_6[[#This Row],[Pass]:[Fail]])),0) -> 0 | M24: =IFERROR((표3_6[[#This Row],[N/A]]/표3_6[[#This Row],[시나리오 수]]),0) -> 0
B25: AS | H25: =SUM(표3_6[[#This Row],[Pass]:[N/A]]) -> 0 | I25: =IFERROR(표3_6[[#This Row],[Total]]/표3_6[[#This Row],[시나리오 수]],0) -> 0 | J25: =IFERROR(SUM(표3_6[[#This Row],[Pass]:[Fail]])/표3_6[[#This Row],[시나리오 수]],0) -> 0 | K25: =IFERROR(표3_6[[#This Row],[Pass]]/SUM(표3_6[[#This Row],[Pass]:[Fail]]),0) -> 0 | L25: =IFERROR((표3_6[[#This Row],[Fail]]/SUM(표3_6[[#This Row],[Pass]:[Fail]])),0) -> 0 | M25: =IFERROR((표3_6[[#This Row],[N/A]]/표3_6[[#This Row],[시나리오 수]]),0) -> 0
B26: … | H26: =SUM(표3_6[[#This Row],[Pass]:[N/A]]) -> 0 | I26: =IFERROR(표3_6[[#This Row],[Total]]/표3_6[[#This Row],[시나리오 수]],0) -> 0 | J26: =IFERROR(SUM(표3_6[[#This Row],[Pass]:[Fail]])/표3_6[[#This Row],[시나리오 수]],0) -> 0 | K26: =IFERROR(표3_6[[#This Row],[Pass]]/SUM(표3_6[[#This Row],[Pass]:[Fail]]),0) -> 0 | L26: =IFERROR((표3_6[[#This Row],[Fail]]/SUM(표3_6[[#This Row],[Pass]:[Fail]])),0) -> 0 | M26: =IFERROR((표3_6[[#This Row],[N/A]]/표3_6[[#This Row],[시나리오 수]]),0) -> 0
I27: =IFERROR(표3_6[[#This Row],[Total]]/표3_6[[#This Row],[시나리오 수]],0) -> 0 | J27: =IFERROR(SUM(표3_6[[#This Row],[Pass]:[Fail]])/표3_6[[#This Row],[시나리오 수]],0) -> 0 | L27: =IFERROR((표3_6[[#This Row],[Fail]]/SUM(표3_6[[#This Row],[Pass]:[Fail]])),0) -> 0 | M27: =IFERROR((표3_6[[#This Row],[N/A]]/표3_6[[#This Row],[시나리오 수]]),0) -> 0
H28: =SUM(표3_6[[#This Row],[Pass]:[N/A]]) -> 0 | I28: =IFERROR(표3_6[[#This Row],[Total]]/표3_6[[#This Row],[시나리오 수]],0) -> 0 | J28: =IFERROR(SUM(표3_6[[#This Row],[Pass]:[Fail]])/표3_6[[#This Row],[시나리오 수]],0) -> 0 | K28: =IFERROR(표3_6[[#This Row],[Pass]]/SUM(표3_6[[#This Row],[Pass]:[Fail]]),0) -> 0 | L28: =IFERROR((표3_6[[#This Row],[Fail]]/SUM(표3_6[[#This Row],[Pass]:[Fail]])),0) -> 0 | M28: =IFERROR((표3_6[[#This Row],[N/A]]/표3_6[[#This Row],[시나리오 수]]),0) -> 0
B29: Total | C29: =SUM(C24:C28) -> 0 | D29: =SUM(D24:D28) -> 0 | E29: =SUM(E24:E28) -> 0 | F29: =SUM(F24:F28) -> 0 | G29: =SUM(G24:G28) -> 0 | H29: =SUM(H24:H28) -> 0 | I29: =IFERROR(표3_6[[#This Row],[Total]]/표3_6[[#This Row],[시나리오 수]],0) -> 0 | J29: =IFERROR(SUM(표3_6[[#This Row],[Pass]:[Fail]])/표3_6[[#This Row],[시나리오 수]],0) -> 0 | K29: =IFERROR(표3_6[[#This Row],[Pass]]/SUM(표3_6[[#This Row],[Pass]:[Fail]]),0) -> 0 | L29: =IFERROR((표3_6[[#This Row],[Fail]]/SUM(표3_6[[#This Row],[Pass]:[Fail]])),0) -> 0 | M29: =IFERROR((표3_6[[#This Row],[N/A]]/표3_6[[#This Row],[시나리오 수]]),0) -> 0
B31: SYS | C31: 시나리오 수 | D31: Pass | E31: Fail | F31: Block | G31: N/A | H31: Total | I31: 진척율 | J31: 수행율 | K31: 성공율 | L31: 결함율 | M31: 수행불가율
B32: PO | H32: =SUM(표3_57[[#This Row],[Pass]:[N/A]]) -> 0 | I32: =IFERROR(표3_57[[#This Row],[Total]]/표3_57[[#This Row],[시나리오 수]],0) -> 0 | J32: =IFERROR(SUM(표3_57[[#This Row],[Pass]:[Fail]])/표3_57[[#This Row],[시나리오 수]],0) -> 0 | K32: =IFERROR(표3_57[[#This Row],[Pass]]/SUM(표3_57[[#This Row],[Pass]:[Fail]]),0) -> 0 | L32: =IFERROR((표3_57[[#This Row],[Fail]]/SUM(표3_57[[#This Row],[Pass]:[Fail]])),0) -> 0 | M32: =IFERROR((표3_57[[#This Row],[N/A]]/표3_57[[#This Row],[시나리오 수]]),0) -> 0
B33: MO | H33: =SUM(표3_57[[#This Row],[Pass]:[N/A]]) -> 0 | I33: =IFERROR(표3_57[[#This Row],[Total]]/표3_57[[#This Row],[시나리오 수]],0) -> 0 | J33: =IFERROR(SUM(표3_57[[#This Row],[Pass]:[Fail]])/표3_57[[#This Row],[시나리오 수]],0) -> 0 | K33: =IFERROR(표3_57[[#This Row],[Pass]]/SUM(표3_57[[#This Row],[Pass]:[Fail]]),0) -> 0 | L33: =IFERROR((표3_57[[#This Row],[Fail]]/SUM(표3_57[[#This Row],[Pass]:[Fail]])),0) -> 0 | M33: =IFERROR((표3_57[[#This Row],[N/A]]/표3_57[[#This Row],[시나리오 수]]),0) -> 0
B34: BO | H34: =SUM(표3_57[[#This Row],[Pass]:[N/A]]) -> 0 | I34: =IFERROR(표3_57[[#This Row],[Total]]/표3_57[[#This Row],[시나리오 수]],0) -> 0 | J34: =IFERROR(SUM(표3_57[[#This Row],[Pass]:[Fail]])/표3_57[[#This Row],[시나리오 수]],0) -> 0 | K34: =IFERROR(표3_57[[#This Row],[Pass]]/SUM(표3_57[[#This Row],[Pass]:[Fail]]),0) -> 0 | L34: =IFERROR((표3_57[[#This Row],[Fail]]/SUM(표3_57[[#This Row],[Pass]:[Fail]])),0) -> 0 | M34: =IFERROR((표3_57[[#This Row],[N/A]]/표3_57[[#This Row],[시나리오 수]]),0) -> 0
B35: PO | I35: =IFERROR(표3_57[[#This Row],[Total]]/표3_57[[#This Row],[시나리오 수]],0) -> 0 | J35: =IFERROR(SUM(표3_57[[#This Row],[Pass]:[Fail]])/표3_57[[#This Row],[시나리오 수]],0) -> 0 | L35: =IFERROR((표3_57[[#This Row],[Fail]]/SUM(표3_57[[#This Row],[Pass]:[Fail]])),0) -> 0 | M35: =IFERROR((표3_57[[#This Row],[N/A]]/표3_57[[#This Row],[시나리오 수]]),0) -> 0
B36: Total | C36: =SUM(C32:C35) -> 0 | D36: =SUM(D32:D35) -> 0 | E36: =SUM(E32:E35) -> 0 | F36: =SUM(F32:F35) -> 0 | G36: =SUM(G32:G35) -> 0 | H36: =SUM(H32:H35) -> 0 | I36: =IFERROR(표3_57[[#This Row],[Total]]/표3_57[[#This Row],[시나리오 수]],0) -> 0 | J36: =IFERROR(SUM(표3_57[[#This Row],[Pass]:[Fail]])/표3_57[[#This Row],[시나리오 수]],0) -> 0 | K36: =IFERROR(표3_57[[#This Row],[Pass]]/SUM(표3_57[[#This Row],[Pass]:[Fail]]),0) -> 0 | L36: =IFERROR((표3_57[[#This Row],[Fail]]/SUM(표3_57[[#This Row],[Pass]:[Fail]])),0) -> 0 | M36: =IFERROR((표3_57[[#This Row],[N/A]]/표3_57[[#This Row],[시나리오 수]]),0) -> 0

Sheet 1-1_주문 클레임 목록
L3: 예약상품 : 통합멤버십 / 1개 상품 바로구매 | AJ3: 포인트 : 통합멤버십 | AZ3: 부분취소 클레임 철회 : 에스크로(무통장/실시간), 휴대폰결제
B5: 시나리오 ID | C5: 사이트 | D5: 회원 유형 | E5: 상품 | Q5: 프로모션 | U5: 쿠폰 | AB5: 배송비 (기준금액 x만원) | AF5: 배송유형 | AI5: 보조 결제수단 | AK5: 주 결제수단 | AR5: 클레임 | BA5: 추가 배송비 결제
E6: 판매채널 | I6: 공급방식 | K6: 상품속성 | O6: 주문수량 | Q6: 할인 | T6: 사은품 | U6: 할인 | W6: 제휴사 할인 쿠폰 | Y6: 품절보상 쿠폰 | AA6: 기타 | AB6: 유료 | AC6: 무료 | AK6: 신용카드 | AN6: 현금성 | AR6: 접수경로 | AT6: 취소 | AV6: 반품 | AX6: 교환 | AZ6: 클레임 철회
E7: ABC-Mart | F7: GS | G7: A-RT | H7: OTS | I7: 자사 | J7: 입점 | K7: 일반 | L7: 예약 | M7: 무료배송 | N7: 픽업 | O7: 단수 | P7: 복수 | Q7: 즉시할인 | R7: 다족구매 할인 | S7: 기간한정특가 | T7: 사은품 지급 | U7: 일반 | V7: 플러스 | W7: 일반 | X7: 플러스 | Y7: 일반 | Z7: 플러스 | AA7: 더블 포인트 | AC7: 무료배송상품 | AD7: 3만원 이상 | AE7: 무료배송 쿠폰 | AF7: 택배 | AG7: 편의점 | AH7: 픽업 | AI7: 기프트 카드 | AJ7: 포인트 | AK7: 신용카드 | AL7: 네이버 페이 | AM7: 카카오 페이 | AN7: 휴대폰 결제 | AO7: 무통장 | AP7: 실시간 계좌이체 | AQ7: 에스크로 | AR7: 프론트 | AS7: 고객센터 | AT7: 전체취소 | AU7: 부분취소 | AV7: 전체반품 | AW7: 부분반품 | AX7: 전체교환 | AY7: 부분교환 | BA7: 신용카드 | BB7: 실시간 계좌이체 | BC7: 환불금액 차감 | BD7: 쿠폰
B8: IT-OC-001 | C8: A-RT | D8: 비회원 | E8: ● | I8: ● | K8: ● | M8: ● | O8: ● | P8: ● | S8: ● | U8: - | V8: - | W8: - | X8: - | Y8: - | Z8: - | AA8: - | AC8: ● | AE8: - | AG8: ● | AI8: - | AJ8: - | AP8: ● | AQ8: ● | AR8: ● | AX8: ● | AZ8: ● | BA8: ● | BD8: -
B9: IT-OC-002 | C9: A-RT | D9: 비회원 | F9: ● | G9: ● | I9: ● | J9: ● | K9: ● | P9: ● | U9: - | V9: - | W9: - | X9: - | Y9: - | Z9: - | AA9: - | AB9: ● | AE9: - | AF9: ● | AI9: - | AJ9: - | AM9: ● | AS9: ● | AW9: ● | BC9: ● | BD9: -
B10: IT-OC-003 | C10: A-RT | D10: 비회원 | G10: ● | J10: ● | K10: ● | O10: ● | Q10: ● | U10: - | V10: - | W10: - | X10: - | Y10: - | Z10: - | AA10: - | AB10: ● | AE10: - | AF10: ● | AI10: - | AJ10: - | AK10: ● | AR10: ● | AT10: ● | BA10: - | BB10: - | BC10: - | BD10: -
B11: IT-OC-004 | C11: A-RT | D11: 온라인회원 | E11: ● | I11: ● | K11: ● | N11: ● | O11: ● | P11: ● | S11: ● | V11: ● | W11: ● | AA11: - | AB11: - | AC11: - | AD11: - | AE11: - | AH11: ● | AI11: ● | AJ11: - | AP11: ● | AQ11: ● | AR11: ● | AV11: ● | BC11: ●
B12: IT-OC-005 | C12: A-RT | D12: 온라인회원 | F12: ● | G12: ● | I12: ● | J12: ● | K12: ● | N12: ● | O12: ● | T12: ● | Y12: ● | AA12: - | AB12: ● | AF12: ● | AJ12: - | AN12: ● | AR12: ● | AU12: ● | AY12: ● | AZ12: ● | BB12: ●
B13: IT-OC-006 | C13: A-RT | D13: 온라인회원 | G13: ● | J13: ● | K13: ● | M13: ● | O13: ● | P13: ● | R13: ● | U13: ● | AA13: - | AC13: ● | AF13: ● | AI13: ● | AJ13: - | AK13: ● | AS13: ● | AT13: ● | BA13: - | BB13: - | BC13: - | BD13: -
B14: IT-OC-007 | C14: A-RT | D14: 임직원 | E14: ● | F14: ● | I14: ● | K14: ● | M14: ● | O14: ● | P14: ● | S14: ● | U14: - | V14: - | W14: - | X14: - | Y14: - | Z14: - | AA14: - | AC14: ● | AE14: - | AG14: ● | AI14: ● | AJ14: - | AR14: ● | AX14: ● | BA14: ● | BD14: -
B15: IT-OC-008 | C15: A-RT | D15: 임직원 | E15: ● | G15: ● | I15: ● | J15: ● | K15: ● | N15: ● | O15: ● | P15: ● | R15: ● | U15: - | V15: - | W15: - | X15: - | Y15: - | Z15: - | AA15: - | AB15: ● | AD15: ● | AE15: - | AF15: ● | AJ15: - | AP15: ● | AQ15: ● | AR15: ● | AU15: ● | AY15: ● | AZ15: ● | BB15: ● | BD15: -
B16: IT-OC-009 | C16: A-RT | D16: 임직원 | G16: ● | J16: ● | K16: ● | O16: ● | U16: - | V16: - | W16: - | X16: - | Y16: - | Z16: - | AA16: - | AD16: ● | AE16: - | AF16: ● | AJ16: - | AK16: ● | AS16: ● | AT16: ● | BA16: - | BB16: - | BC16: - | BD16: -
B17: IT-OC-010 | C17: A-RT | D17: 통합멤버십 | E17: ● | I17: ● | K17: ● | N17: ● | O17: ● | P17: ● | S17: ● | AA17: ● | AD17: ● | AG17: ● | AI17: ● | AL17: ● | AR17: ● | AS17: ● | AV17: ● | AX17: ● | BA17: ●
B18: IT-OC-011 | C18: A-RT | D18: 통합멤버십 | E18: ● | F18: ● | I18: ● | K18: ● | M18: ● | P18: ● | T18: ● | V18: ● | AC18: ● | AG18: ● | AJ18: ● | AO18: ● | AR18: ● | AW18: ● | AY18: ● | BB18: ● | BC18: ●
B19: IT-OC-012 | C19: A-RT | D19: 통합멤버십 | E19: ● | G19: ● | I19: ● | J19: ● | K19: ● | P19: ● | Q19: ● | U19: ● | AE19: ● | AF19: ● | AI19: ● | AJ19: ● | AR19: ● | AV19: ● | AZ19: ● | BD19: ●
B20: IT-OC-013 | C20: A-RT | D20: 통합멤버십 | G20: ● | J20: ● | K20: ● | O20: ● | V20: ● | AD20: ● | AF20: ● | AM20: ● | AS20: ● | AT20: ● | BA20: - | BB20: - | BC20: - | BD20: -
B21: IT-OC-014 | C21: OTS | D21: 비회원 | H21: ● | I21: ● | K21: ● | O21: ● | S21: ● | U21: - | V21: - | W21: - | X21: - | Y21: - | Z21: - | AA21: - | AB21: ● | AE21: - | AF21: ● | AI21: - | AJ21: - | AK21: ● | AR21: ● | AT21: ● | BA21: - | BB21: - | BC21: - | BD21: -
B22: IT-OC-015 | C22: OTS | D22: 비회원 | H22: ● | I22: ● | K22: ● | M22: ● | O22: ● | P22: ● | U22: - | V22: - | W22: - | X22: - | Y22: - | Z22: - | AA22: - | AC22: ● | AE22: - | AG22: ● | AI22: - | AJ22: - | AN22: ● | AS22: ● | AU22: ● | AZ22: ● | BA22: - | BB22: - | BC22: - | BD22: -
B23: IT-OC-016 | C23: OTS | D23: 온라인회원 | H23: ● | I23: ● | K23: ● | N23: ● | P23: ● | Z23: ● | AA23: - | AB23: - | AC23: - | AD23: - | AE23: - | AH23: ● | AJ23: - | AK23: ● | AR23: ● | AX23: ● | BA23: ●
B24: IT-OC-017 | C24: OTS | D24: 온라인회원 | H24: ● | I24: ● | K24: ● | O24: ● | Q24: ● | U24: ● | AA24: - | AB24: ● | AG24: ● | AI24: ● | AJ24: - | AM24: ● | AS24: ● | AV24: ● | AZ24: ● | BC24: ●
B25: IT-OC-018 | C25: OTS | D25: 임직원 | H25: ● | I25: ● | K25: ● | P25: ● | Q25: ● | T25: ● | U25: - | V25: - | W25: - | X25: - | Y25: - | Z25: - | AA25: - | AB25: ● | AE25: - | AG25: ● | AJ25: - | AL25: ● | AS25: ● | AT25: ● | BA25: - | BB25: - | BC25: - | BD25: -
B26: IT-OC-019 | C26: OTS | D26: 임직원 | H26: ● | I26: ● | K26: ● | M26: ● | O26: ● | P26: ● | R26: ● | U26: - | V26: - | W26: - | X26: - | Y26: - | Z26: - | AA26: - | AC26: ● | AE26: - | AF26: ● | AJ26: - | AP26: ● | AQ26: ● | AR26: ● | AW26: ● | AZ26: ● | BB26: ● | BD26: -
B27: IT-OC-020 | C27: OTS | D27: 통합멤버십 | H27: ● | I27: ● | L27: ● | P27: ● | X27: ● | AB27: ● | AG27: ● | AI27: ● | AJ27: ● | AP27: ● | AR27: ● | AU27: ● | BA27: - | BB27: - | BC27: - | BD27: -
B28: IT-OC-021 | C28: OTS | D28: 통합멤버십 | H28: ● | I28: ● | K28: ● | O28: ● | P28: ● | T28: ● | U28: ● | Z28: ● | AB28: ● | AF28: ● | AJ28: ● | AS28: ● | AY28: ● | AZ28: ● | BD28: ●

Sheet 1-2_주문 클레임
B7: No. | C7: 시나리오 ID | D7: 사이트 | E7: 회원 | G7: 상품정보 | S7: 프로모션 | Y7: 쿠폰 | AG7: 주문금액 | AH7: 배송 | AM7: 결제예정금액 | AN7: 보조 결제수단 | AQ7: 주 결제수단 | AT7: 주문정보 | AY7: 주문 진행 상태 | BE7: 클레임 | BJ7: 배송비 추가 결제 | BL7: 환불 금액 | BR7: 테스트 결과
E8: 유형 | F8: ID | G8: 판매 채널 | H8: 판매 주체 | I8: 입점사ID | J8: 상품 유형 | K8: 픽업가능 | L8: 무료배송 | M8: 옵션 추가금액 | N8: 온라인 상품코드 | O8: 정상가 | P8: 수량 | Q8: 소계 | R8: 총 정상가 | S8: 유형 | T8: 프로모션번호 | U8: 프로모션명 | V8: 프로모션 할인율 | W8: 프로모션 할인 | X8: 프로모션 할인 합계 | Y8: 유형 | Z8: 분류 | AA8: 구분 | AB8: 쿠폰번호 | AC8: 쿠폰명 | AD8: 쿠폰할인률 | AE8: 쿠폰할인 | AF8: 쿠폰할인 합계 | AH8: 유형 | AI8: 배송 주체 | AJ8: 무료적용 | AK8: 배송비 | AL8: 배송비 합계 | AN8: 기프트카드 | AO8: 구매 포인트 | AP8: 이벤트포인트 | AQ8: 결제수단 | AR8: 에스크로 | AS8: 결제 금액 | AT8: 주문번호 | AU8: 실 결제 금액 | AV8: 신용카드 전표 | AW8: 현금 영수증 | AX8: 비회원 영수증키 | AY8: 결제완료 | AZ8: 주문취소 | BA8: 상품준비중 | BB8: 배송완료 | BC8: 반품완료 | BD8: 교환완료 | BE8: 접수경로 | BF8: 주체 | BG8: 유형 | BH8: 클레임번호 | BI8: 클레임 철회 | BJ8: 결제수단 | BK8: 추가 배송비 | BL8: 총 환불 금액 | BM8: 기프트카드 | BN8: 구매 포인트 | BO8: 이벤트포인트 | BP8: 주 결제수단 | BQ8: 환불 금액 | BR8: 수행일자 | BS8: 수행자 | BT8: 테스트결과 | BU8: 결함사항 | BV8: 수정여부 | BW8: 비고
B9: 1 | C9: IT-OC-001 | D9: A-RT | E9: 비회원 | G9: ABC-Mart | H9: 자사 | J9: 일반 | L9: O | M9: N | N9: =상품Data!H5 -> 2000000001 | O9: =상품Data!S5 -> 69000 | P9: 1 | Q9: =O9*P9 -> 69000 | R9: =SUM(Q9:Q10) -> 91000 | S9: =프로모션Data!C9 -> 기간한정 특가 | T9: =프로모션Data!D9 -> 1234567894 | U9: =프로모션Data!E9 -> [전체] 기간한정_30% 정률 할인 | V9: 0.3 | W9: =ROUNDUP(Q9*V9, -2) -> 20700 | X9: =SUM(W9:W10) -> 20700 | AF9: =SUM(AE9:AE10) -> 0 | AG9: =O9-W9-AE9 -> 48300 | AH9: 편의점 | AI9: 자사 | AJ9: 무료배송상품 | AK9: 0 | AL9: =SUM(AK9:AK10) -> 0 | AM9: =R9-X9-AF9+AL9 -> 70300 | AQ9: 실시간 계좌이체 | AR9: O | AS9: =AM9-AN9-AO9-AP9 -> 70300 | AW9: O | AX9: O | BE9: 프론트 | BF9: 자사 | BG9: 전체교환 | BI9: O | BJ9: 신용카드 | BP9: 실시간 계좌이체
G10: ABC-Mart | H10: 자사 | J10: 일반 | M10: N | N10: =상품Data!H6 -> 2000000002 | O10: =상품Data!S6 -> 11000 | P10: 2 | Q10: =O10*P10 -> 22000 | AG10: =O10-W10-AE10 -> 11000 | AM10: =R10-X10-AF10+AL10 -> 0
B11: 2 | C11: IT-OC-002 | D11: A-RT | E11: 비회원 | G11: GS | H11: 자사 | J11: 일반 | M11: N | N11: =상품Data!H7 -> 2000000003 | O11: =상품Data!S7 -> 9000 | P11: 2 | Q11: =O11*P11 -> 18000 | R11: =SUM(Q11:Q12) -> 34000 | X11: =SUM(W11:W12) -> 0 | AF11: =SUM(AE11:AE12) -> 0 | AG11: =O11-W11-AE11 -> 9000 | AH11: 택배 | AI11: 자사 | AK11: 2500 | AL11: =SUM(AK11:AK12) -> 5500 | AM11: =R11-X11-AF11+AL11 -> 39500 | AQ11: 카카오페이 | AS11: =AM11-AN11-AO11-AP11 -> 39500 | AV11: O | AX11: O | BP11: 카카오페이
G12: A-RT | H12: 입점 | I12: VD20000001 | J12: 일반 | M12: N | N12: =상품Data!H8 -> 2000000004 | O12: =상품Data!S8 -> 8000 | P12: 2 | Q12: =O12*P12 -> 16000 | AG12: =O12-W12-AE12 -> 8000 | AH12: 택배 | AI12: 입점 | AK12: 3000 | AM12: =R12-X12-AF12+AL12 -> 0 | BE12: 고객센터 | BF12: 입점 | BG12: 부분반품 | BJ12: 환불금액 차감
B13: 3 | C13: IT-OC-003 | D13: A-RT | E13: 비회원 | G13: A-RT | H13: 입점 | I13: VD20000003 | J13: 일반 | M13: Y | N13: =상품Data!H9 -> 2000000005 | O13: =상품Data!S9 -> 15000 | P13: 1 | Q13: =O13*P13 -> 15000 | R13: =Q13 -> 15000 | S13: =프로모션Data!C5 -> 즉시할인 | T13: =프로모션Data!D5 -> 1234567890 | U13: =프로모션Data!E5 -> [전체] 즉시할인_20% 정률 할인 | V13: 0.2 | W13: =ROUNDUP(Q13*V13, -2) -> 3000 | X13: =W13 -> 3000 | AF13: =AE13 -> 0 | AG13: =O13-W13-AE13 -> 12000 | AH13: 택배 | AI13: 입점 | AK13: 2500 | AL13: =AK13 -> 2500 | AM13: =R13-X13-AF13+AL13 -> 14500 | AQ13: 신용카드 | AS13: =AM13-AN13-AO13-AP13 -> 14500 | AV13: O | AX13: O | BE13: 프론트 | BF13: 입점 | BG13: 전체취소 | BP13: 신용카드
B14: 4 | C14: IT-OC-004 | D14: A-RT | E14: 온라인회원 | G14: ABC-Mart | H14: 자사 | J14: 일반 | K14: O | M14: Y | N14: =상품Data!H10 -> 2000000006 | O14: =상품Data!S10 -> 11000 | P14: 1 | Q14: =O14*P14 -> 11000 | R14: =SUM(Q14:Q15) -> 43000 | S14: =프로모션Data!C9 -> 기간한정 특가 | T14: =프로모션Data!D9 -> 1234567894 | U14: =프로모션Data!E9 -> [전체] 기간한정_30% 정률 할인 | V14: 0.3 | W14: =ROUNDUP(Q14*V14, -2) -> 3300 | X14: =SUM(W14:W15) -> 3300 | Y14: =쿠폰Data!C9 -> 할인쿠폰 | Z14: =쿠폰Data!D9 -> 플러스 | AA14: =쿠폰Data!E9 -> 자사 | AB14: =쿠폰Data!F9 -> A12345682 | AC14: =쿠폰Data!G9 -> [플러스/자사/온라인] 20% 정률 할인 / 최대금액 제한없음 | AD14: 0.2 | AE14: =ROUNDUP((Q14-W14)*AD14, -2) -> 1600 | AF14: =SUM(AE14:AE15) -> 3200 | AG14: =O14-W14-AE14 -> 6100 | AH14: 픽업 | AI14: 자사 | AJ14: 픽업배송 | AK14: 0 | AL14: =SUM(AK14:AK15) -> 0 | AM14: =R14-X14-AF14+AL14 -> 36500 | AN14: 30000 | AQ14: 실시간 계좌이체 | AR14: O | AS14: =AM14-AN14-AO14-AP14 -> 6500 | AW14: O | BE14: 프론트 | BF14: 자사 | BG14: 전체반품 | BJ14: 환불금액 차감 | BL14: O | BM14: O | BP14: 실시간 계좌이체
G15: ABC-Mart | H15: 자사 | J15: 일반 | K15: O | M15: N | N15: =상품Data!H11 -> 2000000007 | O15: =상품Data!S11 -> 16000 | P15: 2 | Q15: =O15*P15 -> 32000 | Y15: =쿠폰Data!C13 -> 제휴사 할인쿠폰 | Z15: =쿠폰Data!D13 -> 일반 | AA15: =쿠폰Data!E13 -> 자사 | AB15: =쿠폰Data!F13 -> A12345686 | AC15: =쿠폰Data!G13 -> [일반/자사/회원] 5% 정률 할인 / 최대 5,000원 | AD15: 0.05 | AE15: =ROUNDUP((Q15-W15)*AD15, -2) -> 1600 | AG15: =O15-W15-AE15 -> 14400 | AM15: =R15-X15-AF15+AL15 -> 0
B16: 5 | C16: IT-OC-005 | D16: A-RT | E16: 온라인회원 | G16: A-RT | H16: 입점 | I16: VD20000002 | J16: 일반 | M16: N | N16: =상품Data!H12 -> 2000000008 | O16: =상품Data!S12 -> 14000 | P16: 1 | Q16: =O16*P16 -> 14000 | R16: =SUM(Q16:Q17) -> 32000 | X16: =SUM(W16:W17) -> 0 | Y16: =쿠폰Data!C24 -> 품절보상쿠폰 | Z16: =쿠폰Data!D24 -> 일반 | AA16: =쿠폰Data!E24 -> 입점 | AB16: =쿠폰Data!F24 -> A12345697 | AC16: =쿠폰Data!G24 -> [입점] 품절보상 / 20% 정률 할인 / 1개 단품만 적용 가능 | AD16: 0.2 | AE16: =ROUNDUP((Q16-W16)*AD16, -2) -> 2800 | AF16: =SUM(AE16:AE17) -> 2800 | AG16: =O16-W16-AE16 -> 11200 | AH16: 택배 | AI16: 입점 | AK16: 3000 | AL16: =SUM(AK16:AK17) -> 5500 | AM16: =R16-X16-AF16+AL16 -> 34700 | AQ16: 휴대폰 결제 | AS16: =AM16-AN16-AO16-AP16 -> 34700 | BE16: 프론트 | BF16: 입점 | BG16: 부분취소 | BI16: O | BP16: 휴대폰 결제
G17: GS | H17: 자사 | J17: 일반 | K17: O | M17: N | N17: =상품Data!H13 -> 2000000009 | O17: =상품Data!S13 -> 18000 | P17: 1 | Q17: =O17*P17 -> 18000 | S17: =프로모션Data!C15 -> 상품 사은품 지급 | T17: =프로모션Data!D15 -> 1234567900 | U17: =프로모션Data!E15 -> [전체] 상품 사은품_사은품명(사은품번호) | AG17: =O17-W17-AE17 -> 18000 | AH17: 택배 | AI17: 자사 | AK17: 2500 | AM17: =R17-X17-AF17+AL17 -> 0 | BE17: 프론트 | BF17: 자사 | BG17: 부분교환 | BJ17: 실시간 계좌이체
B18: 6 | C18: IT-OC-006 | D18: A-RT | E18: 온라인회원 | G18: A-RT | H18: 입점 | I18: VD20000003 | J18: 일반 | M18: N | N18: =상품Data!H14 -> 2000000010 | O18: =상품Data!S14 -> 14000 | P18: 1 | Q18: =O18*P18 -> 14000 | R18: =SUM(Q18:Q19) -> 120000 | X18: =SUM(W18:W19) -> 10600 | Y18: =쿠폰Data!C7 -> 할인쿠폰 | Z18: =쿠폰Data!D7 -> 일반 | AA18: =쿠폰Data!E7 -> 입점 | AB18: =쿠폰Data!F7 -> A12345680 | AC18: =쿠폰Data!G7 -> [일반/입점/온라인] 30% 정률 할인 / 최대 15,000원 | AD18: 0.3 | AE18: =ROUNDUP((Q18-W18)*AD18, -2) -> 4200 | AF18: =SUM(AE18:AE19) -> 4200 | AG18: =O18-W18-AE18 -> 9800 | AH18: 택배 | AI18: 입점 | AK18: 2500 | AL18: =SUM(AK18:AK19) -> 2500 | AM18: =R18-X18-AF18+AL18 -> 107700 | AN18: 7700 | AQ18: 신용카드 | AS18: =AM18-AN18-AO18-AP18 -> 100000 | AV18: O | AW18: O | BE18: 고객센터 | BF18: 입점 | BG18: 전체취소 | BL18: O | BM18: O | BP18: 신용카드
G19: A-RT | H19: 입점 | I19: VD20000002 | J19: 일반 | L19: O | M19: N | N19: =상품Data!H15 -> 2000000011 | O19: =상품Data!S15 -> 53000 | P19: 2 | Q19: =O19*P19 -> 106000 | S19: =프로모션Data!C13 -> 다족구매 할인 | T19: =프로모션Data!D13 -> 1234567898 | U19: =프로모션Data!E13 -> [온라인] 다족구매_2족 10%, 3족 20%, 4족 이상 30% | V19: 0.1 | W19: =ROUNDUP(Q19*V19, -2) -> 10600 | AG19: =O19-W19-AE19 -> 42400 | AH19: 택배 | AI19: 입점 | AJ19: 무료배송상품 | AK19: 0 | AM19: =R19-X19-AF19+AL19 -> 0
B20: 7 | C20: IT-OC-007 | D20: A-RT | E20: 임직원 | G20: ABC-Mart | H20: 자사 | J20: 일반 | M20: N | N20: =상품Data!H16 -> 1000000001 | O20: =상품Data!S16 -> 46000 | P20: 1 | Q20: =O20*P20 -> 46000 | R20: =SUM(Q20:Q21) -> 58000 | W20: =Q20*V20 -> 0 | X20: =SUM(W20:W21) -> 0 | AF20: =SUM(AE20:AE21) -> 0 | AG20: =O20-W20-AE20 -> 46000 | AL20: =SUM(AK20:AK21) -> 0 | AM20: =R20-X20-AF20+AL20 -> 58000 | AN20: 58000 | AS20: =AM20-AN20-AO20-AP20 -> 0 | AW20: O | BE20: 프론트 | BF20: 자사 | BG20: 전체교환 | BJ20: 신용카드 | BL20: O | BM20: O
G21: GS | H21: 자사 | J21: 일반 | L21: O | M21: Y | N21: =상품Data!H17 -> 1000000002 | O21: =상품Data!S17 -> 6000 | P21: 2 | Q21: =O21*P21 -> 12000 | AG21: =O21-W21-AE21 -> 6000 | AH21: 편의점 | AI21: 자사 | AJ21: 무료배송상품 | AK21: 0 | AM21: =R21-X21-AF21+AL21 -> 0 | BF21: 자사
B22: 8 | C22: IT-OC-008 | D22: A-RT | E22: 임직원 | G22: A-RT | H22: 입점 | I22: VD20000003 | J22: 일반 | M22: N | N22: =상품Data!H18 -> 2000000012 | O22: =상품Data!S18 -> 66000 | P22: 1 | Q22: =O22*P22 -> 66000 | R22: =SUM(Q22:Q23) -> 84000 | S22: =프로모션Data!C8 -> 즉시할인 | T22: =프로모션Data!D8 -> 1234567893 | U22: =프로모션Data!E8 -> [임직원] 임직원 할인_50% 정률 할인 | V22: 0.5 | W22: =ROUNDUP(Q22*V22, -2) -> 33000 | X22: =SUM(W22:W23) -> 42000 | AF22: =SUM(AE22:AE23) -> 0 | AG22: =O22-W22-AE22 -> 33000 | AH22: 택배 | AI22: 입점 | AJ22: 3만원 이상 | AK22: 0 | AL22: =SUM(AK22:AK23) -> 2500 | AM22: =R22-X22-AF22+AL22 -> 44500 | AQ22: 실시간 계좌이체 | AR22: O | AS22: =AM22-AN22-AO22-AP22 -> 44500 | AW22: O | BE22: 프론트 | BF22: 입점 | BG22: 부분교환 | BJ22: 실시간 계좌이체 | BP22: 실시간 계좌이체
G23: ABC-Mart | H23: 자사 | J23: 일반 | K23: O | M23: N | N23: =상품Data!H19 -> 1000000003 | O23: =상품Data!S19 -> 6000 | P23: 3 | Q23: =O23*P23 -> 18000 | S23: =프로모션Data!C8 -> 즉시할인 | T23: =프로모션Data!D8 -> 1234567893 | U23: =프로모션Data!E8 -> [임직원] 임직원 할인_50% 정률 할인 | V23: 0.5 | W23: =ROUNDUP(Q23*V23, -2) -> 9000 | AG23: =O23-W23-AE23 -> -3000 | AH23: 택배 | AI23: 자사 | AK23: 2500 | AM23: =R23-X23-AF23+AL23 -> 0 | BE23: 프론트 | BF23: 자사 | BG23: 부분취소 | BI23: O | BJ23: 실시간 계좌이체
B24: 9 | C24: IT-OC-009 | D24: A-RT | E24: 임직원 | G24: A-RT | H24: 입점 | I24: VD20000001 | J24: 일반 | M24: N | N24: =상품Data!H20 -> 2000000013 | O24: =상품Data!S20 -> 70000 | P24: 1 | Q24: =O24*P24 -> 70000 | R24: =Q24 -> 70000 | S24: =프로모션Data!C8 -> 즉시할인 | T24: =프로모션Data!D8 -> 1234567893 | U24: =프로모션Data!E8 -> [임직원] 임직원 할인_50% 정률 할인 | V24: 0.5 | W24: =ROUNDUP(Q24*V24, -2) -> 35000 | X24: =W24 -> 35000 | AF24: =AE24 -> 0 | AG24: =O24-W24-AE24 -> 35000 | AH24: 택배 | AI24: 입점 | AJ24: 3만원 이상 | AK24: 0 | AL24: =AK24 -> 0 | AM24: =R24-X24-AF24+AL24 -> 35000 | AQ24: 신용카드 | AS24: =AM24-AN24-AO24-AP24 -> 35000 | AV24: O | BE24: 고객센터 | BF24: 자사 | BG24: 전체취소 | BP24: 신용카드
B25: 10 | C25: IT-OC-010 | D25: A-RT | E25: 통합멤버십 | G25: ABC-Mart | H25: 자사 | J25: 일반 | K25: O | M25: N | N25: =상품Data!H21 -> 2000000014 | O25: =상품Data!S21 -> 16000 | P25: 3 | Q25: =O25*P25 -> 48000 | R25: =SUM(Q25:Q26) -> 80000 | S25: =프로모션Data!C11 -> 기간한정 특가 | T25: =프로모션Data!D11 -> 1234567896 | U25: =프로모션Data!E11 -> [통합멤버십] 기간한정_30% 정률 할인 | V25: 0.3 | W25: =ROUNDUP(Q25*V25, -2) -> 14400 | X25: =SUM(W25:W26) -> 14400 | Y25: =쿠폰Data!C15 -> 더블포인트쿠폰 | Z25: =쿠폰Data!D15 -> - | AA25: =쿠폰Data!E15 -> 자사 | AB25: =쿠폰Data!F15 -> A12345688 | AC25: =쿠폰Data!G15 -> [더블포인트/통합멤버십] 포인트 제외 결제금액 기준 6% 적립 | AF25: =SUM(AE25:AE26) -> 0 | AG25: =O25-W25-AE25 -> 1600 | AH25: 편의점 | AI25: 자사 | AJ25: 3만원 이상 | AK25: 0 | AL25: =SUM(AK25:AK26) -> 0 | AM25: =R25-X25-AF25+AL25 -> 65600 | AN25: 50000 | AQ25: 네이버페이 | AS25: =AM25-AN25-AO25-AP25 -> 15600 | AV25: O | AW25: O | BE25: 고객센터 | BF25: 자사 | BG25: 전체교환 | BJ25: 신용카드 | BL25: O | BM25: O | BP25: 네이버페이
G26: ABC-Mart | H26: 자사 | J26: 일반 | K26: O | M26: N | N26: =상품Data!H22 -> 2000000015 | O26: =상품Data!S22 -> 32000 | P26: 1 | Q26: =O26*P26 -> 32000 | AG26: =O26-W26-AE26 -> 32000 | AM26: =R26-X26-AF26+AL26 -> 0 | BE26: 프론트 | BF26: 자사 | BG26: 전체반품 | BJ26: 신용카드
B27: 11 | C27: IT-OC-011 | D27: A-RT | E27: 통합멤버십 | G27: ABC-Mart | H27: 자사 | J27: 일반 | L27: O | M27: N | N27: =상품Data!H23 -> 2000000016 | O27: =상품Data!S23 -> 10000 | P27: 2 | Q27: =O27*P27 -> 20000 | R27: =SUM(Q27:Q28) -> 38000 | S27: =프로모션Data!C15 -> 상품 사은품 지급 | T27: =프로모션Data!D15 -> 1234567900 | U27: =프로모션Data!E15 -> [전체] 상품 사은품_사은품명(사은품번호) | X27: =SUM(W27:W28) -> 0 | Y27: =쿠폰Data!C10 -> 할인쿠폰 | Z27: =쿠폰Data!D10 -> 플러스 | AA27: =쿠폰Data!E10 -> 자사 | AB27: =쿠폰Data!F10 -> A12345683 | AC27: =쿠폰Data!G10 -> [플러스/자사/통합멤버십] 3,000원 정액 할인 | AE27: 3000 | AF27: =SUM(AE27:AE28) -> 3000 | AG27: =O27-W27-AE27 -> 7000 | AH27: 편의점 | AI27: 자사 | AJ27: 무료배송상품 | AK27: 0 | AL27: =SUM(AK27:AK28) -> 0 | AM27: =R27-X27-AF27+AL27 -> 35000 | AO27: 5000 | AQ27: 무통장 입금 | AS27: =AM27-AN27-AO27-AP27 -> 30000 | AW27: O | BE27: 프론트 | BF27: 자사 | BG27: 부분교환 | BJ27: 환불금액 차감 | BO27: O | BP27: 무통장 입금
G28: GS | H28: 자사 | J28: 일반 | M28: N | N28: =상품Data!H24 -> 2000000017 | O28: =상품Data!S24 -> 9000 | P28: 2 | Q28: =O28*P28 -> 18000 | AG28: =O28-W28-AE28 -> 9000 | AM28: =R28-X28-AF28+AL28 -> 0 | BE28: 프론트 | BF28: 자사 | BG28: 부분반품 | BJ28: 환불금액 차감
B29: 12 | C29: IT-OC-012 | D29: A-RT | E29: 통합멤버십 | G29: ABC-Mart | H29: 자사 | J29: 일반 | M29: N | N29: =상품Data!H25 -> 2000000018 | O29: =상품Data!S25 -> 8000 | P29: 2 | Q29: =O29*P29 -> 16000 | R29: =SUM(Q29:Q31) -> 38000 | S29: =프로모션Data!C7 -> 즉시할인 | T29: =프로모션Data!D7 -> 1234567892 | U29: =프로모션Data!E7 -> [통합멤버십] 즉시할인_20% 정률 할인 | V29: 0.2 | W29: =ROUNDUP(Q29*V29, -2) -> 3200 | X29: =SUM(W29:W31) -> 3200 | Y29: =쿠폰Data!C6 -> 할인쿠폰 | Z29: =쿠폰Data!D6 -> 일반 | AA29: =쿠폰Data!E6 -> 자사 | AB29: =쿠폰Data!F6 -> A12345679 | AC29: =쿠폰Data!G6 -> [일반/자사/통합멤버십] 3,000원 정액 할인 | AE29: 3000 | AF29: =SUM(AE29:AE31) -> 3000 | AG29: =O29-W29-AE29 -> 1800 | AH29: 택배 | AI29: 자사 | AK29: 2500 | AL29: =SUM(AK29:AK31) -> 2500 | AM29: =R29-X29-AF29+AL29 -> 34300 | AN29: 30000 | AO29: 4300 | AS29: =AM29-AN29-AO29-AP29 -> 0 | BF29: 자사 | BL29: O | BM29: O | BN29: O
G30: A-RT | H30: 입점 | I30: VD20000001 | J30: 일반 | M30: N | N30: =상품Data!H26 -> 2000000019 | O30: =상품Data!S26 -> 11000 | P30: 2 | Q30: =O30*P30 -> 22000 | Y30: =쿠폰Data!C17 -> 무료배송쿠폰 | Z30: =쿠폰Data!D17 -> - | AA30: =쿠폰Data!E17 -> 입점 | AB30: =쿠폰Data!F17 -> A12345690 | AC30: =쿠폰Data!G17 -> [입점] 배송비 무료 | AG30: =O30-W30-AE30 -> 11000 | AH30: 택배 | AI30: 입점 | AJ30: 무료배송쿠폰 | AK30: 0 | AM30: =R30-X30-AF30+AL30 -> 0 | BE30: 프론트 | BF30: 입점 | BG30: 전체반품 | BJ30: 무료반품쿠폰
G31: A-RT | H31: 입점 | I31: VD20000001 | N31: 1234567911 | Y31: =쿠폰Data!C21 -> 무료반품쿠폰 | Z31: =쿠폰Data!D21 -> - | AA31: =쿠폰Data!E21 -> 입점 | AB31: =쿠폰Data!F21 -> A12345694 | AC31: =쿠폰Data!G21 -> [입점] 반품배송비 무료 | AM31: =R31-X31-AF31+AL31 -> 0
B32: 13 | C32: IT-OC-013 | D32: A-RT | E32: 통합멤버십 | G32: A-RT | H32: 입점 | I32: VD20000003 | J32: 일반 | M32: N | N32: =상품Data!H27 -> 2000000020 | O32: =상품Data!S27 -> 33000 | P32: 1 | Q32: =O32*P32 -> 33000 | R32: =Q32 -> 33000 | X32: =W32 -> 0 | Y32: =쿠폰Data!C8 -> 할인쿠폰 | Z32: =쿠폰Data!D8 -> 일반 | AA32: =쿠폰Data!E8 -> 입점 | AB32: =쿠폰Data!F8 -> A12345681 | AC32: =쿠폰Data!G8 -> [일반/입점/통합멤버십]5,000원 정액 할인 | AE32: 5000 | AF32: =AE32 -> 5000 | AG32: =O32-W32-AE32 -> 28000 | AH32: 택배 | AI32: 입점 | AJ32: 3만원 이상 | AK32: 0 | AL32: =AK32 -> 0 | AM32: =R32-X32-AF32+AL32 -> 28000 | AQ32: 카카오페이 | AS32: =AM32-AN32-AO32-AP32 -> 28000 | AV32: O | BE32: 고객센터 | BF32: 입점 | BG32: 전체취소 | BP32: 카카오페이
B33: 14 | C33: IT-OC-014 | D33: OTS | E33: 비회원 | G33: OTS | H33: 자사 | J33: 일반 | M33: N | N33: =상품Data!H28 -> 2000000021 | O33: =상품Data!S28 -> 14000 | P33: 1 | Q33: =O33*P33 -> 14000 | R33: =Q33 -> 14000 | S33: =프로모션Data!C10 -> 기간한정 특가 | T33: =프로모션Data!D10 -> 1234567895 | U33: =프로모션Data!E10 -> [전체] 기간한정_5,000원 정액 할인 | W33: 5000 | X33: =W33 -> 5000 | AF33: =AE33 -> 0 | AG33: =O33-W33-AE33 -> 9000 | AH33: 택배 | AI33: 자사 | AK33: 2500 | AL33: =AK33 -> 2500 | AM33: =R33-X33-AF33+AL33 -> 11500 | AQ33: 신용카드 | AS33: =AM33-AN33-AO33-AP33 -> 11500 | AV33: O | AX33: O | BE33: 프론트 | BF33: 자사 | BG33: 전체취소 | BP33: 신용카드
B34: 15 | C34: IT-OC-015 | D34: OTS | E34: 비회원 | G34: OTS | H34: 자사 | J34: 일반 | L34: O | M34: N | N34: =상품Data!H29 -> 2000000022 | O34: =상품Data!S29 -> 43000 | P34: 1 | Q34: =O34*P34 -> 43000 | R34: =SUM(Q34:Q35) -> 65000 | X34: =SUM(W34:W35) -> 0 | AF34: =SUM(AE34:AE35) -> 0 | AG34: =O34-W34-AE34 -> 43000 | AH34: 편의점 | AI34: 자사 | AJ34: 무료배송상품 | AK34: 0 | AL34: =SUM(AK34:AK35) -> 0 | AM34: =R34-X34-AF34+AL34 -> 65000 | AQ34: 휴대폰결제 | AS34: =AM34-AN34-AO34-AP34 -> 65000 | AX34: O | BE34: 고객센터 | BF34: 자사 | BG34: 부분취소 | BI34: O | BP34: 휴대폰결제
G35: OTS | H35: 자사 | J35: 일반 | M35: N | N35: =상품Data!H30 -> 2000000023 | O35: =상품Data!S30 -> 11000 | P35: 2 | Q35: =O35*P35 -> 22000 | AG35: =O35-W35-AE35 -> 11000 | AM35: =R35-X35-AF35+AL35 -> 0
B36: 16 | C36: IT-OC-016 | D36: OTS | E36: 온라인회원 | G36: OTS | H36: 자사 | J36: 일반 | K36: O | M36: N | N36: =상품Data!H31 -> 2000000024 | O36: =상품Data!S31 -> 69000 | P36: 2 | Q36: =O36*P36 -> 138000 | R36: =Q36 -> 138000 | X36: =W36 -> 0 | Y36: =쿠폰Data!C23 -> 품절보상쿠폰 | Z36: =쿠폰Data!D23 -> 플러스 | AA36: =쿠폰Data!E23 -> 자사 | AB36: =쿠폰Data!F23 -> A12345696 | AC36: =쿠폰Data!G23 -> [자사] 품절보상 / 20% 정률 할인 / 상품갯수 제한 없음 | AD36: 0.2 | AE36: =ROUNDUP((Q36-W36)*AD36, -2) -> 27600 | AF36: =SUM(AE36:AE37) -> 27600 | AG36: =O36-W36-AE36 -> 41400 | AH36: 픽업 | AI36: 자사 | AJ36: 무료배송쿠폰 | AK36: 0 | AL36: =SUM(AK36:AK37) -> 0 | AM36: =R36-X36-AF36+AL36 -> 110400 | AQ36: 신용카드 | AS36: =AM36-AN36-AO36-AP36 -> 110400 | AV36: O | BE36: 프론트 | BF36: 자사 | BG36: 전체교환 | BJ36: 신용카드 | BP36: 신용카드
G37: OTS | H37: 자사 | N37: 1234567916 | Y37: =쿠폰Data!C16 -> 무료배송쿠폰 | Z37: =쿠폰Data!D16 -> - | AA37: =쿠폰Data!E16 -> 자사 | AB37: =쿠폰Data!F16 -> A12345689 | AC37: =쿠폰Data!G16 -> [자사] 배송비 무료
B38: 17 | C38: IT-OC-017 | D38: OTS | E38: 온라인회원 | G38: OTS | H38: 자사 | J38: 일반 | M38: N | N38: =상품Data!H32 -> 2000000025 | O38: =상품Data!S32 -> 17000 | P38: 1 | Q38: =O38*P38 -> 17000 | R38: =Q38 -> 17000 | S38: =프로모션Data!C6 -> 즉시할인 | T38: =프로모션Data!D6 -> 1234567891 | U38: =프로모션Data!E6 -> [회원] 즉시할인_3,000원 정액 할인 | W38: 3000 | X38: =W38 -> 3000 | Y38: =쿠폰Data!C5 -> 할인쿠폰 | Z38: =쿠폰Data!D5 -> 일반 | AA38: =쿠폰Data!E5 -> 자사 | AB38: =쿠폰Data!F5 -> A12345678 | AC38: =쿠폰Data!G5 -> [일반/자사/온라인] 20% 정률 할인(최대금액 제한없음) | AD38: 0.2 | AE38: =ROUNDUP((Q38-W38)*AD38, -2) -> 2800 | AF38: =AE38 -> 2800 | AG38: =O38-W38-AE38 -> 11200 | AH38: 편의점 | AI38: 자사 | AK38: 2500 | AL38: =AK38 -> 2500 | AM38: =R38-X38-AF38+AL38 -> 13700 | AN38: 3700 | AQ38: 카카오페이 | AS38: =AM38-AN38-AO38-AP38 -> 10000 | AV38: O | AW38: O | BE38: 고객센터 | BF38: 자사 | BG38: 전체반품 | BI38: O | BJ38: 환불금액 차감 | BL38: O | BM38: O | BP38: 카카오페이
B39: 18 | C39: IT-OC-018 | D39: OTS | E39: 임직원 | G39: OTS | H39: 자사 | J39: 일반 | M39: N | N39: =상품Data!H33 -> 1000000004 | O39: =상품Data!S33 -> 22000 | P39: 2 | Q39: =O39*P39 -> 44000 | W39: =Q39*V39 -> 0 | AG39: =O39-W39-AE39 -> 22000 | AH39: 편의점 | AI39: 자사 | AK39: 2500 | AM39: =R39-X39-AF39+AL39 -> 0 | AQ39: 네이버페이 | AS39: =AM39-AN39-AO39-AP39 -> 0 | AV39: O | BE39: 고객센터 | BF39: 자사 | BG39: 전체취소 | BP39: 네이버페이
B40: 19 | C40: IT-OC-019 | D40: OTS | E40: 임직원 | G40: OTS | H40: 자사 | J40: 일반 | L40: O | M40: N | N40: =상품Data!H34 -> 2000000026 | O40: =상품Data!S34 -> 22000 | P40: 1 | Q40: =O40*P40 -> 22000 | R40: =SUM(Q40:Q41) -> 38000 | S40: =프로모션Data!C8 -> 즉시할인 | T40: =프로모션Data!D8 -> 1234567893 | U40: =프로모션Data!E8 -> [임직원] 임직원 할인_50% 정률 할인 | V40: 0.5 | W40: =ROUNDUP(Q40*V40, -2) -> 11000 | X40: =SUM(W40:W41) -> 11000 | AF40: =SUM(AE40:AE41) -> 0 | AG40: =O40-W40-AE40 -> 11000 | AH40: 택배 | AI40: 자사 | AJ40: 무료배송상품 | AK40: 0 | AL40: =SUM(AK40:AK41) -> 0 | AM40: =R40-X40-AF40+AL40 -> 27000 | AQ40: 실시간 계좌이체 | AR40: O | AS40: =AM40-AN40-AO40-AP40 -> 27000 | AW40: O | BE40: 프론트 | BF40: 자사 | BG40: 부분반품 | BI40: O | BJ40: 실시간 계좌이체 | BP40: 실시간 계좌이체
G41: OTS | H41: 자사 | J41: 일반 | M41: N | N41: =상품Data!H35 -> 2000000027 | O41: =상품Data!S35 -> 8000 | P41: 2 | Q41: =O41*P41 -> 16000 | W41: =Q41*V41 -> 0 | AG41: =O41-W41-AE41 -> 8000 | AM41: =R41-X41-AF41+AL41 -> 0
B42: 20 | C42: IT-OC-020 | D42: OTS | E42: 통합멤버십 | G42: OTS | H42: 자사 | J42: 예약 | M42: Y | N42: =상품Data!H36 -> 2000000028 | O42: =상품Data!S36 -> 9000 | P42: 2 | Q42: =O42*P42 -> 18000 | R42: =Q42 -> 18000 | X42: =W42 -> 0 | Y42: =쿠폰Data!C14 -> 제휴사 할인쿠폰 | Z42: =쿠폰Data!D14 -> 플러스 | AA42: =쿠폰Data!E14 -> 자사 | AB42: =쿠폰Data!F14 -> A12345687 | AC42: =쿠폰Data!G14 -> [플러스/자사/회원] 1,000원 정액 할인 | AE42: 1000 | AF42: =AE42 -> 1000 | AG42: =O42-W42-AE42 -> 8000 | AH42: 편의점 | AI42: 자사 | AK42: 2500 | AL42: =AK42 -> 2500 | AM42: =R42-X42-AF42+AL42 -> 19500 | AN42: 10000 | AO42: 500 | AQ42: 실시간 계좌이체 | AS42: =AM42-AN42-AO42-AP42 -> 9000 | AW42: O | BE42: 프론트 | BF42: 자사 | BG42: 부분취소 | BL42: O | BM42: O | BN42: O | BP42: 실시간 계좌이체
B43: 21 | C43: IT-OC-021 | D43: OTS | E43: 통합멤버십 | G43: OTS | H43: 자사 | J43: 일반 | K43: O | M43: N | N43: =상품Data!H37 -> 2000000029 | O43: =상품Data!S37 -> 10000 | P43: 1 | Q43: =O43*P43 -> 10000 | R43: =SUM(Q43:Q45) -> 22000 | S43: =프로모션Data!C16 -> 상품 사은품 지급 | T43: =프로모션Data!D16 -> 1234567901 | U43: =프로모션Data!E16 -> [비회원 제외] 상품 사은품_사은품명(사은품번호) | X43: =SUM(W43:W45) -> 0 | Y43: =쿠폰Data!C6 -> 할인쿠폰 | Z43: =쿠폰Data!D6 -> 일반 | AA43: =쿠폰Data!E6 -> 자사 | AB43: =쿠폰Data!F6 -> A12345679 | AC43: =쿠폰Data!G6 -> [일반/자사/통합멤버십] 3,000원 정액 할인 | AE43: 3000 | AF43: =SUM(AE43:AE45) -> 5400 | AG43: =O43-W43-AE43 -> 7000 | AH43: 택배 | AI43: 자사 | AK43: 2500 | AL43: =SUM(AK43:AK45) -> 2500 | AM43: =R43-X43-AF43+AL43 -> 19100 | AO43: 100 | AS43: =AM43-AN43-AO43-AP43 -> 19000 | BE43: 고객센터 | BF43: 자사 | BG43: 부분교환 | BI43: O | BJ43: 무료교환쿠폰 | BO43: O
G44: OTS | H44: 자사 | N44: 1234567922 | Y44: =쿠폰Data!C18 -> 무료교환쿠폰 | Z44: =쿠폰Data!D18 -> - | AA44: =쿠폰Data!E18 -> 자사 | AB44: =쿠폰Data!F18 -> A12345691 | AC44: =쿠폰Data!G18 -> [자사] 교환배송비 무료 | AM44: =R44-X44-AF44+AL44 -> 0
G45: OTS | H45: 자사 | J45: 일반 | M45: N | N45: =상품Data!$H$38 -> 2000000030 | O45: =상품Data!$S$38 -> 4000 | P45: 3 | Q45: =O45*P45 -> 12000 | Y45: =쿠폰Data!C22 -> 품절보상쿠폰 | Z45: =쿠폰Data!D22 -> 플러스 | AA45: =쿠폰Data!E22 -> 자사 | AB45: =쿠폰Data!F22 -> A12345695 | AC45: =쿠폰Data!G22 -> [자사] 품절보상 / 20% 정률 할인 / 1개 단품만 적용 가능 | AD45: 0.2 | AE45: =ROUNDUP((Q45-W45)*AD45, -2) -> 2400 | AG45: =O45-W45-AE45 -> 1600 | AM45: =R45-X45-AF45+AL45 -> 0

Sheet 2-1_AS 목록
B7: 통합테스트 시나리오 목록
B9: No. | C9: 프로세스 | D9: 시나리오 ID | E9: 시나리오명 | F9: 비고
B10: 1 | C10: AS 심의 | D10: IT-AS-001 | E10: AS 심의 정상 진행 프로세스
B11: 2 | D11: IT-AS-002 | E11: AS 심의 신청 자동 취소
B12: 3 | D12: IT-AS-003 | E12: AS 심의 신청 후 AS 수선 전환
B13: 4 | D13: IT-AS-004 | E13: AS 심의 불가 처리 후 교환 클레임 생성
B14: 5 | C14: AS 수선 | D14: IT-AS-005 | E14: AS 수선 정상 진행 프로세스
B15: 6 | D15: IT-AS-006 | E15: AS 수선 신청 자동 취소
B16: 7 | D16: IT-AS-007 | E16: AS 수선 불가 처리 후 반품 클레임 생성

Sheet 2-2_AS
B2: 참조 문서 | C2: ABC_04.설계_03.프로세스정의서_06.클레임 AS_20190430_v1.10.pptx
B4: 프로세스
B34: 시나리오 순서
B35: 1. AS 심의 정상 진행 프로세스 (IT-AS-001) : 1-1 -> 2 -> 3 -> 4 -> 5 -> 6 -> 7 2. AS 심의 신청 자동 취소 (IT-AS-002) : 1-1 -> 2 -> 3 -> 8 3. AS 심의 신청 후 AS 수선 전환 (IT-AS-003) : 1-1 -> 2 -> 3 -> 4 -> 5 -> 9 -> 10 -> 6 -> 7 4. AS 심의 불가 처리 후 교환 클레임 생성 (IT-AS-004) : 1-1 -> 2 -> 3 -> 4 -> 5 -> 11 -> 12 5. AS 수선 정상 진행 프로세스 (IT-AS-005) : 1-2 -> 2 -> 3 -> 4 -> 5 -> 9 -> 10 -> 6 -> 7 6. AS 수선 신청 자동 취소 (IT-AS-006) : 1-2 -> 2 -> 3 -> 8 7. AS 수선 불가 처리 후 반품 클레임 생성 (IT-AS-007) : 1-2 -> 2 -> 3 -> 4 -> 5 -> 11 -> 12
B36: 테스트 사전 준비사항
B37: AS 신청을 위한 1년 이내 주문번호 7개, 주문회원 ID/Password, AS 접수/처리 가능한 BO ID/Password
B39: No. | C39: 사이트 | D39: ID | E39: 시나리오명 | F39: SYS | G39: 중요도 | H39: 테스트 항목 | I39: 수행 절차 | J39: 입력값 | K39: 기대 결과 | L39: 수행일자 | M39: 수행자 | N39: 테스트결과 | O39: 수정여부 | P39: 비고
B40: =ROW()-39 -> 1 | C40: A-RT | D40: IT-AS-001-001 | E40: AS 심의 정상 진행 프로세스 | F40: FO | G40: 중 | H40: AS 심의 신청 | I40: 1. PC Front 로그인 2. 마이페이지 > 쇼핑내역 > 반품/교환/AS 메뉴로 이동 3. AS신청 탭에서 AS 신청할 주문번호 선택 4. '심의' AS 로 선택한 후 관련 입력항목 등록 후 '신청' 버튼 클릭 | J40: 1. ID/Password : 3. 주문번호 : | K40: 필수항목 모두 입력시, "신청이 완료되었습니다." Alert 노출 후 신청내역 화면으로 전환되고 AS 접수번호가 노출됨. AS 접수번호 :
B41: =ROW()-39 -> 2 | C41: A-RT | D41: IT-AS-001-002 | E41: AS 심의 정상 진행 프로세스 | F41: BO | G41: 중 | H41: AS 심의 신청 내용 확인 및 수거지시 | I41: 1. BO 로그인 2. 주문관리 > 클레임관리 > AS관리 메뉴로 이동 3. 'IT-AS-001-001'에서 신청한 AS 접수번호 검색 및 선택 4. AS 내역 확인 후 '수거지시' 버튼 클릭 | J41: 1. ID/Password : 3. AS 접수번호 : | K41: "AS 상품의 수거지시가 완료되었습니다" Alert 노출 후 AS 진행 상태가 '수거지시'로 조회됨.
B42: =ROW()-39 -> 3 | C42: A-RT | D42: IT-AS-001-003 | E42: AS 심의 정상 진행 프로세스 | F42: BO | G42: 중 | H42: AS 상품 수령 | I42: 0. BO 로그인 상태 유지 1. '상품 수령' 버튼 클릭 | K42: "AS 상품이 수령 완료되었습니다" Alert 노출 후 AS 진행 상태가 '수령완료'로 조회됨.
B43: =ROW()-39 -> 4 | C43: A-RT | D43: IT-AS-001-004 | E43: AS 심의 정상 진행 프로세스 | F43: BO | G43: 중 | H43: AS 상품 심의 완료 | I43: 0. BO 로그인 상태 유지 1. 심의 결과를 입력하고, '심의완료' 버튼 클릭 | K43: "AS 상품이 심의 완료되었습니다" Alert 노출 후 AS 진행 상태가 '심의완료'로 조회됨.
B44: =ROW()-39 -> 5 | C44: A-RT | D44: IT-AS-001-005 | E44: AS 심의 정상 진행 프로세스 | F44: BO | G44: 중 | H44: AS 상품 반송 처리 | I44: 0. BO 로그인 상태 유지 1. 고객 협의 결과를 입력하고, '반송' 버튼 클릭 | K44: "AS 상품이 반송 처리되었습니다" Alert 노출. 이후 송장번호가 입력되면, AS 진행 상태가 '배송중'으로 조회됨.
B45: =ROW()-39 -> 6 | C45: A-RT | D45: IT-AS-001-006 | E45: AS 심의 정상 진행 프로세스 | F45: FO | G45: 하 | H45: AS 완료 | I45: 1. PC Front 로그인 2. 마이페이지 > 쇼핑내역 > 반품/교환/AS 메뉴로 이동 3. AS현황 탭에서 신청한 AS내역 조회 | J45: 1. ID/Password : 3. AS 접수번호 : | K45: AS 진행 상태가 'AS 배송중'으로 조회됨. AS 상품 수령 후에는 'AS완료'로 조회됨.
B46: =ROW()-39 -> 7 | C46: A-RT | D46: IT-AS-002-001 | E46: AS 심의 신청 자동 취소 | F46: FO | G46: 중 | H46: AS 심의 신청 | I46: 1. PC Front 로그인 2. 마이페이지 > 쇼핑내역 > 반품/교환/AS 메뉴로 이동 3. AS신청 탭에서 AS 신청할 주문번호 선택 4. '심의' AS 로 선택한 후 관련 입력항목 등록 후 '신청' 버튼 클릭 | J46: 1. ID/Password : 3. 주문번호 : | K46: 필수항목 모두 입력시, "신청이 완료되었습니다." Alert 노출 후 신청내역 화면으로 전환되고 AS 접수번호가 노출됨. AS 접수번호 :
B47: =ROW()-39 -> 8 | C47: A-RT | D47: IT-AS-002-002 | E47: AS 심의 신청 자동 취소 | F47: BO | G47: 중 | H47: AS 심의 신청 내용 확인 및 수거지시 | I47: 1. BO 로그인 2. 주문관리 > 클레임관리 > AS관리 메뉴로 이동 3. 'IT-AS-002-001'에서 신청한 AS 접수번호 검색 및 선택 4. AS 내역 확인 후 '수거지시' 버튼 클릭 | J47: 1. ID/Password : 3. AS 접수번호 : | K47: "AS 상품의 수거지시가 완료되었습니다" Alert 노출 후 AS 진행 상태가 '수거지시'로 조회됨.
B48: =ROW()-39 -> 9 | C48: A-RT | D48: IT-AS-002-003 | E48: AS 심의 신청 자동 취소 | F48: FO | G48: 중 | H48: AS 접수 자동 취소 | I48: 0. 'IT-AS-002-001'에서 AS 신청 이후 15일 내에 AS 상품 발송 안함. 1. PC Front 로그인 2. 마이페이지 > 쇼핑내역 > 반품/교환/AS 메뉴로 이동 3. AS현황 탭에서 신청한 AS내역 조회 | J48: 1. ID/Password : 3. AS 접수번호 : | K48: AS 진행 상태가 'AS접수취소'로 조회됨.
B49: =ROW()-39 -> 10 | C49: A-RT | D49: IT-AS-003-001 | E49: AS 심의 신청 후 AS 수선 전환 | F49: FO | G49: 중 | H49: AS 심의 신청 | I49: 1. PC Front 로그인 2. 마이페이지 > 쇼핑내역 > 반품/교환/AS 메뉴로 이동 3. AS신청 탭에서 AS 신청할 주문번호 선택 4. '심의' AS 로 선택한 후 관련 입력항목 등록 후 '신청' 버튼 클릭 | J49: 1. ID/Password : 3. 주문번호 : | K49: 필수항목 모두 입력시, "신청이 완료되었습니다." Alert 노출 후 신청내역 화면으로 전환되고 AS 접수번호가 노출됨. AS 접수번호 :
B50: =ROW()-39 -> 11 | C50: A-RT | D50: IT-AS-003-002 | E50: AS 심의 신청 후 AS 수선 전환 | F50: BO | G50: 중 | H50: AS 심의 신청 내용 확인 및 수거지시 | I50: 1. BO 로그인 2. 주문관리 > 클레임관리 > AS관리 메뉴로 이동 3. 'IT-AS-001-001'에서 신청한 AS 접수번호 검색 및 선택 4. AS 내역 확인 후 '수거지시' 버튼 클릭 | J50: 1. ID/Password : 3. AS 접수번호 : | K50: "AS 상품의 수거지시가 완료되었습니다" Alert 노출 후 AS 진행 상태가 '수거지시'로 조회됨.
B51: =ROW()-39 -> 12 | C51: A-RT | D51: IT-AS-003-003 | E51: AS 심의 신청 후 AS 수선 전환 | F51: BO | G51: 중 | H51: AS 상품 수령 | I51: 0. BO 로그인 상태 유지 1. '상품 수령' 버튼 클릭 | K51: "AS 상품이 수령 완료되었습니다" Alert 노출 후 AS 진행 상태가 '수령완료'로 조회됨.
B52: =ROW()-39 -> 13 | C52: A-RT | D52: IT-AS-003-004 | E52: AS 심의 신청 후 AS 수선 전환 | F52: BO | G52: 중 | H52: AS 상품 수선 완료 | I52: 0. BO 로그인 상태 유지 1. AS 유형을 '수선'으로 변경하고, 수선 결과 입력 후 '수선완료' 버튼 클릭 | K52: "AS 상품이 수선 완료되었습니다" Alert 노출 후 AS 진행 상태가 '수선완료'로 조회됨.
B53: =ROW()-39 -> 14 | C53: A-RT | D53: IT-AS-003-005 | E53: AS 심의 신청 후 AS 수선 전환 | F53: BO | G53: 중 | H53: AS 비용 청구 | I53: 0. BO 로그인 상태 유지 1. AS 수선비와 배송비 등 비용을 입력하고, '비용결제요청' 버튼 클릭 | K53: "AS 비용 결제요청이 완료되었습니다" Alert 노출 후 AS 진행 상태가 '비용결제요청'으로 조회됨.
B54: =ROW()-39 -> 15 | C54: A-RT | D54: IT-AS-003-006 | E54: AS 심의 신청 후 AS 수선 전환 | F54: FO | G54: 상 | H54: AS 비용 결제 | I54: 0. 'IT-AS-003-005'에서 요청한 비용을 AS 입금 대표계좌로 입금 1. PC Front 로그인 2. 마이페이지 > 쇼핑내역 > 반품/교환/AS 메뉴로 이동 3. AS현황 탭에서 신청한 AS내역 조회 | K54: AS 진행 상태가 '비용결제완료'로 조회됨.
B55: =ROW()-39 -> 16 | C55: A-RT | D55: IT-AS-003-007 | E55: AS 심의 신청 후 AS 수선 전환 | F55: BO | G55: 중 | H55: AS 상품 배송 처리 | I55: 0. BO 로그인 상태 유지 1. AS 진행 상태가 '비용결제완료' 인지 확인 후, '발송' 버튼 클릭 | K55: "AS 상품이 발송 처리되었습니다" Alert 노출. 이후 송장번호가 입력되면, AS 진행 상태가 '배송중'으로 조회됨.
B56: =ROW()-39 -> 17 | C56: A-RT | D56: IT-AS-003-008 | E56: AS 심의 신청 후 AS 수선 전환 | F56: FO | G56: 하 | H56: AS 완료 | I56: 1. PC Front 로그인 2. 마이페이지 > 쇼핑내역 > 반품/교환/AS 메뉴로 이동 3. AS현황 탭에서 신청한 AS내역 조회 | J56: 1. ID/Password : 3. AS 접수번호 : | K56: AS 진행 상태가 'AS 배송중'으로 조회됨. AS 상품 수령 후에는 'AS완료'로 조회됨.
B57: =ROW()-39 -> 18 | C57: A-RT | D57: IT-AS-004-001 | E57: AS 심의 불가 처리 후 교환 클레임 생성 | F57: FO | G57: 중 | H57: AS 심의 신청 | I57: 1. PC Front 로그인 2. 마이페이지 > 쇼핑내역 > 반품/교환/AS 메뉴로 이동 3. AS신청 탭에서 AS 신청할 주문번호 선택 4. '심의' AS 로 선택한 후 관련 입력항목 등록 후 '신청' 버튼 클릭 | J57: 1. ID/Password : 3. 주문번호 : | K57: 필수항목 모두 입력시, "신청이 완료되었습니다." Alert 노출 후 신청내역 화면으로 전환되고 AS 접수번호가 노출됨. AS 접수번호 :
B58: =ROW()-39 -> 19 | C58: A-RT | D58: IT-AS-004-002 | E58: AS 심의 불가 처리 후 교환 클레임 생성 | F58: BO | G58: 중 | H58: AS 심의 신청 내용 확인 및 수거지시 | I58: 1. BO 로그인 2. 주문관리 > 클레임관리 > AS관리 메뉴로 이동 3. 'IT-AS-004-001'에서 신청한 AS 접수번호 검색 및 선택 4. AS 내역 확인 후 '수거지시' 버튼 클릭 | J58: 1. ID/Password : 3. AS 접수번호 : | K58: "AS 상품의 수거지시가 완료되었습니다" Alert 노출 후 AS 진행 상태가 '수거지시'로 조회됨.
B59: =ROW()-39 -> 20 | C59: A-RT | D59: IT-AS-004-003 | E59: AS 심의 불가 처리 후 교환 클레임 생성 | F59: BO | G59: 중 | H59: AS 상품 수령 | I59: 0. BO 로그인 상태 유지 1. '상품 수령' 버튼 클릭 | K59: "AS 상품이 수령 완료되었습니다" Alert 노출 후 AS 진행 상태가 '수령완료'로 조회됨.
B60: =ROW()-39 -> 21 | C60: A-RT | D60: IT-AS-004-004 | E60: AS 심의 불가 처리 후 교환 클레임 생성 | F60: BO | G60: 중 | H60: AS 상품 심의 완료 | I60: 0. BO 로그인 상태 유지 1. 심의 결과를 입력하고, '심의완료' 버튼 클릭 | K60: "AS 상품이 심의 완료되었습니다" Alert 노출 후 AS 진행 상태가 '심의완료'로 조회됨.
B61: =ROW()-39 -> 22 | C61: A-RT | D61: IT-AS-004-005 | E61: AS 심의 불가 처리 후 교환 클레임 생성 | F61: BO | G61: 중 | H61: AS 상품 교환 처리 | I61: 0. BO 로그인 상태 유지 1. 고객 협의 결과를 입력하고, 'AS불가 > 교환 접수' 선택 후 '저장' 버튼 클릭 | K61: "AS 상품이 교환 접수되었습니다" Alert 노출 후, AS 진행 상태가 'AS불가'로 조회됨.
B62: =ROW()-39 -> 23 | C62: A-RT | D62: IT-AS-004-006 | E62: AS 심의 불가 처리 후 교환 클레임 생성 | F62: FO | G62: 상 | H62: AS불가 후 교환 클레임 생성 확인 | I62: 1. PC Front 로그인 2. 마이페이지 > 쇼핑내역 > 반품/교환/AS 메뉴로 이동 3. AS현황 탭에서 신청한 AS내역 조회 4. 교환현황 탭에서 교환 클레임 내역 확인 | J62: 1. ID/Password : 3. AS 접수번호 : | K62: 3. AS현황 탭에서 AS 진행 상태가 'AS불가'로 조회됨. 4. 교환현황 탭에서 AS 신청 상품에 대한 교환 클레임 생성 내역이 조회됨.
B63: =ROW()-39 -> 24 | C63: OTS | D63: IT-AS-005-001 | E63: AS 수선 정상 진행 프로세스 | F63: MO | G63: 상 | H63: AS 수선 신청 | I63: 1. Mobile Front 로그인 2. 마이페이지 > 쇼핑내역 > 반품/교환/AS 메뉴로 이동 3. AS신청 탭에서 AS 신청할 주문번호 선택 4. '수선' AS 로 선택한 후 관련 입력항목 등록 및 왕복배송비를 신용카드로 결제하고 '신청' 버튼 클릭 | J63: 1. ID/Password : 3. 주문번호 : | K63: 필수항목 모두 입력시, "신청이 완료되었습니다." Alert 노출 후 신청내역 화면으로 전환되고 AS 접수번호가 노출됨. AS 접수번호 :
B64: =ROW()-39 -> 25 | C64: OTS | D64: IT-AS-005-002 | E64: AS 수선 정상 진행 프로세스 | F64: BO | G64: 중 | H64: AS 수선 신청 내용 확인 및 수거지시 | I64: 1. BO 로그인 2. 주문관리 > 클레임관리 > AS관리 메뉴로 이동 3. 'IT-AS-005-001'에서 신청한 AS 접수번호 검색 및 선택 4. AS 내역 확인 후 '수거지시' 버튼 클릭 | J64: 1. ID/Password : 3. AS 접수번호 : | K64: "AS 상품의 수거지시가 완료되었습니다" Alert 노출 후 AS 진행 상태가 '수거지시'로 조회됨.
B65: =ROW()-39 -> 26 | C65: OTS | D65: IT-AS-005-003 | E65: AS 수선 정상 진행 프로세스 | F65: BO | G65: 중 | H65: AS 상품 수령 | I65: 0. BO 로그인 상태 유지 1. '상품 수령' 버튼 클릭 | K65: "AS 상품이 수령 완료되었습니다" Alert 노출 후 AS 진행 상태가 '수령완료'로 조회됨.
B66: =ROW()-39 -> 27 | C66: OTS | D66: IT-AS-005-004 | E66: AS 수선 정상 진행 프로세스 | F66: BO | G66: 중 | H66: AS 상품 수선 완료 | I66: 0. BO 로그인 상태 유지 1. 수선 결과를 입력하고, '수선완료' 버튼 클릭 | K66: "AS 상품이 수선 완료되었습니다" Alert 노출 후 AS 진행 상태가 '수선완료'로 조회됨.
B67: =ROW()-39 -> 28 | C67: OTS | D67: IT-AS-005-005 | E67: AS 수선 정상 진행 프로세스 | F67: BO | G67: 중 | H67: AS 비용 청구 | I67: 0. BO 로그인 상태 유지 1. AS 수선비를 입력하고, '비용결제요청' 버튼 클릭 | K67: "AS 비용 결제요청이 완료되었습니다" Alert 노출 후 AS 진행 상태가 '비용결제요청'으로 조회됨.
B68: =ROW()-39 -> 29 | C68: OTS | D68: IT-AS-005-006 | E68: AS 수선 정상 진행 프로세스 | F68: MO | G68: 상 | H68: AS 비용 결제 | I68: 0. 'IT-AS-005-005'에서 요청한 비용을 AS 입금 대표계좌로 입금 1. Mobile Front 로그인 2. 마이페이지 > 쇼핑내역 > 반품/교환/AS 메뉴로 이동 3. AS현황 탭에서 신청한 AS내역 조회 | K68: AS 진행 상태가 '비용결제완료'로 조회됨.
B69: =ROW()-39 -> 30 | C69: OTS | D69: IT-AS-005-007 | E69: AS 수선 정상 진행 프로세스 | F69: BO | G69: 중 | H69: AS 상품 배송 처리 | I69: 0. BO 로그인 상태 유지 1. AS 진행 상태가 '비용결제완료' 인지 확인 후, '발송' 버튼 클릭 | K69: "AS 상품이 발송 처리되었습니다" Alert 노출. 이후 송장번호가 입력되면, AS 진행 상태가 '배송중'으로 조회됨.
B70: =ROW()-39 -> 31 | C70: OTS | D70: IT-AS-005-008 | E70: AS 수선 정상 진행 프로세스 | F70: MO | G70: 하 | H70: AS 완료 | I70: 1. Mobile Front 로그인 2. 마이페이지 > 쇼핑내역 > 반품/교환/AS 메뉴로 이동 3. AS현황 탭에서 신청한 AS내역 조회 | J70: 1. ID/Password : 3. AS 접수번호 : | K70: AS 진행 상태가 'AS 배송중'으로 조회됨. AS 상품 수령 후에는 'AS완료'로 조회됨.
B71: =ROW()-39 -> 32 | C71: OTS | D71: IT-AS-006-001 | E71: AS 수선 신청 자동 취소 | F71: MO | G71: 상 | H71: AS 수선 신청 | I71: 1. Mobile Front 로그인 2. 마이페이지 > 쇼핑내역 > 반품/교환/AS 메뉴로 이동 3. AS신청 탭에서 AS 신청할 주문번호 선택 4. '수선' AS 로 선택한 후 관련 입력항목 등록 및 왕복배송비를 실시간계좌이체로 결제하고 '신청' 버튼 클릭 | J71: 1. ID/Password : 3. 주문번호 : | K71: 필수항목 모두 입력시, "신청이 완료되었습니다." Alert 노출 후 신청내역 화면으로 전환되고 AS 접수번호가 노출됨. AS 접수번호 :
B72: =ROW()-39 -> 33 | C72: OTS | D72: IT-AS-006-002 | E72: AS 수선 신청 자동 취소 | F72: BO | G72: 중 | H72: AS 수선 신청 내용 확인 및 수거지시 | I72: 1. BO 로그인 2. 주문관리 > 클레임관리 > AS관리 메뉴로 이동 3. 'IT-AS-006-001'에서 신청한 AS 접수번호 검색 및 선택 4. AS 내역 확인 후 '수거지시' 버튼 클릭 | J72: 1. ID/Password : 3. AS 접수번호 : | K72: "AS 상품의 수거지시가 완료되었습니다" Alert 노출 후 AS 진행 상태가 '수거지시'로 조회됨.
...

Sheet 회원Data
B3: No. | C3: 회원유형 | D3: ID | E3: Password | F3: Tester | G3: 회원명 | H3: 이메일 | I3: 휴대폰 | J3: 비고
B4: =ROW()-3 -> 1 | C4: 온라인 회원
B5: =ROW()-3 -> 2 | C5: 온라인 회원
B6: =ROW()-3 -> 3 | C6: 온라인 회원
B7: =ROW()-3 -> 4 | C7: 온라인 회원
B8: =ROW()-3 -> 5 | C8: 온라인 회원
B9: =ROW()-3 -> 6 | C9: 통합멤버십 회원
B10: =ROW()-3 -> 7 | C10: 통합멤버십 회원
B11: =ROW()-3 -> 8 | C11: 통합멤버십 회원
B12: =ROW()-3 -> 9 | C12: 통합멤버십 회원
B13: =ROW()-3 -> 10 | C13: 통합멤버십 회원
B14: =ROW()-3 -> 11 | C14: 통합멤버십 회원
B15: =ROW()-3 -> 12 | C15: 통합멤버십 회원
... B23: =ROW()-3 -> 20 | C23: 임직원
B25: * 통합테스트 환경에서 사용 가능한 회원유형별 계정정보 등록, 동일 ID를 2명 이상이 사용하지 않도록 Test 정보 등록

Sheet 입점사Data
B3: No. | C3: 입점업체명 | D3: 입점사 코드(ERP) | E3: 주문 배송비 | G3: 교환 배송비 | I3: 반품 배송비 | L3: 상품
E4: 기준 결제금액 | F4: 배송비 | G4: 기준 | H4: 교환 배송비 | I4: 기준 | J4: 주문 배송 유료 | K4: 주문 배송 무료 | L4: 온라인 상품코드 | M4: 판매자 상품코드 | N4: 상품명 | O4: 시나리오ID
B5: 1 | C5: 입점사1 | D5: VD0001 | E5: 19000 | F5: 3000 | G5: 선불 | H5: 6000 | I5: 선불 | J5: 3000 | K5: 6000 | L5: 2000000004 | M5: VD0001_004 | N5: 2000000004 | O5: IT-OC-002
B6: 2 | L6: 2000000013 | M6: VD0001_013 | N6: 2000000013 | O6: IT-OC-009
B7: 3 | L7: 2000000019 | M7: VD0001_019 | N7: 2000000019 | O7: IT-OC-012
B8: 4 | C8: 입점사2 | D8: VD0002 | E8: 20000 | F8: 3000 | G8: 선불 | H8: 6000 | I8: 선불 | J8: 3000 | K8: 6000 | L8: 2000000008 | M8: VD0002_008 | N8: 2000000008 | O8: IT-OC-005
B9: 5 | L9: 2000000011 | M9: VD0002_011 | N9: 2000000011 | O9: IT-OC-006
B10: 6 | C10: 입점사3 | D10: VD0003 | E10: 20000 | F10: 2500 | G10: 선불 | H10: 5000 | I10: 선불 | J10: 2500 | K10: 5000 | L10: 2000000005 | M10: VD0003_005 | N10: 2000000005 | O10: IT-OC-003
B11: 7 | L11: 2000000010 | M11: VD0003_010 | N11: 2000000010 | O11: IT-OC-006
B12: 8 | L12: 2000000012 | M12: VD0003_012 | N12: 2000000012 | O12: IT-OC-008
B13: 9 | L13: 2000000020 | M13: VD0003_020 | N13: 2000000020 | O13: IT-OC-013

Sheet 상품Data
B3: No. | C3: 공급 방식 | D3: 판매 채널 | E3: 입점사 코드(ERP) | F3: 입점업체명 | G3: 온라인 상품코드 | H3: 온라인 상품코드 | I3: ERP 상품코드 | J3: 판매자 상품코드 | K3: 상품명 | L3: 상품 속성 | R3: 정상가 | S3: 수정정상가 | T3: 임직원가 | U3: 수정임직원가 | V3: 유료 옵션 | AA3: 비고 | AB3: 케이스 ID
L4: 예약상품 | M4: 픽업가능 | N4: 무료배송 | O4: 임직원 할인 제외 | P4: 임직원 할인률 | Q4: 출시 2주 미만 | V4: 유료 옵션 | W4: 유료 옵션명 | X4: 옵션 추가가격 | Y4: 옵션 포함 정상가 | Z4: 옵션포함 임직원가
B5: 1 | C5: 자사 | D5: ABC-Mart | G5: 1234567890 | H5: 2000000001 | I5: 0000001 | K5: 2000000001 | N5: O | P5: 0.5 | R5: 70280 | S5: 69000 | T5: =IF(COUNTA(O5,Q5), R5, P5*R5) -> 35140 | U5: =IF(COUNTA(O5,Q5), S5, P5*S5) -> 34500 | Y5: =IF(COUNTA(V5), S5+X5, S5) -> 69000 | Z5: =_xlfn.IFS(AND(COUNTA(V5), (COUNTA(O5,Q5) = 0)), U5+X5*P5, AND(COUNTA(V5), (COUNTA(O5,Q5) > 0)), U5+X5, TRUE, U5) -> 34500 | AB5: IT-OC-001
B6: 2 | C6: 자사 | D6: ABC-Mart | G6: 1234567891 | H6: 2000000002 | I6: 0000002 | K6: 2000000002 | P6: 0.5 | R6: 11410 | S6: 11000 | T6: =IF(COUNTA(O6,Q6), R6, P6*R6) -> 5705 | U6: =IF(COUNTA(O6,Q6), S6, P6*S6) -> 5500 | Y6: =IF(COUNTA(V6), S6+X6, S6) -> 11000 | Z6: =_xlfn.IFS(AND(COUNTA(V6), (COUNTA(O6,Q6) = 0)), U6+X6*P6, AND(COUNTA(V6), (COUNTA(O6,Q6) > 0)), U6+X6, TRUE, U6) -> 5500 | AB6: IT-OC-001
B7: 3 | C7: 자사 | D7: GS | G7: 1234567892 | H7: 2000000003 | I7: 0000003 | K7: 2000000003 | P7: 0.5 | R7: 8860 | S7: 9000 | T7: =IF(COUNTA(O7,Q7), R7, P7*R7) -> 4430 | U7: =IF(COUNTA(O7,Q7), S7, P7*S7) -> 4500 | Y7: =IF(COUNTA(V7), S7+X7, S7) -> 9000 | Z7: =_xlfn.IFS(AND(COUNTA(V7), (COUNTA(O7,Q7) = 0)), U7+X7*P7, AND(COUNTA(V7), (COUNTA(O7,Q7) > 0)), U7+X7, TRUE, U7) -> 4500 | AB7: IT-OC-002
B8: 4 | C8: 입점 | D8: A-RT | E8: VD0001 | F8: 입점사1 | G8: 1234567893 | H8: 2000000004 | J8: VD0001_004 | K8: 2000000004 | P8: 0.5 | R8: 8660 | S8: 8000 | T8: =IF(COUNTA(O8,Q8), R8, P8*R8) -> 4330 | U8: =IF(COUNTA(O8,Q8), S8, P8*S8) -> 4000 | Y8: =IF(COUNTA(V8), S8+X8, S8) -> 8000 | Z8: =_xlfn.IFS(AND(COUNTA(V8), (COUNTA(O8,Q8) = 0)), U8+X8*P8, AND(COUNTA(V8), (COUNTA(O8,Q8) > 0)), U8+X8, TRUE, U8) -> 4000 | AB8: IT-OC-002
B9: 5 | C9: 입점 | D9: A-RT | E9: VD0003 | F9: 입점사3 | G9: 1234567894 | H9: 2000000005 | J9: VD0003_005 | K9: 2000000005 | P9: 0.5 | R9: 15820 | S9: 15000 | T9: =IF(COUNTA(O9,Q9), R9, P9*R9) -> 7910 | U9: =IF(COUNTA(O9,Q9), S9, P9*S9) -> 7500 | V9: O | W9: 유료옵션1 | X9: 1000 | Y9: =IF(COUNTA(V9), S9+X9, S9) -> 16000 | Z9: =_xlfn.IFS(AND(COUNTA(V9), (COUNTA(O9,Q9) = 0)), U9+X9*P9, AND(COUNTA(V9), (COUNTA(O9,Q9) > 0)), U9+X9, TRUE, U9) -> 8000 | AB9: IT-OC-003
B10: 6 | C10: 자사 | D10: ABC-Mart | G10: 1234567895 | H10: 2000000006 | I10: 0000004 | K10: 2000000006 | M10: O | P10: 0.5 | R10: 11710 | S10: 11000 | T10: =IF(COUNTA(O10,Q10), R10, P10*R10) -> 5855 | U10: =IF(COUNTA(O10,Q10), S10, P10*S10) -> 5500 | Y10: =IF(COUNTA(V10), S10+X10, S10) -> 11000 | Z10: =_xlfn.IFS(AND(COUNTA(V10), (COUNTA(O10,Q10) = 0)), U10+X10*P10, AND(COUNTA(V10), (COUNTA(O10,Q10) > 0)), U10+X10, TRUE, U10) -> 5500 | AB10: IT-OC-004
B11: 7 | C11: 자사 | D11: ABC-Mart | G11: 1234567896 | H11: 2000000007 | I11: 0000005 | K11: 2000000007 | M11: O | P11: 0.5 | R11: 16230 | S11: 16000 | T11: =IF(COUNTA(O11,Q11), R11, P11*R11) -> 8115 | U11: =IF(COUNTA(O11,Q11), S11, P11*S11) -> 8000 | Y11: =IF(COUNTA(V11), S11+X11, S11) -> 16000 | Z11: =_xlfn.IFS(AND(COUNTA(V11), (COUNTA(O11,Q11) = 0)), U11+X11*P11, AND(COUNTA(V11), (COUNTA(O11,Q11) > 0)), U11+X11, TRUE, U11) -> 8000 | AB11: IT-OC-004
B12: 8 | C12: 입점 | D12: A-RT | E12: VD0002 | F12: 입점사2 | G12: 1234567897 | H12: 2000000008 | J12: VD0002_008 | K12: 2000000008 | P12: 0.5 | R12: 14490 | S12: 14000 | T12: =IF(COUNTA(O12,Q12), R12, P12*R12) -> 7245 | U12: =IF(COUNTA(O12,Q12), S12, P12*S12) -> 7000 | Y12: =IF(COUNTA(V12), S12+X12, S12) -> 14000 | Z12: =_xlfn.IFS(AND(COUNTA(V12), (COUNTA(O12,Q12) = 0)), U12+X12*P12, AND(COUNTA(V12), (COUNTA(O12,Q12) > 0)), U12+X12, TRUE, U12) -> 7000 | AB12: IT-OC-005
B13: 9 | C13: 자사 | D13: GS | G13: 1234567898 | H13: 2000000009 | I13: 0000006 | K13: 2000000009 | M13: O | P13: 0.5 | R13: 18620 | S13: 18000 | T13: =IF(COUNTA(O13,Q13), R13, P13*R13) -> 9310 | U13: =IF(COUNTA(O13,Q13), S13, P13*S13) -> 9000 | Y13: =IF(COUNTA(V13), S13+X13, S13) -> 18000 | Z13: =_xlfn.IFS(AND(COUNTA(V13), (COUNTA(O13,Q13) = 0)), U13+X13*P13, AND(COUNTA(V13), (COUNTA(O13,Q13) > 0)), U13+X13, TRUE, U13) -> 9000 | AB13: IT-OC-005
B14: 10 | C14: 입점 | D14: A-RT | E14: VD0003 | F14: 입점사3 | G14: 1234567899 | H14: 2000000010 | J14: VD0003_010 | K14: 2000000010 | P14: 0.5 | R14: 14350 | S14: 14000 | T14: =IF(COUNTA(O14,Q14), R14, P14*R14) -> 7175 | U14: =IF(COUNTA(O14,Q14), S14, P14*S14) -> 7000 | Y14: =IF(COUNTA(V14), S14+X14, S14) -> 14000 | Z14: =_xlfn.IFS(AND(COUNTA(V14), (COUNTA(O14,Q14) = 0)), U14+X14*P14, AND(COUNTA(V14), (COUNTA(O14,Q14) > 0)), U14+X14, TRUE, U14) -> 7000 | AB14: IT-OC-006
B15: 11 | C15: 입점 | D15: A-RT | E15: VD0002 | F15: 입점사2 | G15: 1234567900 | H15: 2000000011 | J15: VD0002_011 | K15: 2000000011 | N15: O | P15: 0.5 | R15: 53690 | S15: 53000 | T15: =IF(COUNTA(O15,Q15), R15, P15*R15) -> 26845 | U15: =IF(COUNTA(O15,Q15), S15, P15*S15) -> 26500 | Y15: =IF(COUNTA(V15), S15+X15, S15) -> 53000 | Z15: =_xlfn.IFS(AND(COUNTA(V15), (COUNTA(O15,Q15) = 0)), U15+X15*P15, AND(COUNTA(V15), (COUNTA(O15,Q15) > 0)), U15+X15, TRUE, U15) -> 26500 | AB15: IT-OC-006
B16: 12 | C16: 자사 | D16: ABC-Mart | G16: 1234567901 | H16: 1000000001 | I16: 0000007 | K16: 1000000001 | O16: O | R16: 46060 | S16: 46000 | T16: =IF(COUNTA(O16,Q16), R16, P16*R16) -> 46060 | U16: =IF(COUNTA(O16,Q16), S16, P16*S16) -> 46000 | Y16: =IF(COUNTA(V16), S16+X16, S16) -> 46000 | Z16: =_xlfn.IFS(AND(COUNTA(V16), (COUNTA(O16,Q16) = 0)), U16+X16*P16, AND(COUNTA(V16), (COUNTA(O16,Q16) > 0)), U16+X16, TRUE, U16) -> 46000 | AB16: IT-OC-007
B17: 13 | C17: 자사 | D17: GS | G17: 1234567902 | H17: 1000000002 | I17: 0000008 | K17: 1000000002 | N17: O | P17: 0.5 | Q17: O | R17: 6900 | S17: 6000 | T17: =IF(COUNTA(O17,Q17), R17, P17*R17) -> 6900 | U17: =IF(COUNTA(O17,Q17), S17, P17*S17) -> 6000 | Y17: =IF(COUNTA(V17), S17+X17, S17) -> 6000 | Z17: =_xlfn.IFS(AND(COUNTA(V17), (COUNTA(O17,Q17) = 0)), U17+X17*P17, AND(COUNTA(V17), (COUNTA(O17,Q17) > 0)), U17+X17, TRUE, U17) -> 6000 | AA17: =COUNTA(O17,Q17) -> 1 | AB17: IT-OC-007
B18: 14 | C18: 입점 | D18: A-RT | E18: VD0003 | F18: 입점사3 | G18: 1234567903 | H18: 2000000012 | J18: VD0003_012 | K18: 2000000012 | P18: 0.5 | R18: 66710 | S18: 66000 | T18: =IF(COUNTA(O18,Q18), R18, P18*R18) -> 33355 | U18: =IF(COUNTA(O18,Q18), S18, P18*S18) -> 33000 | Y18: =IF(COUNTA(V18), S18+X18, S18) -> 66000 | Z18: =_xlfn.IFS(AND(COUNTA(V18), (COUNTA(O18,Q18) = 0)), U18+X18*P18, AND(COUNTA(V18), (COUNTA(O18,Q18) > 0)), U18+X18, TRUE, U18) -> 33000 | AB18: IT-OC-008
B19: 15 | C19: 자사 | D19: ABC-Mart | G19: 1234567904 | H19: 1000000003 | I19: 0000009 | K19: 1000000003 | M19: O | P19: 0.5 | R19: 6570 | S19: 6000 | T19: =IF(COUNTA(O19,Q19), R19, P19*R19) -> 3285 | U19: =IF(COUNTA(O19,Q19), S19, P19*S19) -> 3000 | Y19: =IF(COUNTA(V19), S19+X19, S19) -> 6000 | Z19: =_xlfn.IFS(AND(COUNTA(V19), (COUNTA(O19,Q19) = 0)), U19+X19*P19, AND(COUNTA(V19), (COUNTA(O19,Q19) > 0)), U19+X19, TRUE, U19) -> 3000 | AB19: IT-OC-008
B20: 16 | C20: 입점 | D20: A-RT | E20: VD0001 | F20: 입점사1 | G20: 1234567905 | H20: 2000000013 | J20: VD0001_013 | K20: 2000000013 | P20: 0.5 | R20: 70280 | S20: 70000 | T20: =IF(COUNTA(O20,Q20), R20, P20*R20) -> 35140 | U20: =IF(COUNTA(O20,Q20), S20, P20*S20) -> 35000 | Y20: =IF(COUNTA(V20), S20+X20, S20) -> 70000 | Z20: =_xlfn.IFS(AND(COUNTA(V20), (COUNTA(O20,Q20) = 0)), U20+X20*P20, AND(COUNTA(V20), (COUNTA(O20,Q20) > 0)), U20+X20, TRUE, U20) -> 35000 | AB20: IT-OC-009
