Workbook
Name CASE: [1]코드!$K$35:$K$41
Name DBMS: [1]코드!$G$35:$G$49
Name EndUser: [1]코드!$D$35:$D$39
Name HW: [1]코드!$I$35:$I$59
Name Language: [1]코드!$J$35:$J$61
Name LType: [1]코드!$M$35:$M$37
Name MW: [1]코드!$H$35:$H$49
Name OS: [1]코드!$F$35:$F$42
Name Platform: [1]코드!$L$35:$L$37
Name 개발형태: [1]코드!$C$2:$C$7
Name 계약방식: [1]코드!$A$2:$A$10
Name 계약형태: [1]코드!$H$2:$H$4
Name 낙찰구분: [1]코드!$B$2:$B$5
Name 방법론: [1]코드!$E$35:$E$51
Name 사업부: [1]코드!$J$2:$J$7
Name 서비스영역: [1]코드!$K$2:$K$13
Name 업종: [1]코드!$D$2:$D$9
Name 업종상세: [1]코드!$E$2:$E$32
Name 적용사이트: [1]코드!$C$35:$C$38
Name 전략프로젝트: [1]코드!$G$2:$G$3
Name 프로덕트유형: [1]코드!$B$35:$B$39
Name 프로덕트타입: [1]코드!$A$35:$A$49
Name 프로젝트단계: [1]코드!$F$2:$F$7

Sheet 표지
B25: 프로젝트 | D25: ABC-MART 온라인 쇼핑몰 2.0 구축
B26: 작성자 | D26: 박주희 차장 | F26: 작성일 | H26: 43627
B27: 승인자 | F27: 승인일

Sheet 개정이력
B6: 제.개정 이력
B8: 버전 | C8: 제.개정일자 | D8: 제.개정내용 | H8: 작성자
B9: 0.1 | C9: 43604 | D9: 초안 작성 | H9: 박주희
B10: 0.2 | C10: 43627 | D10: 수정/보완 | H10: 조영진

Sheet 헤더
A1: 통합테스트 시나리오 및 결과서
B2: 프로젝트 | C2: ABC-MART 온라인 쇼핑몰 2.0 구축 | E2: 단계 | F2: 테스트
B3: 작성자 | C3: 박주희 차장 | E3: 작성일 | F3: 43627

Sheet 결과
B3: 회원가입 Sheet
B5: SYS | C5: 시나리오 수 | D5: Pass | E5: Fail | F5: Block | G5: N/A | H5: Total | I5: 진척율 | J5: 수행율 | K5: 성공율 | L5: 결함율 | M5: 수행불가율
B6: FO | C6: =COUNTIF(TS_회원가입[SYS],표1_1[[#This Row],[SYS]]) -> 32 | D6: =COUNTIFS('1_회원가입'!$F:$F,표1_1[[#This Row],[SYS]],'1_회원가입'!$N:$N,표1_1[[#Headers],[Pass]]) -> 0 | E6: =COUNTIFS('1_회원가입'!$F:$F,표1_1[[#This Row],[SYS]],'1_회원가입'!$N:$N,표1_1[[#Headers],[Fail]]) -> 0 | F6: =COUNTIFS('1_회원가입'!$F:$F,표1_1[[#This Row],[SYS]],'1_회원가입'!$N:$N,표1_1[[#Headers],[Block]]) -> 0 | G6: =COUNTIFS('1_회원가입'!$F:$F,표1_1[[#This Row],[SYS]],'1_회원가입'!$N:$N,표1_1[[#Headers],[N/A]]) -> 0 | H6: =SUM(표1_1[[#This Row],[Pass]:[N/A]]) -> 0 | I6: =IFERROR(표1_1[[#This Row],[Total]]/표1_1[[#This Row],[시나리오 수]],0) -> 0 | J6: =IFERROR(SUM(표1_1[[#This Row],[Pass]:[Fail]])/(표1_1[[#This Row],[시나리오 수]]-표1_1[[#This Row],[N/A]]),0) -> 0 | K6: =IFERROR(표1_1[[#This Row],[Pass]]/SUM(표1_1[[#This Row],[Pass]:[Fail]]),0) -> 0 | L6: =IFERROR((표1_1[[#This Row],[Fail]]/SUM(표1_1[[#This Row],[Pass]:[Fail]])),0) -> 0 | M6: =IFERROR((표1_1[[#This Row],[Block]]/표1_1[[#This Row],[시나리오 수]]),0) -> 0
B7: MO | C7: =COUNTIF(TS_회원가입[SYS],표1_1[[#This Row],[SYS]]) -> 32 | D7: =COUNTIFS('1_회원가입'!$F:$F,표1_1[[#This Row],[SYS]],'1_회원가입'!$N:$N,표1_1[[#Headers],[Pass]]) -> 0 | E7: =COUNTIFS('1_회원가입'!$F:$F,표1_1[[#This Row],[SYS]],'1_회원가입'!$N:$N,표1_1[[#Headers],[Fail]]) -> 0 | F7: =COUNTIFS('1_회원가입'!$F:$F,표1_1[[#This Row],[SYS]],'1_회원가입'!$N:$N,표1_1[[#Headers],[Block]]) -> 0 | G7: =COUNTIFS('1_회원가입'!$F:$F,표1_1[[#This Row],[SYS]],'1_회원가입'!$N:$N,표1_1[[#Headers],[N/A]]) -> 0 | H7: =SUM(표1_1[[#This Row],[Pass]:[N/A]]) -> 0 | I7: =IFERROR(표1_1[[#This Row],[Total]]/표1_1[[#This Row],[시나리오 수]],0) -> 0 | J7: =IFERROR(SUM(표1_1[[#This Row],[Pass]:[Fail]])/(표1_1[[#This Row],[시나리오 수]]-표1_1[[#This Row],[N/A]]),0) -> 0 | K7: =IFERROR(표1_1[[#This Row],[Pass]]/SUM(표1_1[[#This Row],[Pass]:[Fail]]),0) -> 0 | L7: =IFERROR((표1_1[[#This Row],[Fail]]/SUM(표1_1[[#This Row],[Pass]:[Fail]])),0) -> 0 | M7: =IFERROR((표1_1[[#This Row],[Block]]/표1_1[[#This Row],[시나리오 수]]),0) -> 0
B8: BO | C8: =COUNTIF(TS_회원가입[SYS],표1_1[[#This Row],[SYS]]) -> 6 | D8: =COUNTIFS('1_회원가입'!$F:$F,표1_1[[#This Row],[SYS]],'1_회원가입'!$N:$N,표1_1[[#Headers],[Pass]]) -> 0 | E8: =COUNTIFS('1_회원가입'!$F:$F,표1_1[[#This Row],[SYS]],'1_회원가입'!$N:$N,표1_1[[#Headers],[Fail]]) -> 0 | F8: =COUNTIFS('1_회원가입'!$F:$F,표1_1[[#This Row],[SYS]],'1_회원가입'!$N:$N,표1_1[[#Headers],[Block]]) -> 0 | G8: =COUNTIFS('1_회원가입'!$F:$F,표1_1[[#This Row],[SYS]],'1_회원가입'!$N:$N,표1_1[[#Headers],[N/A]]) -> 0 | H8: =SUM(표1_1[[#This Row],[Pass]:[N/A]]) -> 0 | I8: =IFERROR(표1_1[[#This Row],[Total]]/표1_1[[#This Row],[시나리오 수]],0) -> 0 | J8: =IFERROR(SUM(표1_1[[#This Row],[Pass]:[Fail]])/(표1_1[[#This Row],[시나리오 수]]-표1_1[[#This Row],[N/A]]),0) -> 0 | K8: =IFERROR(표1_1[[#This Row],[Pass]]/SUM(표1_1[[#This Row],[Pass]:[Fail]]),0) -> 0 | L8: =IFERROR((표1_1[[#This Row],[Fail]]/SUM(표1_1[[#This Row],[Pass]:[Fail]])),0) -> 0 | M8: =IFERROR((표1_1[[#This Row],[Block]]/표1_1[[#This Row],[시나리오 수]]),0) -> 0
B9: PO | C9: =COUNTIF(TS_회원가입[SYS],표1_1[[#This Row],[SYS]]) -> 0 | D9: =COUNTIFS('1_회원가입'!$F:$F,표1_1[[#This Row],[SYS]],'1_회원가입'!$N:$N,표1_1[[#Headers],[Pass]]) -> 0 | E9: =COUNTIFS('1_회원가입'!$F:$F,표1_1[[#This Row],[SYS]],'1_회원가입'!$N:$N,표1_1[[#Headers],[Fail]]) -> 0 | F9: =COUNTIFS('1_회원가입'!$F:$F,표1_1[[#This Row],[SYS]],'1_회원가입'!$N:$N,표1_1[[#Headers],[Block]]) -> 0 | G9: =COUNTIFS('1_회원가입'!$F:$F,표1_1[[#This Row],[SYS]],'1_회원가입'!$N:$N,표1_1[[#Headers],[N/A]]) -> 0 | H9: =SUM(표1_1[[#This Row],[Pass]:[N/A]]) -> 0 | I9: =IFERROR(표1_1[[#This Row],[Total]]/표1_1[[#This Row],[시나리오 수]],0) -> 0 | J9: =IFERROR(SUM(표1_1[[#This Row],[Pass]:[Fail]])/(표1_1[[#This Row],[시나리오 수]]-표1_1[[#This Row],[N/A]]),0) -> 0 | K9: =IFERROR(표1_1[[#This Row],[Pass]]/SUM(표1_1[[#This Row],[Pass]:[Fail]]),0) -> 0 | L9: =IFERROR((표1_1[[#This Row],[Fail]]/SUM(표1_1[[#This Row],[Pass]:[Fail]])),0) -> 0 | M9: =IFERROR((표1_1[[#This Row],[Block]]/표1_1[[#This Row],[시나리오 수]]),0) -> 0
B10: Total | C10: =SUM(C6:C9) -> 70 | D10: =SUM(D6:D9) -> 0 | E10: =SUM(E6:E9) -> 0 | F10: =SUM(F6:F9) -> 0 | G10: =SUM(G6:G9) -> 0 | H10: =SUM(H6:H9) -> 0 | I10: =IFERROR(표1_1[[#This Row],[Total]]/표1_1[[#This Row],[시나리오 수]],0) -> 0 | J10: =IFERROR(SUM(표1_1[[#This Row],[Pass]:[Fail]])/(표1_1[[#This Row],[시나리오 수]]-표1_1[[#This Row],[N/A]]),0) -> 0 | K10: =IFERROR(표1_1[[#This Row],[Pass]]/SUM(표1_1[[#This Row],[Pass]:[Fail]]),0) -> 0 | L10: =IFERROR((표1_1[[#This Row],[Fail]]/SUM(표1_1[[#This Row],[Pass]:[Fail]])),0) -> 0 | M10: =IFERROR((표1_1[[#This Row],[Block]]/표1_1[[#This Row],[시나리오 수]]),0) -> 0
B12: 회원전환 Sheet
B14: SYS | C14: 시나리오 수 | D14: Pass | E14: Fail | F14: Block | G14: N/A | H14: Total | I14: 진척율 | J14: 수행율 | K14: 성공율 | L14: 결함율 | M14: 수행불가율
B15: FO | C15: =COUNTIF(TS_회원전환[SYS],표1_2[[#This Row],[SYS]]) -> 34 | D15: =COUNTIFS('2_회원전환'!$F:$F,표1_2[[#This Row],[SYS]],'2_회원전환'!$N:$N,표1_2[[#Headers],[Pass]]) -> 0 | E15: =COUNTIFS('2_회원전환'!$F:$F,표1_2[[#This Row],[SYS]],'2_회원전환'!$N:$N,표1_2[[#Headers],[Fail]]) -> 0 | F15: =COUNTIFS('2_회원전환'!$F:$F,표1_2[[#This Row],[SYS]],'2_회원전환'!$N:$N,표1_2[[#Headers],[Block]]) -> 0 | G15: =COUNTIFS('2_회원전환'!$F:$F,표1_2[[#This Row],[SYS]],'2_회원전환'!$N:$N,표1_2[[#Headers],[N/A]]) -> 0 | H15: =SUM(표1_2[[#This Row],[Pass]:[N/A]]) -> 0 | I15: =IFERROR(표1_2[[#This Row],[Total]]/표1_2[[#This Row],[시나리오 수]],0) -> 0 | J15: =IFERROR(SUM(표1_2[[#This Row],[Pass]:[Fail]])/(표1_2[[#This Row],[시나리오 수]]-표1_2[[#This Row],[N/A]]),0) -> 0 | K15: =IFERROR(표1_2[[#This Row],[Pass]]/SUM(표1_2[[#This Row],[Pass]:[Fail]]),0) -> 0 | L15: =IFERROR((표1_2[[#This Row],[Fail]]/SUM(표1_2[[#This Row],[Pass]:[Fail]])),0) -> 0 | M15: =IFERROR((표1_2[[#This Row],[Block]]/표1_2[[#This Row],[시나리오 수]]),0) -> 0
B16: MO | C16: =COUNTIF(TS_회원전환[SYS],표1_2[[#This Row],[SYS]]) -> 34 | D16: =COUNTIFS('2_회원전환'!$F:$F,표1_2[[#This Row],[SYS]],'2_회원전환'!$N:$N,표1_2[[#Headers],[Pass]]) -> 0 | E16: =COUNTIFS('2_회원전환'!$F:$F,표1_2[[#This Row],[SYS]],'2_회원전환'!$N:$N,표1_2[[#Headers],[Fail]]) -> 0 | F16: =COUNTIFS('2_회원전환'!$F:$F,표1_2[[#This Row],[SYS]],'2_회원전환'!$N:$N,표1_2[[#Headers],[Block]]) -> 0 | G16: =COUNTIFS('2_회원전환'!$F:$F,표1_2[[#This Row],[SYS]],'2_회원전환'!$N:$N,표1_2[[#Headers],[N/A]]) -> 0 | H16: =SUM(표1_2[[#This Row],[Pass]:[N/A]]) -> 0 | I16: =IFERROR(표1_2[[#This Row],[Total]]/표1_2[[#This Row],[시나리오 수]],0) -> 0 | J16: =IFERROR(SUM(표1_2[[#This Row],[Pass]:[Fail]])/표1_2[[#This Row],[시나리오 수]],0) -> 0 | K16: =IFERROR(표1_2[[#This Row],[Pass]]/SUM(표1_2[[#This Row],[Pass]:[Fail]]),0) -> 0 | L16: =IFERROR((표1_2[[#This Row],[Fail]]/SUM(표1_2[[#This Row],[Pass]:[Fail]])),0) -> 0 | M16: =IFERROR((표1_2[[#This Row],[Block]]/표1_2[[#This Row],[시나리오 수]]),0) -> 0
B17: BO | C17: =COUNTIF(TS_회원전환[SYS],표1_2[[#This Row],[SYS]]) -> 12 | D17: =COUNTIFS('2_회원전환'!$F:$F,표1_2[[#This Row],[SYS]],'2_회원전환'!$N:$N,표1_2[[#Headers],[Pass]]) -> 0 | E17: =COUNTIFS('2_회원전환'!$F:$F,표1_2[[#This Row],[SYS]],'2_회원전환'!$N:$N,표1_2[[#Headers],[Fail]]) -> 0 | F17: =COUNTIFS('2_회원전환'!$F:$F,표1_2[[#This Row],[SYS]],'2_회원전환'!$N:$N,표1_2[[#Headers],[Block]]) -> 0 | G17: =COUNTIFS('2_회원전환'!$F:$F,표1_2[[#This Row],[SYS]],'2_회원전환'!$N:$N,표1_2[[#Headers],[N/A]]) -> 0 | H17: =SUM(표1_2[[#This Row],[Pass]:[N/A]]) -> 0 | I17: =IFERROR(표1_2[[#This Row],[Total]]/표1_2[[#This Row],[시나리오 수]],0) -> 0 | J17: =IFERROR(SUM(표1_2[[#This Row],[Pass]:[Fail]])/표1_2[[#This Row],[시나리오 수]],0) -> 0 | K17: =IFERROR(표1_2[[#This Row],[Pass]]/SUM(표1_2[[#This Row],[Pass]:[Fail]]),0) -> 0 | L17: =IFERROR((표1_2[[#This Row],[Fail]]/SUM(표1_2[[#This Row],[Pass]:[Fail]])),0) -> 0 | M17: =IFERROR((표1_2[[#This Row],[Block]]/표1_2[[#This Row],[시나리오 수]]),0) -> 0
B18: PO | C18: =COUNTIF(TS_회원전환[SYS],표1_2[[#This Row],[SYS]]) -> 0 | D18: =COUNTIFS('2_회원전환'!$F:$F,표1_2[[#This Row],[SYS]],'2_회원전환'!$N:$N,표1_2[[#Headers],[Pass]]) -> 0 | E18: =COUNTIFS('2_회원전환'!$F:$F,표1_2[[#This Row],[SYS]],'2_회원전환'!$N:$N,표1_2[[#Headers],[Fail]]) -> 0 | F18: =COUNTIFS('2_회원전환'!$F:$F,표1_2[[#This Row],[SYS]],'2_회원전환'!$N:$N,표1_2[[#Headers],[Block]]) -> 0 | G18: =COUNTIFS('2_회원전환'!$F:$F,표1_2[[#This Row],[SYS]],'2_회원전환'!$N:$N,표1_2[[#Headers],[N/A]]) -> 0 | H18: =SUM(표1_2[[#This Row],[Pass]:[N/A]]) -> 0 | I18: =IFERROR(표1_2[[#This Row],[Total]]/표1_2[[#This Row],[시나리오 수]],0) -> 0 | J18: =IFERROR(SUM(표1_2[[#This Row],[Pass]:[Fail]])/표1_2[[#This Row],[시나리오 수]],0) -> 0 | K18: =IFERROR(표1_2[[#This Row],[Pass]]/SUM(표1_2[[#This Row],[Pass]:[Fail]]),0) -> 0 | L18: =IFERROR((표1_2[[#This Row],[Fail]]/SUM(표1_2[[#This Row],[Pass]:[Fail]])),0) -> 0 | M18: =IFERROR((표1_2[[#This Row],[Block]]/표1_2[[#This Row],[시나리오 수]]),0) -> 0
B19: Total | C19: =SUM(C15:C18) -> 80 | D19: =SUM(D15:D18) -> 0 | E19: =SUM(E15:E18) -> 0 | F19: =SUM(F15:F18) -> 0 | G19: =SUM(G15:G18) -> 0 | H19: =SUM(H15:H18) -> 0 | I19: =IFERROR(표1_2[[#This Row],[Total]]/표1_2[[#This Row],[시나리오 수]],0) -> 0 | J19: =IFERROR(SUM(표1_2[[#This Row],[Pass]:[Fail]])/표1_2[[#This Row],[시나리오 수]],0) -> 0 | K19: =IFERROR(표1_2[[#This Row],[Pass]]/SUM(표1_2[[#This Row],[Pass]:[Fail]]),0) -> 0 | L19: =IFERROR((표1_2[[#This Row],[Fail]]/SUM(표1_2[[#This Row],[Pass]:[Fail]])),0) -> 0 | M19: =IFERROR((표1_2[[#This Row],[Block]]/표1_2[[#This Row],[시나리오 수]]),0) -> 0
B21: 로그인 Sheet
B23: SYS | C23: 시나리오 수 | D23: Pass | E23: Fail | F23: Block | G23: N/A | H23: Total | I23: 진척율 | J23: 수행율 | K23: 성공율 | L23: 결함율 | M23: 수행불가율
B24: FO | C24: =COUNTIF(TS_로그인[SYS],표1_3[[#This Row],[SYS]]) -> 30 | D24: =COUNTIFS('3_로그인'!$F:$F,표1_3[[#This Row],[SYS]],'3_로그인'!$N:$N,표1_3[[#Headers],[Pass]]) -> 0 | E24: =COUNTIFS('3_로그인'!$F:$F,표1_3[[#This Row],[SYS]],'3_로그인'!$N:$N,표1_3[[#Headers],[Fail]]) -> 0 | F24: =COUNTIFS('3_로그인'!$F:$F,표1_3[[#This Row],[SYS]],'3_로그인'!$N:$N,표1_3[[#Headers],[Block]]) -> 0 | G24: =COUNTIFS('3_로그인'!$F:$F,표1_3[[#This Row],[SYS]],'3_로그인'!$N:$N,표1_3[[#Headers],[N/A]]) -> 0 | H24: =SUM(표1_3[[#This Row],[Pass]:[N/A]]) -> 0 | I24: =IFERROR(표1_3[[#This Row],[Total]]/표1_3[[#This Row],[시나리오 수]],0) -> 0 | J24: =IFERROR(SUM(표1_3[[#This Row],[Pass]:[Fail]])/(표1_3[[#This Row],[시나리오 수]]-표1_3[[#This Row],[N/A]]),0) -> 0 | K24: =IFERROR(표1_3[[#This Row],[Pass]]/SUM(표1_3[[#This Row],[Pass]:[Fail]]),0) -> 0 | L24: =IFERROR((표1_3[[#This Row],[Fail]]/SUM(표1_3[[#This Row],[Pass]:[Fail]])),0) -> 0 | M24: =IFERROR((표1_3[[#This Row],[Block]]/표1_3[[#This Row],[시나리오 수]]),0) -> 0
B25: MO | C25: =COUNTIF(TS_로그인[SYS],표1_3[[#This Row],[SYS]]) -> 30 | D25: =COUNTIFS('3_로그인'!$F:$F,표1_3[[#This Row],[SYS]],'3_로그인'!$N:$N,표1_3[[#Headers],[Pass]]) -> 0 | E25: =COUNTIFS('3_로그인'!$F:$F,표1_3[[#This Row],[SYS]],'3_로그인'!$N:$N,표1_3[[#Headers],[Fail]]) -> 0 | F25: =COUNTIFS('3_로그인'!$F:$F,표1_3[[#This Row],[SYS]],'3_로그인'!$N:$N,표1_3[[#Headers],[Block]]) -> 0 | G25: =COUNTIFS('3_로그인'!$F:$F,표1_3[[#This Row],[SYS]],'3_로그인'!$N:$N,표1_3[[#Headers],[N/A]]) -> 0 | H25: =SUM(표1_3[[#This Row],[Pass]:[N/A]]) -> 0 | I25: =IFERROR(표1_3[[#This Row],[Total]]/표1_3[[#This Row],[시나리오 수]],0) -> 0 | J25: =IFERROR(SUM(표1_3[[#This Row],[Pass]:[Fail]])/(표1_3[[#This Row],[시나리오 수]]-표1_3[[#This Row],[N/A]]),0) -> 0 | K25: =IFERROR(표1_3[[#This Row],[Pass]]/SUM(표1_3[[#This Row],[Pass]:[Fail]]),0) -> 0 | L25: =IFERROR((표1_3[[#This Row],[Fail]]/SUM(표1_3[[#This Row],[Pass]:[Fail]])),0) -> 0 | M25: =IFERROR((표1_3[[#This Row],[Block]]/표1_3[[#This Row],[시나리오 수]]),0) -> 0
B26: BO | C26: =COUNTIF(TS_로그인[SYS],표1_3[[#This Row],[SYS]]) -> 3 | D26: =COUNTIFS('3_로그인'!$F:$F,표1_3[[#This Row],[SYS]],'3_로그인'!$N:$N,표1_3[[#Headers],[Pass]]) -> 0 | E26: =COUNTIFS('3_로그인'!$F:$F,표1_3[[#This Row],[SYS]],'3_로그인'!$N:$N,표1_3[[#Headers],[Fail]]) -> 0 | F26: =COUNTIFS('3_로그인'!$F:$F,표1_3[[#This Row],[SYS]],'3_로그인'!$N:$N,표1_3[[#Headers],[Block]]) -> 0 | G26: =COUNTIFS('3_로그인'!$F:$F,표1_3[[#This Row],[SYS]],'3_로그인'!$N:$N,표1_3[[#Headers],[N/A]]) -> 0 | H26: =SUM(표1_3[[#This Row],[Pass]:[N/A]]) -> 0 | I26: =IFERROR(표1_3[[#This Row],[Total]]/표1_3[[#This Row],[시나리오 수]],0) -> 0 | J26: =IFERROR(SUM(표1_3[[#This Row],[Pass]:[Fail]])/(표1_3[[#This Row],[시나리오 수]]-표1_3[[#This Row],[N/A]]),0) -> 0 | K26: =IFERROR(표1_3[[#This Row],[Pass]]/SUM(표1_3[[#This Row],[Pass]:[Fail]]),0) -> 0 | L26: =IFERROR((표1_3[[#This Row],[Fail]]/SUM(표1_3[[#This Row],[Pass]:[Fail]])),0) -> 0 | M26: =IFERROR((표1_3[[#This Row],[Block]]/표1_3[[#This Row],[시나리오 수]]),0) -> 0
B27: PO | C27: =COUNTIF(TS_로그인[SYS],표1_3[[#This Row],[SYS]]) -> 0 | D27: =COUNTIFS('3_로그인'!$F:$F,표1_3[[#This Row],[SYS]],'3_로그인'!$N:$N,표1_3[[#Headers],[Pass]]) -> 0 | E27: =COUNTIFS('3_로그인'!$F:$F,표1_3[[#This Row],[SYS]],'3_로그인'!$N:$N,표1_3[[#Headers],[Fail]]) -> 0 | F27: =COUNTIFS('3_로그인'!$F:$F,표1_3[[#This Row],[SYS]],'3_로그인'!$N:$N,표1_3[[#Headers],[Block]]) -> 0 | G27: =COUNTIFS('3_로그인'!$F:$F,표1_3[[#This Row],[SYS]],'3_로그인'!$N:$N,표1_3[[#Headers],[N/A]]) -> 0 | H27: =SUM(표1_3[[#This Row],[Pass]:[N/A]]) -> 0 | I27: =IFERROR(표1_3[[#This Row],[Total]]/표1_3[[#This Row],[시나리오 수]],0) -> 0 | J27: =IFERROR(SUM(표1_3[[#This Row],[Pass]:[Fail]])/(표1_3[[#This Row],[시나리오 수]]-표1_3[[#This Row],[N/A]]),0) -> 0 | K27: =IFERROR(표1_3[[#This Row],[Pass]]/SUM(표1_3[[#This Row],[Pass]:[Fail]]),0) -> 0 | L27: =IFERROR((표1_3[[#This Row],[Fail]]/SUM(표1_3[[#This Row],[Pass]:[Fail]])),0) -> 0 | M27: =IFERROR((표1_3[[#This Row],[Block]]/표1_3[[#This Row],[시나리오 수]]),0) -> 0
B28: Total | C28: =SUM(C24:C27) -> 63 | D28: =SUM(D24:D27) -> 0 | E28: =SUM(E24:E27) -> 0 | F28: =SUM(F24:F27) -> 0 | G28: =SUM(G24:G27) -> 0 | H28: =SUM(H24:H27) -> 0 | I28: =IFERROR(표1_3[[#This Row],[Total]]/표1_3[[#This Row],[시나리오 수]],0) -> 0 | J28: =IFERROR(SUM(표1_3[[#This Row],[Pass]:[Fail]])/표1_3[[#This Row],[시나리오 수]],0) -> 0 | K28: =IFERROR(표1_3[[#This Row],[Pass]]/SUM(표1_3[[#This Row],[Pass]:[Fail]]),0) -> 0 | L28: =IFERROR((표1_3[[#This Row],[Fail]]/SUM(표1_3[[#This Row],[Pass]:[Fail]])),0) -> 0 | M28: =IFERROR((표1_3[[#This Row],[Block]]/표1_3[[#This Row],[시나리오 수]]),0) -> 0
B30: ID 찾기 Sheet
B32: SYS | C32: 시나리오 수 | D32: Pass | E32: Fail | F32: Block | G32: N/A | H32: Total | I32: 진척율 | J32: 수행율 | K32: 성공율 | L32: 결함율 | M32: 수행불가율
B33: FO | C33: =COUNTIF(TS_ID찾기[SYS],표1_4[[#This Row],[SYS]]) -> 20 | D33: =COUNTIFS('4_ID 찾기'!$F:$F,표1_4[[#This Row],[SYS]],'4_ID 찾기'!$N:$N,표1_4[[#Headers],[Pass]]) -> 0 | E33: =COUNTIFS('4_ID 찾기'!$F:$F,표1_4[[#This Row],[SYS]],'4_ID 찾기'!$N:$N,표1_4[[#Headers],[Fail]]) -> 0 | F33: =COUNTIFS('4_ID 찾기'!$F:$F,표1_4[[#This Row],[SYS]],'4_ID 찾기'!$N:$N,표1_4[[#Headers],[Block]]) -> 0 | G33: =COUNTIFS('4_ID 찾기'!$F:$F,표1_4[[#This Row],[SYS]],'4_ID 찾기'!$N:$N,표1_4[[#Headers],[N/A]]) -> 0 | H33: =SUM(표1_4[[#This Row],[Pass]:[N/A]]) -> 0 | I33: =IFERROR(표1_4[[#This Row],[Total]]/표1_4[[#This Row],[시나리오 수]],0) -> 0 | J33: =IFERROR(SUM(표1_4[[#This Row],[Pass]:[Fail]])/(표1_4[[#This Row],[시나리오 수]]-표1_4[[#This Row],[N/A]]),0) -> 0 | K33: =IFERROR(표1_4[[#This Row],[Pass]]/SUM(표1_4[[#This Row],[Pass]:[Fail]]),0) -> 0 | L33: =IFERROR((표1_4[[#This Row],[Fail]]/SUM(표1_4[[#This Row],[Pass]:[Fail]])),0) -> 0 | M33: =IFERROR((표1_4[[#This Row],[Block]]/표1_4[[#This Row],[시나리오 수]]),0) -> 0
B34: MO | C34: =COUNTIF(TS_ID찾기[SYS],표1_4[[#This Row],[SYS]]) -> 20 | D34: =COUNTIFS('4_ID 찾기'!$F:$F,표1_4[[#This Row],[SYS]],'4_ID 찾기'!$N:$N,표1_4[[#Headers],[Pass]]) -> 0 | E34: =COUNTIFS('4_ID 찾기'!$F:$F,표1_4[[#This Row],[SYS]],'4_ID 찾기'!$N:$N,표1_4[[#Headers],[Fail]]) -> 0 | F34: =COUNTIFS('4_ID 찾기'!$F:$F,표1_4[[#This Row],[SYS]],'4_ID 찾기'!$N:$N,표1_4[[#Headers],[Block]]) -> 0 | G34: =COUNTIFS('4_ID 찾기'!$F:$F,표1_4[[#This Row],[SYS]],'4_ID 찾기'!$N:$N,표1_4[[#Headers],[N/A]]) -> 0 | H34: =SUM(표1_4[[#This Row],[Pass]:[N/A]]) -> 0 | I34: =IFERROR(표1_4[[#This Row],[Total]]/표1_4[[#This Row],[시나리오 수]],0) -> 0 | J34: =IFERROR(SUM(표1_4[[#This Row],[Pass]:[Fail]])/(표1_4[[#This Row],[시나리오 수]]-표1_4[[#This Row],[N/A]]),0) -> 0 | K34: =IFERROR(표1_4[[#This Row],[Pass]]/SUM(표1_4[[#This Row],[Pass]:[Fail]]),0) -> 0 | L34: =IFERROR((표1_4[[#This Row],[Fail]]/SUM(표1_4[[#This Row],[Pass]:[Fail]])),0) -> 0 | M34: =IFERROR((표1_4[[#This Row],[Block]]/표1_4[[#This Row],[시나리오 수]]),0) -> 0
B35: BO | C35: =COUNTIF(TS_ID찾기[SYS],표1_4[[#This Row],[SYS]]) -> 0 | D35: =COUNTIFS('4_ID 찾기'!$F:$F,표1_4[[#This Row],[SYS]],'4_ID 찾기'!$N:$N,표1_4[[#Headers],[Pass]]) -> 0 | E35: =COUNTIFS('4_ID 찾기'!$F:$F,표1_4[[#This Row],[SYS]],'4_ID 찾기'!$N:$N,표1_4[[#Headers],[Fail]]) -> 0 | F35: =COUNTIFS('4_ID 찾기'!$F:$F,표1_4[[#This Row],[SYS]],'4_ID 찾기'!$N:$N,표1_4[[#Headers],[Block]]) -> 0 | G35: =COUNTIFS('4_ID 찾기'!$F:$F,표1_4[[#This Row],[SYS]],'4_ID 찾기'!$N:$N,표1_4[[#Headers],[N/A]]) -> 0 | H35: =SUM(표1_4[[#This Row],[Pass]:[N/A]]) -> 0 | I35: =IFERROR(표1_4[[#This Row],[Total]]/표1_4[[#This Row],[시나리오 수]],0) -> 0 | J35: =IFERROR(SUM(표1_4[[#This Row],[Pass]:[Fail]])/(표1_4[[#This Row],[시나리오 수]]-표1_4[[#This Row],[N/A]]),0) -> 0 | K35: =IFERROR(표1_4[[#This Row],[Pass]]/SUM(표1_4[[#This Row],[Pass]:[Fail]]),0) -> 0 | L35: =IFERROR((표1_4[[#This Row],[Fail]]/SUM(표1_4[[#This Row],[Pass]:[Fail]])),0) -> 0 | M35: =IFERROR((표1_4[[#This Row],[Block]]/표1_4[[#This Row],[시나리오 수]]),0) -> 0
B36: PO | C36: =COUNTIF(TS_ID찾기[SYS],표1_4[[#This Row],[SYS]]) -> 0 | D36: =COUNTIFS('4_ID 찾기'!$F:$F,표1_4[[#This Row],[SYS]],'4_ID 찾기'!$N:$N,표1_4[[#Headers],[Pass]]) -> 0 | E36: =COUNTIFS('4_ID 찾기'!$F:$F,표1_4[[#This Row],[SYS]],'4_ID 찾기'!$N:$N,표1_4[[#Headers],[Fail]]) -> 0 | F36: =COUNTIFS('4_ID 찾기'!$F:$F,표1_4[[#This Row],[SYS]],'4_ID 찾기'!$N:$N,표1_4[[#Headers],[Block]]) -> 0 | G36: =COUNTIFS('4_ID 찾기'!$F:$F,표1_4[[#This Row],[SYS]],'4_ID 찾기'!$N:$N,표1_4[[#Headers],[N/A]]) -> 0 | H36: =SUM(표1_4[[#This Row],[Pass]:[N/A]]) -> 0 | I36: =IFERROR(표1_4[[#This Row],[Total]]/표1_4[[#This Row],[시나리오 수]],0) -> 0 | J36: =IFERROR(SUM(표1_4[[#This Row],[Pass]:[Fail]])/(표1_4[[#This Row],[시나리오 수]]-표1_4[[#This Row],[N/A]]),0) -> 0 | K36: =IFERROR(표1_4[[#This Row],[Pass]]/SUM(표1_4[[#This Row],[Pass]:[Fail]]),0) -> 0 | L36: =IFERROR((표1_4[[#This Row],[Fail]]/SUM(표1_4[[#This Row],[Pass]:[Fail]])),0) -> 0 | M36: =IFERROR((표1_4[[#This Row],[Block]]/표1_4[[#This Row],[시나리오 수]]),0) -> 0
B37: Total | C37: =SUM(C33:C36) -> 40 | D37: =SUM(D33:D36) -> 0 | E37: =SUM(E33:E36) -> 0 | F37: =SUM(F33:F36) -> 0 | G37: =SUM(G33:G36) -> 0 | H37: =SUM(H33:H36) -> 0 | I37: =IFERROR(표1_4[[#This Row],[Total]]/표1_4[[#This Row],[시나리오 수]],0) -> 0 | J37: =IFERROR(SUM(표1_4[[#This Row],[Pass]:[Fail]])/표1_4[[#This Row],[시나리오 수]],0) -> 0 | K37: =IFERROR(표1_4[[#This Row],[Pass]]/SUM(표1_4[[#This Row],[Pass]:[Fail]]),0) -> 0 | L37: =IFERROR((표1_4[[#This Row],[Fail]]/SUM(표1_4[[#This Row],[Pass]:[Fail]])),0) -> 0 | M37: =IFERROR((표1_4[[#This Row],[Block]]/표1_4[[#This Row],[시나리오 수]]),0) -> 0
B39: PW 찾기 Sheet
B41: SYS | C41: 시나리오 수 | D41: Pass | E41: Fail | F41: Block | G41: N/A | H41: Total | I41: 진척율 | J41: 수행율 | K41: 성공율 | L41: 결함율 | M41: 수행불가율
B42: FO | C42: =COUNTIF(TS_PW찾기[SYS],표1_5[[#This Row],[SYS]]) -> 24 | D42: =COUNTIFS('5_PW 찾기'!$F:$F,표1_5[[#This Row],[SYS]],'5_PW 찾기'!$N:$N,표1_5[[#Headers],[Pass]]) -> 0 | E42: =COUNTIFS('5_PW 찾기'!$F:$F,표1_5[[#This Row],[SYS]],'5_PW 찾기'!$N:$N,표1_5[[#Headers],[Fail]]) -> 0 | F42: =COUNTIFS('5_PW 찾기'!$F:$F,표1_5[[#This Row],[SYS]],'5_PW 찾기'!$N:$N,표1_5[[#Headers],[Block]]) -> 0 | G42: =COUNTIFS('5_PW 찾기'!$F:$F,표1_5[[#This Row],[SYS]],'5_PW 찾기'!$N:$N,표1_5[[#Headers],[N/A]]) -> 0 | H42: =SUM(표1_5[[#This Row],[Pass]:[N/A]]) -> 0 | I42: =IFERROR(표1_5[[#This Row],[Total]]/표1_5[[#This Row],[시나리오 수]],0) -> 0 | J42: =IFERROR(SUM(표1_5[[#This Row],[Pass]:[Fail]])/(표1_5[[#This Row],[시나리오 수]]-표1_5[[#This Row],[N/A]]),0) -> 0 | K42: =IFERROR(표1_5[[#This Row],[Pass]]/SUM(표1_5[[#This Row],[Pass]:[Fail]]),0) -> 0 | L42: =IFERROR((표1_5[[#This Row],[Fail]]/SUM(표1_5[[#This Row],[Pass]:[Fail]])),0) -> 0 | M42: =IFERROR((표1_5[[#This Row],[Block]]/표1_5[[#This Row],[시나리오 수]]),0) -> 0
B43: MO | C43: =COUNTIF(TS_PW찾기[SYS],표1_5[[#This Row],[SYS]]) -> 24 | D43: =COUNTIFS('5_PW 찾기'!$F:$F,표1_5[[#This Row],[SYS]],'5_PW 찾기'!$N:$N,표1_5[[#Headers],[Pass]]) -> 0 | E43: =COUNTIFS('5_PW 찾기'!$F:$F,표1_5[[#This Row],[SYS]],'5_PW 찾기'!$N:$N,표1_5[[#Headers],[Fail]]) -> 0 | F43: =COUNTIFS('5_PW 찾기'!$F:$F,표1_5[[#This Row],[SYS]],'5_PW 찾기'!$N:$N,표1_5[[#Headers],[Block]]) -> 0 | G43: =COUNTIFS('5_PW 찾기'!$F:$F,표1_5[[#This Row],[SYS]],'5_PW 찾기'!$N:$N,표1_5[[#Headers],[N/A]]) -> 0 | H43: =SUM(표1_5[[#This Row],[Pass]:[N/A]]) -> 0 | I43: =IFERROR(표1_5[[#This Row],[Total]]/표1_5[[#This Row],[시나리오 수]],0) -> 0 | J43: =IFERROR(SUM(표1_5[[#This Row],[Pass]:[Fail]])/(표1_5[[#This Row],[시나리오 수]]-표1_5[[#This Row],[N/A]]),0) -> 0 | K43: =IFERROR(표1_5[[#This Row],[Pass]]/SUM(표1_5[[#This Row],[Pass]:[Fail]]),0) -> 0 | L43: =IFERROR((표1_5[[#This Row],[Fail]]/SUM(표1_5[[#This Row],[Pass]:[Fail]])),0) -> 0 | M43: =IFERROR((표1_5[[#This Row],[Block]]/표1_5[[#This Row],[시나리오 수]]),0) -> 0
B44: BO | C44: =COUNTIF(TS_PW찾기[SYS],표1_5[[#This Row],[SYS]]) -> 0 | D44: =COUNTIFS('5_PW 찾기'!$F:$F,표1_5[[#This Row],[SYS]],'5_PW 찾기'!$N:$N,표1_5[[#Headers],[Pass]]) -> 0 | E44: =COUNTIFS('5_PW 찾기'!$F:$F,표1_5[[#This Row],[SYS]],'5_PW 찾기'!$N:$N,표1_5[[#Headers],[Fail]]) -> 0 | F44: =COUNTIFS('5_PW 찾기'!$F:$F,표1_5[[#This Row],[SYS]],'5_PW 찾기'!$N:$N,표1_5[[#Headers],[Block]]) -> 0 | G44: =COUNTIFS('5_PW 찾기'!$F:$F,표1_5[[#This Row],[SYS]],'5_PW 찾기'!$N:$N,표1_5[[#Headers],[N/A]]) -> 0 | H44: =SUM(표1_5[[#This Row],[Pass]:[N/A]]) -> 0 | I44: =IFERROR(표1_5[[#This Row],[Total]]/표1_5[[#This Row],[시나리오 수]],0) -> 0 | J44: =IFERROR(SUM(표1_5[[#This Row],[Pass]:[Fail]])/(표1_5[[#This Row],[시나리오 수]]-표1_5[[#This Row],[N/A]]),0) -> 0 | K44: =IFERROR(표1_5[[#This Row],[Pass]]/SUM(표1_5[[#This Row],[Pass]:[Fail]]),0) -> 0 | L44: =IFERROR((표1_5[[#This Row],[Fail]]/SUM(표1_5[[#This Row],[Pass]:[Fail]])),0) -> 0 | M44: =IFERROR((표1_5[[#This Row],[Block]]/표1_5[[#This Row],[시나리오 수]]),0) -> 0
B45: PO | C45: =COUNTIF(TS_PW찾기[SYS],표1_5[[#This Row],[SYS]]) -> 0 | D45: =COUNTIFS('5_PW 찾기'!$F:$F,표1_5[[#This Row],[SYS]],'5_PW 찾기'!$N:$N,표1_5[[#Headers],[Pass]]) -> 0 | E45: =COUNTIFS('5_PW 찾기'!$F:$F,표1_5[[#This Row],[SYS]],'5_PW 찾기'!$N:$N,표1_5[[#Headers],[Fail]]) -> 0 | F45: =COUNTIFS('5_PW 찾기'!$F:$F,표1_5[[#This Row],[SYS]],'5_PW 찾기'!$N:$N,표1_5[[#Headers],[Block]]) -> 0 | G45: =COUNTIFS('5_PW 찾기'!$F:$F,표1_5[[#This Row],[SYS]],'5_PW 찾기'!$N:$N,표1_5[[#Headers],[N/A]]) -> 0 | H45: =SUM(표1_5[[#This Row],[Pass]:[N/A]]) -> 0 | I45: =IFERROR(표1_5[[#This Row],[Total]]/표1_5[[#This Row],[시나리오 수]],0) -> 0 | J45: =IFERROR(SUM(표1_5[[#This Row],[Pass]:[Fail]])/(표1_5[[#This Row],[시나리오 수]]-표1_5[[#This Row],[N/A]]),0) -> 0 | K45: =IFERROR(표1_5[[#This Row],[Pass]]/SUM(표1_5[[#This Row],[Pass]:[Fail]]),0) -> 0 | L45: =IFERROR((표1_5[[#This Row],[Fail]]/SUM(표1_5[[#This Row],[Pass]:[Fail]])),0) -> 0 | M45: =IFERROR((표1_5[[#This Row],[Block]]/표1_5[[#This Row],[시나리오 수]]),0) -> 0
B46: Total | C46: =SUM(C42:C45) -> 48 | D46: =SUM(D42:D45) -> 0 | E46: =SUM(E42:E45) -> 0 | F46: =SUM(F42:F45) -> 0 | G46: =SUM(G42:G45) -> 0 | H46: =SUM(H42:H45) -> 0 | I46: =IFERROR(표1_5[[#This Row],[Total]]/표1_5[[#This Row],[시나리오 수]],0) -> 0 | J46: =IFERROR(SUM(표1_5[[#This Row],[Pass]:[Fail]])/표1_5[[#This Row],[시나리오 수]],0) -> 0 | K46: =IFERROR(표1_5[[#This Row],[Pass]]/SUM(표1_5[[#This Row],[Pass]:[Fail]]),0) -> 0 | L46: =IFERROR((표1_5[[#This Row],[Fail]]/SUM(표1_5[[#This Row],[Pass]:[Fail]])),0) -> 0 | M46: =IFERROR((표1_5[[#This Row],[Block]]/표1_5[[#This Row],[시나리오 수]]),0) -> 0
B48: 임직원 인증 Sheet
B50: SYS | C50: 시나리오 수 | D50: Pass | E50: Fail | F50: Block | G50: N/A | H50: Total | I50: 진척율 | J50: 수행율 | K50: 성공율 | L50: 결함율 | M50: 수행불가율
B51: FO | C51: =COUNTIF(TS_임직원인증[SYS],표1_6[[#This Row],[SYS]]) -> 8 | D51: =COUNTIFS('6_임직원 인증'!$F:$F,표1_6[[#This Row],[SYS]],'6_임직원 인증'!$N:$N,표1_6[[#Headers],[Pass]]) -> 0 | E51: =COUNTIFS('6_임직원 인증'!$F:$F,표1_6[[#This Row],[SYS]],'6_임직원 인증'!$N:$N,표1_6[[#Headers],[Fail]]) -> 0 | F51: =COUNTIFS('6_임직원 인증'!$F:$F,표1_6[[#This Row],[SYS]],'6_임직원 인증'!$N:$N,표1_6[[#Headers],[Block]]) -> 0 | G51: =COUNTIFS('6_임직원 인증'!$F:$F,표1_6[[#This Row],[SYS]],'6_임직원 인증'!$N:$N,표1_6[[#Headers],[N/A]]) -> 0 | H51: =SUM(표1_6[[#This Row],[Pass]:[N/A]]) -> 0 | I51: =IFERROR(표1_6[[#This Row],[Total]]/표1_6[[#This Row],[시나리오 수]],0) -> 0 | J51: =IFERROR(SUM(표1_6[[#This Row],[Pass]:[Fail]])/(표1_6[[#This Row],[시나리오 수]]-표1_6[[#This Row],[N/A]]),0) -> 0 | K51: =IFERROR(표1_6[[#This Row],[Pass]]/SUM(표1_6[[#This Row],[Pass]:[Fail]]),0) -> 0 | L51: =IFERROR((표1_6[[#This Row],[Fail]]/SUM(표1_6[[#This Row],[Pass]:[Fail]])),0) -> 0 | M51: =IFERROR((표1_6[[#This Row],[Block]]/표1_6[[#This Row],[시나리오 수]]),0) -> 0
B52: MO | C52: =COUNTIF(TS_임직원인증[SYS],표1_6[[#This Row],[SYS]]) -> 8 | D52: =COUNTIFS('6_임직원 인증'!$F:$F,표1_6[[#This Row],[SYS]],'6_임직원 인증'!$N:$N,표1_6[[#Headers],[Pass]]) -> 0 | E52: =COUNTIFS('6_임직원 인증'!$F:$F,표1_6[[#This Row],[SYS]],'6_임직원 인증'!$N:$N,표1_6[[#Headers],[Fail]]) -> 0 | F52: =COUNTIFS('6_임직원 인증'!$F:$F,표1_6[[#This Row],[SYS]],'6_임직원 인증'!$N:$N,표1_6[[#Headers],[Block]]) -> 0 | G52: =COUNTIFS('6_임직원 인증'!$F:$F,표1_6[[#This Row],[SYS]],'6_임직원 인증'!$N:$N,표1_6[[#Headers],[N/A]]) -> 0 | H52: =SUM(표1_6[[#This Row],[Pass]:[N/A]]) -> 0 | I52: =IFERROR(표1_6[[#This Row],[Total]]/표1_6[[#This Row],[시나리오 수]],0) -> 0 | J52: =IFERROR(SUM(표1_6[[#This Row],[Pass]:[Fail]])/(표1_6[[#This Row],[시나리오 수]]-표1_6[[#This Row],[N/A]]),0) -> 0 | K52: =IFERROR(표1_6[[#This Row],[Pass]]/SUM(표1_6[[#This Row],[Pass]:[Fail]]),0) -> 0 | L52: =IFERROR((표1_6[[#This Row],[Fail]]/SUM(표1_6[[#This Row],[Pass]:[Fail]])),0) -> 0 | M52: =IFERROR((표1_6[[#This Row],[Block]]/표1_6[[#This Row],[시나리오 수]]),0) -> 0
B53: BO | C53: =COUNTIF(TS_임직원인증[SYS],표1_6[[#This Row],[SYS]]) -> 12 | D53: =COUNTIFS('6_임직원 인증'!$F:$F,표1_6[[#This Row],[SYS]],'6_임직원 인증'!$N:$N,표1_6[[#Headers],[Pass]]) -> 0 | E53: =COUNTIFS('6_임직원 인증'!$F:$F,표1_6[[#This Row],[SYS]],'6_임직원 인증'!$N:$N,표1_6[[#Headers],[Fail]]) -> 0 | F53: =COUNTIFS('6_임직원 인증'!$F:$F,표1_6[[#This Row],[SYS]],'6_임직원 인증'!$N:$N,표1_6[[#Headers],[Block]]) -> 0 | G53: =COUNTIFS('6_임직원 인증'!$F:$F,표1_6[[#This Row],[SYS]],'6_임직원 인증'!$N:$N,표1_6[[#Headers],[N/A]]) -> 0 | H53: =SUM(표1_6[[#This Row],[Pass]:[N/A]]) -> 0 | I53: =IFERROR(표1_6[[#This Row],[Total]]/표1_6[[#This Row],[시나리오 수]],0) -> 0 | J53: =IFERROR(SUM(표1_6[[#This Row],[Pass]:[Fail]])/(표1_6[[#This Row],[시나리오 수]]-표1_6[[#This Row],[N/A]]),0) -> 0 | K53: =IFERROR(표1_6[[#This Row],[Pass]]/SUM(표1_6[[#This Row],[Pass]:[Fail]]),0) -> 0 | L53: =IFERROR((표1_6[[#This Row],[Fail]]/SUM(표1_6[[#This Row],[Pass]:[Fail]])),0) -> 0 | M53: =IFERROR((표1_6[[#This Row],[Block]]/표1_6[[#This Row],[시나리오 수]]),0) -> 0
...

Sheet 0_목록
B7: No. | C7: 프로세스 | D7: 시나리오 ID | E7: 시나리오명 | F7: 비고
B8: 1 | C8: 회원가입 | D8: IT-MB-001 | E8: 회원가입
B9: 2 | D9: IT-MB-002 | E9: 회원관리
B10: 3 | C10: 회원전환 | D10: IT-MB-003 | E10: 회원전환
B11: 4 | C11: 로그인 | D11: IT-MB-004 | E11: 로그인
B12: 5 | C12: ID 찾기 | D12: IT-MB-005 | E12: ID 찾기
B13: 6 | C13: PW 찾기 | D13: IT-MB-006 | E13: PW 찾기
B14: 7 | C14: 임직원인증 | D14: IT-MB-007 | E14: 임직원인증
B15: 8 | C15: 회원탈퇴 | D15: IT-MB-008 | E15: 회원탈퇴
B16: 9 | D16: IT-MB-009 | E16: 휴면예정회원

Sheet 1_회원가입
B2: 참조 문서 | C2: ABC_04.설계_03.프로세스정의서_01.회원_20190425_v1.10.pptx.pptx ABC_04.설계_02.화면설계서_FO_02.회원_20190502_v1.10.pptx ABC_04.설계_02.화면설계서_MO_02.회원_20190502_v1.02.pptx ABC_04.설계_02.화면설계서_BO_01_회원_20190429_v2.02.pptx
B4: 프로세스
B34: 시나리오 순서
B35: 1. 회원가입 (IT-MB-001) - 통합멤버십회원 : 1 > 2 > 3 > 4 > 5 > 6 > 7 > 8 > 9 - 온라인회원 : 10 > 11 > 12 > 13 > 14 > 15 > 16 > 17 2. 회원관리 (IT-MB-002)
B36: 테스트 사전 준비사항
B37: 통합멤버십회원, 온라인회원 가입이 가능한 계정정보(핸드폰, 아이핀 인증이 가능한 사용자)
B39: No. | C39: 사이트 | D39: ID | E39: 시나리오명 | F39: SYS | G39: 중요도 | H39: 테스트 항목 | I39: 수행 절차 | J39: 입력값 | K39: 기대 결과 | L39: 수행일자 | M39: 수행자 | N39: 테스트결과 | O39: 결함사항 | P39: 수정여부 | Q39: 비고
B40: 1 | C40: A-RT | D40: IT-MB-001-001 | E40: 회원가입 | F40: FO | G40: 상 | H40: [통합멤버십] 회원가입 | I40: 1. 회원가입 버튼선택 - 통합멤버십 | K40: 통합멤버십 약관동의 화면으로 이동
B41: 2 | C41: A-RT | D41: IT-MB-001-002 | E41: 회원가입 | F41: FO | G41: 중 | H41: [통합멤버십] 약관동의 | I41: 1. 회원가입 > 약관동의 2. 약관동의 체크 3. 하단 인증 버튼 선택 | J41: 체크박스 체크 | K41: 필수 체크 기능확인
B42: 3 | C42: A-RT | D42: IT-MB-001-003 | E42: 회원가입 | F42: FO | G42: 중 | H42: [통합멤버십] 인증 | I42: 1. 회원가입 > 약관동의 2. 휴대폰 인증 선택 | J42: 인증 정보입력 | K42: 정상 인증 후 하단에 인증 정보 입력 확인 - 이름/생년월일/휴대폰번호
B43: 4 | C43: A-RT | D43: IT-MB-001-004 | E43: 회원가입 | F43: FO | G43: 중 | I43: 1. 회원가입 > 약관동의 2. 아이핀 인증 선택 | J43: 인증 정보입력 | K43: 정상 인증 후 하단에 인증이 완료 확인
B44: 5 | C44: A-RT | D44: IT-MB-001-005 | E44: 회원가입 | F44: FO | G44: 중 | I44: 1. 회원가입 > 약관동의 2. 아이핀 인증 선택 | K44: 아이핀 인증시 하단 휴대폰 인증 확인
B45: 6 | C45: A-RT | D45: IT-MB-001-006 | E45: 회원가입 | F45: FO | G45: 상 | H45: [통합멤버십] 회원정보입력 | I45: 1. 회원가입 > 약관동의 > 인증 > 정보입력 2. 각 필드 입력 항목에 텍스트 입력 | J45: 이름, 생년월일, 아이디, 비밀번호, 비밀번호 확인, 이메일, 휴대폰번호, 마케팅 동의여부, 단골매장설정 | K45: 필드 정보 입력 후 회원가입 버튼 선택 시 완료 페이지로 이동 확인
B46: 7 | C46: A-RT | D46: IT-MB-001-007 | E46: 회원가입 | F46: FO | G46: 중 | I46: 1. 회원가입 > 약관동의 > 인증 > 정보입력 2. 각 필드 입력 항목에 텍스트 입력 | K46: 비밀번호, 이메일은 조합 양식 입력 확인
B47: 8 | C47: A-RT | D47: IT-MB-001-008 | E47: 회원가입 | F47: FO | G47: 상 | H47: [통합멤버십] 아이디/이메일 중복체크 | I47: 1. 회원가입 > 약관동의 > 인증 > 회원정보입력 2. 아이디/이메일 중복체크 확인 | J47: 아이디/이메일 | K47: 아이디와 이메일 입력 완료시중복체크가 정상 동작 확인
B48: 9 | C48: A-RT | D48: IT-MB-001-009 | E48: 회원가입 | F48: FO | G48: 중 | H48: [통합멤버십] 가입축하 메일발송 | I48: 1. 회원가입 > 약관동의 > 인증 > 회원정보입력 2. 회원가입 완료 버튼 선택 | J48: 회원가입 버튼 선택 | K48: 회원가입 완료시 가입축하메일이 발송 확인
B49: 10 | C49: A-RT | D49: IT-MB-001-010 | E49: 회원가입 | F49: FO | G49: 상 | H49: [통합멤버십] 쇼핑몰 로그인 | I49: 1. 회원가입 > 약관동의 > 인증 > 회원정보입력 2. 회원가입 완료 > 로그인 | J49: 통합멤버십 회원 아이디 비밀번호 입력 | K49: 신규 가입한 아이디/비밀번호로 로그인 확인 - 통합멤버십회원 등급 확인
B50: 11 | C50: A-RT | D50: IT-MB-001-011 | E50: 회원가입 | F50: FO | G50: 중 | H50: [온라인회원] 회원가입 | I50: 1. 회원가입 버튼선택 - 온라인회원 | K50: 온라인회원 약관동의 화면으로 이동
B51: 12 | C51: A-RT | D51: IT-MB-001-012 | E51: 회원가입 | F51: FO | G51: 중 | H51: [온라인회원] 약관동의 | I51: 1. 회원가입 > 약관동의 2. 약관동의 체크 3. 하단 인증 버튼 선택 | J51: 체크박스 체크 | K51: 필수 체크 기능확인
B52: 13 | C52: A-RT | D52: IT-MB-001-013 | E52: 회원가입 | F52: FO | G52: 상 | H52: [온라인회원] 회원정보입력 | I52: 1. 회원가입 > 약관동의 > 정보입력 2. 각 필드 입력 항목에 텍스트 입력 | J52: 이름, 아이디, 비밀번호, 비밀번호 확인, 이메일, 휴대폰번호, 마케팅 동의여부 | K52: 필드 정보 입력 후 회원가입 선택, 완료 페이지로 이동 확인
B53: 14 | C53: A-RT | D53: IT-MB-001-014 | E53: 회원가입 | F53: FO | G53: 상 | H53: [온라인회원] 휴대폰 인증 | I53: 1. 회원가입 > 약관동의 > 정보입력 2. 휴대폰 인증 선택 | J53: 인증 정보입력 | K53: 정상 인증 후 하단에 인증 정보 입력 확인 - 이름/생년월일/휴대폰번호
B54: 15 | C54: A-RT | D54: IT-MB-001-015 | E54: 회원가입 | F54: FO | G54: 중 | H54: [온라인회원] 가입축하 메일발송 | I54: 1. 회원가입 > 약관동의 > 정보입력 2. 회원가입 완료 | J54: 회원가입 버튼 선택 | K54: 회원가입 완료시 가입축하메일이 발송 확인
B55: 16 | C55: A-RT | D55: IT-MB-001-016 | E55: 회원가입 | F55: FO | G55: 상 | H55: [온라인회원] 쇼핑몰 로그인 | I55: 1. 회원가입 > 약관동의 > 인증 > 회원정보입력 2. 회원가입 완료 > 로그인 | J55: 온라인 회원 아이디 비밀번호 입력 | K55: 신규 가입한 아이디/비밀번호로 로그인 확인 - 온라인회원 등급 확인
B56: 17 | C56: A-RT | D56: IT-MB-001-017 | E56: 회원가입 | F56: MO | G56: 상 | H56: [통합멤버십] 회원가입 | I56: 1. 회원가입 버튼선택 - 통합멤버십 | K56: 통합멤버십 약관동의 화면으로 이동
B57: 18 | C57: A-RT | D57: IT-MB-001-018 | E57: 회원가입 | F57: MO | G57: 중 | H57: [통합멤버십] 약관동의 | I57: 1. 회원가입 > 약관동의 2. 약관동의 체크 3. 하단 인증 버튼 선택 | J57: 체크박스 체크 | K57: 필수 체크 기능확인
B58: 19 | C58: A-RT | D58: IT-MB-001-019 | E58: 회원가입 | F58: MO | G58: 중 | H58: [통합멤버십] 인증 | I58: 1. 회원가입 > 약관동의 2. 휴대폰 인증 선택 | J58: 인증 정보입력 | K58: 정상 인증 후 하단에 인증 정보 입력 확인 - 이름/생년월일/휴대폰번호
B59: 20 | C59: A-RT | D59: IT-MB-001-020 | E59: 회원가입 | F59: MO | G59: 중 | I59: 1. 회원가입 > 약관동의 2. 아이핀 인증 선택 | J59: 인증 정보입력 | K59: 정상 인증 후 하단에 인증이 완료 확인
B60: 21 | C60: A-RT | D60: IT-MB-001-021 | E60: 회원가입 | F60: MO | G60: 중 | I60: 1. 회원가입 > 약관동의 2. 아이핀 인증 선택 | K60: 아이핀 인증시 하단 휴대폰 인증 확인
B61: 22 | C61: A-RT | D61: IT-MB-001-022 | E61: 회원가입 | F61: MO | G61: 상 | H61: [통합멤버십] 회원정보입력 | I61: 1. 회원가입 > 약관동의 > 인증 > 정보입력 2. 각 필드 입력 항목에 텍스트 입력 | J61: 이름, 생년월일, 아이디, 비밀번호, 비밀번호 확인, 이메일, 휴대폰번호, 마케팅 동의여부, 단골매장설정 | K61: 필드 정보 입력 후 회원가입 버튼 선택 시 완료 페이지로 이동 확인
B62: 23 | C62: A-RT | D62: IT-MB-001-023 | E62: 회원가입 | F62: MO | G62: 중 | I62: 1. 회원가입 > 약관동의 > 인증 > 정보입력 2. 각 필드 입력 항목에 텍스트 입력 | K62: 비밀번호, 이메일은 조합 양식 입력 확인
B63: 24 | C63: A-RT | D63: IT-MB-001-024 | E63: 회원가입 | F63: MO | G63: 상 | H63: [통합멤버십] 아이디/이메일 중복체크 | I63: 1. 회원가입 > 약관동의 > 인증 > 회원정보입력 2. 아이디/이메일 중복체크 확인 | J63: 아이디/이메일 | K63: 아이디와 이메일 입력 완료시중복체크가 정상 동작 확인
B64: 25 | C64: A-RT | D64: IT-MB-001-025 | E64: 회원가입 | F64: MO | G64: 중 | H64: [통합멤버십] 가입축하 메일발송 | I64: 1. 회원가입 > 약관동의 > 인증 > 회원정보입력 2. 회원가입 버튼 선택 | J64: 회원가입 버튼 선택 | K64: 회원가입 완료시 가입축하메일이 발송 확인
B65: 26 | C65: A-RT | D65: IT-MB-001-026 | E65: 회원가입 | F65: MO | G65: 상 | H65: [통합멤버십] 쇼핑몰 로그인 | I65: 1. 회원가입 > 약관동의 > 인증 > 회원정보입력 2. 회원가입 완료 > 로그인 | J65: 통합멤버십 회원 아이디 비밀번호 입력 | K65: 신규 가입한 아이디/비밀번호로 로그인 확인 - 통합멤버십회원 등급 확인
B66: 27 | C66: A-RT | D66: IT-MB-001-027 | E66: 회원가입 | F66: MO | G66: 중 | H66: [온라인회원] 회원가입 | I66: 1. 회원가입 버튼선택 - 온라인회원 | K66: 온라인회원 약관동의 화면으로 이동
B67: 28 | C67: A-RT | D67: IT-MB-001-028 | E67: 회원가입 | F67: MO | G67: 중 | H67: [온라인회원] 약관동의 | I67: 1. 회원가입 > 약관동의 2. 약관동의 체크 3. 하단 인증 버튼 선택 | J67: 체크박스 체크 | K67: 필수 체크 기능확인
B68: 29 | C68: A-RT | D68: IT-MB-001-029 | E68: 회원가입 | F68: MO | G68: 상 | H68: [온라인회원] 회원정보입력 | I68: 1. 회원가입 > 약관동의 > 정보입력 2. 각 필드 입력 항목에 텍스트 입력 | J68: 이름, 아이디, 비밀번호, 비밀번호 확인, 이메일, 휴대폰번호, 마케팅 동의여부 | K68: 필드 정보 입력 후 회원가입 선택, 완료 페이지로 이동 확인
B69: 30 | C69: A-RT | D69: IT-MB-001-030 | E69: 회원가입 | F69: MO | G69: 상 | H69: [온라인회원] 휴대폰 인증 | I69: 1. 회원가입 > 약관동의 > 정보입력 2. 휴대폰 인증 선택 | J69: 인증 정보입력 | K69: 정상 인증 후 하단에 인증 정보 입력 확인 - 이름/생년월일/휴대폰번호
B70: 31 | C70: A-RT | D70: IT-MB-001-031 | E70: 회원가입 | F70: MO | G70: 중 | H70: [온라인회원] 가입축하 메일발송 | I70: 1. 회원가입 > 약관동의 > 정보입력 2. 회원가입 완료 | J70: 회원가입 버튼 선택 | K70: 회원가입 완료시 가입축하메일이 발송 확인
B71: 32 | C71: A-RT | D71: IT-MB-001-032 | E71: 회원가입 | F71: MO | G71: 상 | H71: [온라인회원] 쇼핑몰 로그인 | I71: 1. 회원가입 > 약관동의 > 인증 > 회원정보입력 2. 회원가입 완료 > 로그인 | J71: 온라인 회원 아이디 비밀번호 입력 | K71: 신규 가입한 아이디/비밀번호로 로그인 확인 - 온라인회원 등급 확인
B72: 33 | C72: OTS | D72: IT-MB-001-033 | E72: 회원가입 | F72: FO | G72: 상 | H72: [통합멤버십] 회원가입 | I72: 1. 회원가입 버튼선택 - 통합멤버십 | K72: 통합멤버십 약관동의 화면으로 이동
...

Sheet 2_회원전환
B2: 참조 문서 | C2: ABC_04.설계_03.프로세스정의서_01.회원_20190425_v1.10.pptx ABC_04.설계_02.화면설계서_FO_02.회원_20190502_v1.10.pptx ABC_04.설계_02.화면설계서_MO_02.회원_20190502_v1.02.pptx ABC_04.설계_02.화면설계서_BO_01_회원_20190429_v2.02.pptx
B4: 프로세스
B34: 시나리오 순서
B35: 1. 회원전환 (IT-MB-003) - 멤버십회원 > 통합멤버십회원 : 1 > 2 > 10 > 11 - 온라인,SNS > 통합멤버십회원 : 3 > 4 > 5 > 6 > 7 > 8 > 9 > 10 > 11 - SNS > 온라인회원 : 12 > 13 > 14 > 15 > 16 > 17 > 18 > 19
B36: 테스트 사전 준비사항
B37: 온라인회원, SNS회원 중 가입이 가능한 계정정보(핸드폰, 아이핀 인증이 가능한 사용자)
B39: No. | C39: 사이트 | D39: ID | E39: 시나리오명 | F39: SYS | G39: 중요도 | H39: 테스트 항목 | I39: 수행 절차 | J39: 입력값 | K39: 기대 결과 | L39: 수행일자 | M39: 수행자 | N39: 테스트결과 | O39: 결함사항 | P39: 수정여부 | Q39: 비고
B40: 1 | C40: A-RT | D40: IT-MB-003-001 | E40: 회원 전환 | F40: FO | G40: 상 | H40: 회원전환 [멤버십회원 > 통합멤버십] | I40: 1. 멤버십회원 로그인 > 회원전환 팝업창 2. 통합멤버십회원 전환 버튼 선택 | K40: 통합멤버십 약관동의 화면으로 이동
B41: 2 | C41: A-RT | D41: IT-MB-003-002 | E41: 회원 전환 | F41: FO | G41: 중 | H41: 약관동의 | I41: 1. 회원 전환 페이지 2. 약관동의 체크후 하단 회원전환 버튼 선택 | J41: 체크박스 체크 | K41: 필수 체크 기능 확인
B42: 3 | C42: A-RT | D42: IT-MB-003-003 | E42: 회원 전환 | F42: FO | G42: 중 | H42: 전환 메일 발송 | I42: 1. 회원 전환 페이지 2. 하단 회원전환 버튼 선택 | K42: 전환 완료시 통합멤버십 전환메일 발송 확인
B43: 4 | C43: A-RT | D43: IT-MB-003-004 | E43: 회원 전환 | F43: FO | G43: 상 | H43: 쇼핑몰 로그인 | I43: 1. 로그인 2. 전환된 통합멤버십회원 아이디 비밀번호 입력 | J43: 아이디/비밀번호 | K43: 전환한 아이디/비밀번호로 로그인 확인- 통합멤버십회원 등급 확인
B44: 5 | C44: A-RT | D44: IT-MB-003-005 | E44: 회원 전환 | F44: BO | G44: 상 | H44: 통합멤버십 전환고객 확인 | I44: 1. 회원관리 > 회원목록 2. 통합멤버십회원 검색 | K44: 통합멤버십으로 전환된 회원 정보 확인
B45: 6 | C45: A-RT | D45: IT-MB-003-006 | E45: 회원 전환 | F45: FO | G45: 상 | H45: 회원전환 [SNS,온라인회원 > 통합멤버십] | I45: 1. SNS, 온라인회원 로그인 > 회원전환 팝업창 2. 통합멤버십회원 전환 선택 | K45: 통합멤버십 약관동의 화면으로 이동
B46: 7 | C46: A-RT | D46: IT-MB-003-007 | E46: 회원 전환 | F46: FO | G46: 중 | H46: 약관동의 | I46: 1. 회원 전환 페이지 2. 약관동의 체크후 하단 회원전환 버튼 선택 | J46: 체크박스 체크 | K46: 필수 체크 기능 확인
B47: 8 | C47: A-RT | D47: IT-MB-003-008 | E47: 회원 전환 | F47: FO | G47: 중 | H47: 인증 | I47: 1. 회원 전환 페이지 2. 휴대폰 인증 선택 | J47: 인증 정보입력 | K47: 정상적으로 인증후 하단에 인증 정보(이름/생년월일/휴대폰번호)가 입력되는지 확인 - 기존 아이디와 이메일을 정확하게 불러오는지 확인
B48: 9 | C48: A-RT | D48: IT-MB-003-009 | E48: 회원 전환 | F48: FO | G48: 중 | H48: 인증 | I48: 1. 회원 전환 페이지 2. 아이핀 인증 선택 | J48: 인증 정보입력 | K48: 정상적으로 인증후 하단에 인증이 완료 확인 - 아이핀 인증시 하단 휴대폰 인증 확인 - 기존 아이디와 이메일을 정확하게 불러오는지 확인
B49: 10 | C49: A-RT | D49: IT-MB-003-010 | E49: 회원 전환 | F49: FO | G49: 상 | H49: 회원정보입력 | I49: 1. 회원 전환 페이지 2. 각 필드 입력 항목에 텍스트 입력 | J49: 비밀번호, 비밀번호 확인 휴대폰번호, 마케팅 동의여부 | K49: 필드 정보 입력 후 회원전환 선택 > 완료 페이지로 이동 확인
B50: 11 | C50: A-RT | D50: IT-MB-003-011 | E50: 회원 전환 | F50: FO | G50: 중 | H50: 전환 메일 발송 | I50: 1. 회원 전환 페이지 2. 하단 회원전환 버튼 선택 | K50: 전환 완료시 통합멤버십 전환메일 발송 확인
B51: 12 | C51: A-RT | D51: IT-MB-003-012 | E51: 회원 전환 | F51: FO | G51: 상 | H51: 쇼핑몰 로그인 | I51: 1. 로그인 2. 전환된 통합멤버십회원 아이디 비밀번호 입력 | J51: 아이디/비밀번호 | K51: 전환한 아이디/비밀번호로 로그인 확인- 통합멤버십회원 등급 확인
B52: 13 | C52: A-RT | D52: IT-MB-003-013 | E52: 회원 전환 | F52: BO | G52: 상 | H52: 통합멤버십 전환고객 확인 | I52: 1. 회원관리 > 회원목록 2. 통합멤버십회원 검색 | K52: 통합멤버십으로 전환된 회원 정보 확인
B53: 14 | C53: A-RT | D53: IT-MB-003-014 | E53: 회원 전환 | F53: FO | G53: 상 | H53: 회원전환 [SNS > 온라인회원] | I53: 1. SNS 로그인 > 회원전환 팝업창 2. 온라인회원 전환 선택 | K53: 온라인회원 약관동의 화면으로 이동
B54: 15 | C54: A-RT | D54: IT-MB-003-015 | E54: 회원 전환 | F54: FO | G54: 중 | H54: 약관동의 | I54: 1. 회원 전환 페이지 2. 약관동의 체크후 하단 회원전환 버튼 선택 | J54: 체크박스 체크 | K54: 필수 체크 기능 확인
B55: 16 | C55: A-RT | D55: IT-MB-003-016 | E55: 회원 전환 | F55: FO | G55: 상 | H55: 회원정보입력 | I55: 1. 회원 전환 페이지 2. 각 필드 입력 항목에 텍스트 입력 | J55: 이름, 아이디, 비밀번호, 비밀번호 확인 이메일, 휴대폰번호, 마케팅 동의여부 | K55: 필드 정보 입력 후 회원가입 선택, 완료 페이지로 이동 확인
B56: 17 | C56: A-RT | D56: IT-MB-003-017 | E56: 회원 전환 | F56: FO | G56: 상 | H56: 휴대폰 인증 | I56: 1. 회원 전환 페이지 2. 휴대폰 인증 선택 | J56: 인증 정보입력 | K56: 정상적으로 인증후 하단에 인증 정보(이름/생년월일/휴대폰번호)가 입력되는지 확인
B57: 18 | C57: A-RT | D57: IT-MB-003-018 | E57: 회원 전환 | F57: FO | G57: 중 | H57: 전환 메일 발송 | I57: 1. 회원 전환 페이지 2. 하단 회원전환 버튼 선택 | K57: 전환 완료시 통합멤버십 전환메일 발송 확인
B58: 19 | C58: A-RT | D58: IT-MB-003-019 | E58: 회원 전환 | F58: FO | G58: 상 | H58: 쇼핑몰 로그인 | I58: 1. 로그인 2. 전환된 온라인회원 아이디 비밀번호 입력 | J58: 아이디/비밀번호 | K58: 신규 가입한 아이디/비밀번호로 로그인 확인- 온라인회원 등급 확인
B59: 20 | C59: A-RT | D59: IT-MB-003-020 | E59: 회원 전환 | F59: BO | G59: 상 | H59: 통합멤버십 전환고객 확인 | I59: 1. 회원관리 > 회원목록 2. 온라인 회원 검색 | K59: 온라인회원으로 전환된 회원 정보 확인
B60: 21 | C60: A-RT | D60: IT-MB-003-021 | E60: 회원 전환 | F60: MO | G60: 상 | H60: 회원전환 [멤버십회원 > 통합멤버십] | I60: 1. 멤버십회원 로그인 > 회원전환 팝업창 2. 통합멤버십회원 전환 버튼 선택 | K60: 통합멤버십 약관동의 화면으로 이동
B61: 22 | C61: A-RT | D61: IT-MB-003-022 | E61: 회원 전환 | F61: MO | G61: 중 | H61: 약관동의 | I61: 1. 회원 전환 페이지 2. 약관동의 체크후 하단 회원전환 버튼 선택 | J61: 체크박스 체크 | K61: 필수 체크 기능 확인
B62: 23 | C62: A-RT | D62: IT-MB-003-023 | E62: 회원 전환 | F62: MO | G62: 중 | H62: 전환 메일 발송 | I62: 1. 회원 전환 페이지 2. 하단 회원전환 버튼 선택 | K62: 전환 완료시 통합멤버십 전환메일 발송 확인
B63: 24 | C63: A-RT | D63: IT-MB-003-024 | E63: 회원 전환 | F63: MO | G63: 상 | H63: 쇼핑몰 로그인 | I63: 1. 로그인 2. 전환된 통합멤버십회원 아이디 비밀번호 입력 | J63: 아이디/비밀번호 | K63: 전환한 아이디/비밀번호로 로그인 확인- 통합멤버십회원 등급 확인
B64: 25 | C64: A-RT | D64: IT-MB-003-025 | E64: 회원 전환 | F64: BO | G64: 상 | H64: 통합멤버십 전환고객 확인 | I64: 1. 회원관리 > 회원목록 2. 통합멤버십회원 검색 | K64: 통합멤버십으로 전환된 회원 정보 확인
B65: 26 | C65: A-RT | D65: IT-MB-003-026 | E65: 회원 전환 | F65: MO | G65: 상 | H65: 회원전환 [SNS,온라인회원 > 통합멤버십] | I65: 1. SNS, 온라인회원 로그인 > 회원전환 팝업창 2. 통합멤버십회원 전환 선택 | K65: 통합멤버십 약관동의 화면으로 이동
B66: 27 | C66: A-RT | D66: IT-MB-003-027 | E66: 회원 전환 | F66: MO | G66: 중 | H66: 약관동의 | I66: 1. 회원 전환 페이지 2. 약관동의 체크후 하단 회원전환 버튼 선택 | J66: 체크박스 체크 | K66: 필수 체크 기능 확인
B67: 28 | C67: A-RT | D67: IT-MB-003-028 | E67: 회원 전환 | F67: MO | G67: 중 | H67: 인증 | I67: 1. 회원 전환 페이지 2. 휴대폰 인증 선택 | J67: 인증 정보입력 | K67: 정상적으로 인증후 하단에 인증 정보(이름/생년월일/휴대폰번호)가 입력되는지 확인 - 기존 아이디와 이메일을 정확하게 불러오는지 확인
B68: 29 | C68: A-RT | D68: IT-MB-003-029 | E68: 회원 전환 | F68: MO | G68: 중 | H68: 인증 | I68: 1. 회원 전환 페이지 2. 아이핀 인증 선택 | J68: 인증 정보입력 | K68: 정상적으로 인증후 하단에 인증이 완료 확인 - 아이핀 인증시 하단 휴대폰 인증 확인 - 기존 아이디와 이메일을 정확하게 불러오는지 확인
B69: 30 | C69: A-RT | D69: IT-MB-003-030 | E69: 회원 전환 | F69: MO | G69: 상 | H69: 회원정보입력 | I69: 1. 회원 전환 페이지 2. 각 필드 입력 항목에 텍스트 입력 | J69: 비밀번호, 비밀번호 확인 휴대폰번호, 마케팅 동의여부 | K69: 필드 정보 입력 후 회원전환 선택 > 완료 페이지로 이동 확인
B70: 31 | C70: A-RT | D70: IT-MB-003-031 | E70: 회원 전환 | F70: MO | G70: 중 | H70: 전환 메일 발송 | I70: 1. 회원 전환 페이지 2. 하단 회원전환 버튼 선택 | K70: 전환 완료시 통합멤버십 전환메일 발송 확인
B71: 32 | C71: A-RT | D71: IT-MB-003-032 | E71: 회원 전환 | F71: MO | G71: 상 | H71: 쇼핑몰 로그인 | I71: 1. 로그인 2. 전환된 통합멤버십회원 아이디 비밀번호 입력 | J71: 아이디/비밀번호 | K71: 전환한 아이디/비밀번호로 로그인 확인- 통합멤버십회원 등급 확인
B72: 33 | C72: A-RT | D72: IT-MB-003-033 | E72: 회원 전환 | F72: BO | G72: 상 | H72: 통합멤버십 전환고객 확인 | I72: 1. 회원관리 > 회원목록 2. 통합멤버십회원 검색 | K72: 통합멤버십으로 전환된 회원 정보 확인
...

Sheet 3_로그인
B2: 참조 문서 | C2: ABC_04.설계_03.프로세스정의서_01.회원_20190425_v1.10.pptx ABC_04.설계_02.화면설계서_FO_02.회원_20190502_v1.10.pptx ABC_04.설계_02.화면설계서_MO_02.회원_20190502_v1.02.pptx ABC_04.설계_02.화면설계서_BO_01_회원_20190429_v2.02.pptx
B4: 프로세스
B34: 시나리오 순서
B35: 1. 로그인 (IT-MB-004) - 회원 로그인 : 1 > 2 > 3 > 4 > 5 - SNS 로그인 : 6 > 7 > 8 > 9
B36: 테스트 사전 준비사항
B37: 통합멤버십회원, 온라인회원, SNS회원(페이스북, 네이버, 카카오) 계정별 로그인이 가능한 ID, PW
B39: No. | C39: 사이트 | D39: ID | E39: 시나리오명 | F39: SYS | G39: 중요도 | H39: 테스트 항목 | I39: 수행 절차 | J39: 입력값 | K39: 기대 결과 | L39: 수행일자 | M39: 수행자 | N39: 테스트결과 | O39: 결함사항 | P39: 수정여부 | Q39: 비고
B40: 1 | C40: A-RT | D40: IT-MB-004-001 | E40: 로그인 | F40: FO | G40: 상 | H40: 로그인 페이지 | I40: 1. 로그인 페이지 2. 각 버튼 링크 확인 - 회원로그인탭, 비회원 주문조회, 페이스북로그인, 네이버로그인, 카카오로그인, 아이디찾기, 비밀번호찾기, 회원가입, 비회원 주문 버튼 선택 | K40: 각 버튼의 링크가 정확하게 이동되는지 확인
B41: 2 | C41: A-RT | D41: IT-MB-004-002 | E41: 로그인 | F41: FO | G41: 상 | H41: 정상 로그인 | I41: 1. 로그인 페이지 2. 통합멤버십회원 로그인 확인 | J41: 통합멤버십회원 ID, PW 입력 | K41: 로그인 후 로그인 이전 페이지 이동(예 : 장바구니페이지에서 로그인 완료후 장바구니페이지로 이동)
B42: 3 | C42: A-RT | D42: IT-MB-004-003 | E42: 로그인 | F42: FO | G42: 상 | H42: 정상 로그인 | I42: 1. 로그인 페이지 2. 멤버십회원 로그인 확인 | J42: 통합멤버십회원 ID, PW 입력 | K42: 멤버십회원인 경우 회원전환 페이지 팝업 노출 - 로그인 후 로그인 이전 페이지 이동 확인
B43: 4 | C43: A-RT | D43: IT-MB-004-004 | E43: 로그인 | F43: FO | G43: 상 | H43: 정상 로그인 | I43: 1. 로그인 페이지 2. 온라인회원 로그인 확인 | J43: 온라인회원 ID, PW 입력 | K43: 온라인회원인 경우 회원전환 페이지 팝업 노출 - 로그인 후 로그인 이전 페이지 이동 확인
B44: 5 | C44: A-RT | D44: IT-MB-004-005 | E44: 로그인 | F44: FO | G44: 중 | H44: 탈퇴회원 로그인 | I44: 1. 로그인 페이지 2. 탈퇴회원 로그인 확인 - 회원 구분별 ID, PW 입력 후 탈퇴회원 안내 확인 | J44: 탈퇴후 14일 이내회원 ID, PW입력 | K44: 탈퇴회원안내 팝업 노출
B45: 6 | C45: A-RT | D45: IT-MB-004-006 | E45: 로그인 | F45: FO | G45: 중 | H45: 비밀번호 오류 | I45: 1. 로그인 페이지 2. PW 오류 로그인 확인 | J45: PW 입력 5회 오류 | K45: 5회 비밀번호 오류시 보안문자입력 팝업창 노출 - 보안문자 새로고침 확인 - 보안문자 정상 입력시 로그인페이지로 이동
B46: 7 | C46: A-RT | D46: IT-MB-004-007 | E46: 로그인 | F46: FO | G46: 중 | H46: 비밀번호 변경이력 확인 | I46: 1. 로그인 페이지 2. N일내 비밀번호 변경이력이 없는 회원의 로그인 확인 | J46: N일내 비밀번호 변경이력이 없는 회원의 ID, PW 입력 | K46: 로그인 완료 후 N일내 PW변경 이력이 없는 회원은 PW변경 팝업 노출
B47: 8 | C47: A-RT | D47: IT-MB-004-008 | E47: 로그인 | F47: FO | G47: 중 | H47: 아이디 저장 체크 확인 | I47: 1. 로그인 페이지 2. 아이디 저장 체크 후 로그아웃 뒤에 재 로그인 | K47: 재로그인시 저장되었던 아이디 자동입력
B48: 9 | C48: A-RT | D48: IT-MB-004-009 | E48: 로그인 | F48: FO | G48: 중 | H48: 자동로그아웃 | I48: 1. 로그인 페이지 2. 로그인 후 2시간 경과시 자동로그아웃 확인 | K48: 로그인 2시간 경과후 자동 로그아웃
B49: 10 | C49: A-RT | D49: IT-MB-004-010 | E49: 로그인 | F49: FO | G49: 중 | H49: 비밀번호 변경안내 팝업 확인 | I49: 1. BO > 조건날짜관리에 날짜 입력 2. 로그인 페이지 > 로그인완료 3. 비밀번호 변경 이력 N일 확인 | K49: 비밀번호 변경이력 N일이 BO 조건날짜관리에서 입력한대로 정확히 표시되는지 확인 - BO에서 90일로 체크시 90일 이후 로그인 회원은 비밀번호 변경 팝업 노출
B50: 11 | C50: A-RT | D50: IT-MB-004-011 | E50: 로그인 | F50: FO | G50: 중 | H50: 비밀번호 변경안내 팝업 확인 | I50: 1. BO > 조건날짜관리에 날짜 입력 2. 로그인 페이지 > 로그인완료 3. 다음에변경, 지금변경 버튼 선택 | K50: 다음에 변경 버튼 : 창닫힘 지금변경: 비밀번호 변경 페이지로 이동
B51: 12 | C51: A-RT | D51: IT-MB-004-012 | E51: 로그인 | F51: FO | G51: 상 | H51: SNS로그인 확인 | I51: 1. 로그인 페이지 2. 페이스북로그인, 네이버로그인, 카카오로그인 버튼 선택 | K51: 정상 로그인 후 로그인 이전 페이지 이동(예 : 장바구니페이지에서 로그인 완료후 장바구니페이지로 이동) - 멤버십회원, 온라인회원은 회원전환 페이지 팝업 노출
B52: 13 | C52: A-RT | D52: IT-MB-004-013 | E52: 로그인 | F52: FO | G52: 상 | H52: SNS로그인 계정연동 확인 | I52: 1. 로그인 페이지 2. 페이스북로그인, 네이버로그인, 카카오로그인 버튼 선택 | J52: 계정연동이 안된 페이스북, 네이버, 카카오 계정입력 | K52: SNS 계정연결 팝업창 노출
B53: 14 | C53: A-RT | D53: IT-MB-004-014 | E53: 로그인 | F53: FO | G53: 중 | H53: 기존아이디 SNS 계정연결 확인 | I53: 1. 로그인 페이지 2. 계정연결이 안된 페이스북로그인, 네이버로그인, 카카오로그인 3. 기존아이디 연결 버튼 선택 | K53: [확인] : 창닫힘 > 마이페이지 > 개인정보 > SNS연결설정 페이지로 이동 [취소] : 창닫힘 > 메인화면 이동
B54: 15 | C54: A-RT | D54: IT-MB-004-015 | E54: 로그인 | F54: FO | G54: 중 | H54: 신규가입 후 연결 SNS 계정연결 확인 | I54: 1. 로그인 페이지 2. 계정연결이 안된 페이스북로그인, 네이버로그인, 카카오로그인 3. 신규가입 후 연결 버튼 선택 | K54: 회원가입 게이트 페이지로 이동
B55: 16 | C55: A-RT | D55: IT-MB-004-016 | E55: 로그인 | F55: MO | G55: 상 | H55: 로그인 페이지 | I55: 1. 로그인 페이지 2. 각 버튼 링크 확인 - 회원로그인탭, 비회원 주문조회, 페이스북로그인, 네이버로그인, 카카오로그인, 아이디찾기, 비밀번호찾기, 회원가입, 비회원 주문 버튼 선택 | K55: 각 버튼의 링크가 정확하게 이동되는지 확인
B56: 17 | C56: A-RT | D56: IT-MB-004-017 | E56: 로그인 | F56: MO | G56: 상 | H56: 정상 로그인 | I56: 1. 로그인 페이지 2. 통합멤버십회원 로그인 확인 | J56: 통합멤버십회원 ID, PW 입력 | K56: 로그인 후 로그인 이전 페이지 이동(예 : 장바구니페이지에서 로그인 완료후 장바구니페이지로 이동)
B57: 18 | C57: A-RT | D57: IT-MB-004-018 | E57: 로그인 | F57: MO | G57: 상 | H57: 정상 로그인 | I57: 1. 로그인 페이지 2. 멤버십회원 로그인 확인 | J57: 통합멤버십회원 ID, PW 입력 | K57: 멤버십회원인 경우 회원전환 페이지 팝업 노출 - 로그인 후 로그인 이전 페이지 이동 확인
B58: 19 | C58: A-RT | D58: IT-MB-004-019 | E58: 로그인 | F58: MO | G58: 상 | H58: 정상 로그인 | I58: 1. 로그인 페이지 2. 온라인회원 로그인 확인 | J58: 온라인회원 ID, PW 입력 | K58: 온라인회원인 경우 회원전환 페이지 팝업 노출 - 로그인 후 로그인 이전 페이지 이동 확인
B59: 20 | C59: A-RT | D59: IT-MB-004-020 | E59: 로그인 | F59: MO | G59: 중 | H59: 탈퇴회원 로그인 | I59: 1. 로그인 페이지 2. 탈퇴회원 로그인 확인 - 회원 구분별 ID, PW 입력 후 탈퇴회원 안내 확인 | J59: 탈퇴후 14일 이내회원 ID, PW입력 | K59: 탈퇴회원안내 팝업 노출
B60: 21 | C60: A-RT | D60: IT-MB-004-021 | E60: 로그인 | F60: MO | G60: 중 | H60: 비밀번호 오류 | I60: 1. 로그인 페이지 2. PW 오류 로그인 확인 | J60: PW 입력 5회 오류 | K60: 5회 비밀번호 오류시 보안문자입력 팝업창 노출 - 보안문자 새로고침 확인 - 보안문자 정상 입력시 로그인페이지로 이동
B61: 22 | C61: A-RT | D61: IT-MB-004-022 | E61: 로그인 | F61: MO | G61: 중 | H61: 비밀번호 변경이력 확인 | I61: 1. 로그인 페이지 2. N일내 비밀번호 변경이력이 없는 회원의 로그인 확인 | J61: N일내 비밀번호 변경이력이 없는 회원의 ID, PW 입력 | K61: 로그인 완료 후 N일내 PW변경 이력이 없는 회원은 PW변경 팝업 노출
B62: 23 | C62: A-RT | D62: IT-MB-004-023 | E62: 로그인 | F62: MO | G62: 중 | H62: 아이디 저장 체크 확인 | I62: 1. 로그인 페이지 2. 아이디 저장 체크 후 로그아웃 뒤에 재 로그인 | K62: 재로그인시 저장되었던 아이디 자동입력
B63: 24 | C63: A-RT | D63: IT-MB-004-024 | E63: 로그인 | F63: MO | G63: 중 | H63: 자동로그아웃 | I63: 1. 로그인 페이지 2. 로그인 후 2시간 경과시 자동로그아웃 확인 | K63: 로그인 2시간 경과후 자동 로그아웃
B64: 25 | C64: A-RT | D64: IT-MB-004-025 | E64: 로그인 | F64: MO | G64: 중 | H64: 비밀번호 변경안내 팝업 확인 | I64: 1. BO > 조건날짜관리에 날짜 입력 2. 로그인 페이지 > 로그인완료 3. 비밀번호 변경 이력 N일 확인 | K64: 비밀번호 변경이력 N일이 BO 조건날짜관리에서 입력한대로 정확히 표시되는지 확인 - BO에서 90일로 체크시 90일 이후 로그인 회원은 비밀번호 변경 팝업 노출
B65: 26 | C65: A-RT | D65: IT-MB-004-026 | E65: 로그인 | F65: MO | G65: 중 | H65: 비밀번호 변경안내 팝업 확인 | I65: 1. BO > 조건날짜관리에 날짜 입력 2. 로그인 페이지 > 로그인완료 3. 다음에변경, 지금변경 버튼 선택 | K65: 다음에 변경 버튼 : 창닫힘 지금변경: 비밀번호 변경 페이지로 이동
B66: 27 | C66: A-RT | D66: IT-MB-004-027 | E66: 로그인 | F66: MO | G66: 상 | H66: SNS로그인 확인 | I66: 1. 로그인 페이지 2. 페이스북로그인, 네이버로그인, 카카오로그인 버튼 선택 | K66: 정상 로그인 후 로그인 이전 페이지 이동(예 : 장바구니페이지에서 로그인 완료후 장바구니페이지로 이동) - 멤버십회원, 온라인회원은 회원전환 페이지 팝업 노출
B67: 28 | C67: A-RT | D67: IT-MB-004-028 | E67: 로그인 | F67: MO | G67: 상 | H67: SNS로그인 계정연동 확인 | I67: 1. 로그인 페이지 2. 페이스북로그인, 네이버로그인, 카카오로그인 버튼 선택 | J67: 계정연동이 안된 페이스북, 네이버, 카카오 계정입력 | K67: SNS 계정연결 팝업창 노출
B68: 29 | C68: A-RT | D68: IT-MB-004-029 | E68: 로그인 | F68: MO | G68: 중 | H68: 기존아이디 SNS 계정연결 확인 | I68: 1. 로그인 페이지 2. 계정연결이 안된 페이스북로그인, 네이버로그인, 카카오로그인 3. 기존아이디 연결 버튼 선택 | K68: [확인] : 창닫힘 > 마이페이지 > 개인정보 > SNS연결설정 페이지로 이동 [취소] : 창닫힘 > 메인화면 이동
B69: 30 | C69: A-RT | D69: IT-MB-004-030 | E69: 로그인 | F69: MO | G69: 중 | H69: 신규가입 후 연결 SNS 계정연결 확인 | I69: 1. 로그인 페이지 2. 계정연결이 안된 페이스북로그인, 네이버로그인, 카카오로그인 3. 신규가입 후 연결 버튼 선택 | K69: 회원가입 게이트 페이지로 이동
B70: 31 | C70: OTS | D70: IT-MB-004-031 | E70: 로그인 | F70: FO | G70: 상 | H70: 로그인 페이지 | I70: 1. 로그인 페이지 2. 각 버튼 링크 확인 - 회원로그인탭, 비회원 주문조회, 페이스북로그인, 네이버로그인, 카카오로그인, 아이디찾기, 비밀번호찾기, 회원가입, 비회원 주문 버튼 선택 | K70: 각 버튼의 링크가 정확하게 이동되는지 확인
B71: 32 | C71: OTS | D71: IT-MB-004-032 | E71: 로그인 | F71: FO | G71: 상 | H71: 정상 로그인 | I71: 1. 로그인 페이지 2. 통합멤버십회원 로그인 확인 | J71: 통합멤버십회원 ID, PW 입력 | K71: 로그인 후 로그인 이전 페이지 이동(예 : 장바구니페이지에서 로그인 완료후 장바구니페이지로 이동)
B72: 33 | C72: OTS | D72: IT-MB-004-033 | E72: 로그인 | F72: FO | G72: 상 | H72: 정상 로그인 | I72: 1. 로그인 페이지 2. 멤버십회원 로그인 확인 | J72: 통합멤버십회원 ID, PW 입력 | K72: 멤버십회원인 경우 회원전환 페이지 팝업 노출 - 로그인 후 로그인 이전 페이지 이동 확인
...

Sheet 4_ID 찾기
B2: 참조 문서 | C2: ABC_04.설계_03.프로세스정의서_01.회원_20190425_v1.10.pptx ABC_04.설계_02.화면설계서_FO_02.회원_20190502_v1.10.pptx ABC_04.설계_02.화면설계서_MO_02.회원_20190502_v1.02.pptx ABC_04.설계_02.화면설계서_BO_01_회원_20190429_v2.02.pptx
B4: 프로세스
B34: 시나리오 순서
B35: 1. ID 찾기 (IT-MB-005) - 이메일 주소로 찾기 : 1 > 2 > 3 > 4 > 5 - 휴대폰 번호로 찾기 : 6 > 7 > 8 > 9 > 10
B36: 테스트 사전 준비사항
B37: 통합멤버십회원, 온라인회원 계정별 휴대폰번호, 이메일이 정상적으로 등록된 계정
B39: No. | C39: 사이트 | D39: ID | E39: 시나리오명 | F39: SYS | G39: 중요도 | H39: 테스트 항목 | I39: 수행 절차 | J39: 입력값 | K39: 기대 결과 | L39: 수행일자 | M39: 수행자 | N39: 테스트결과 | O39: 결함사항 | P39: 수정여부 | Q39: 비고
B40: 1 | C40: A-RT | D40: IT-MB-005-001 | E40: ID 찾기 | F40: FO | G40: 상 | H40: ID 찾기 페이지 | I40: 1. ID 찾기 페이지 2. 휴대폰 번호로 찾기, 이메일 주소로 찾기, 회원가입 버튼 선택 | K40: 각 버튼의 링크가 정확하게 이동되는지 확인
B41: 2 | C41: A-RT | D41: IT-MB-005-002 | E41: ID 찾기 | F41: FO | G41: 상 | H41: 이메일 주소로 찾기 | I41: 1. ID 찾기 > 이메일 주소로 찾기 2. 이름, 이메일주소 입력 후 인증번호 요청 선택 | J41: 이름, 이메일주소 입력 | K41: 이름, 이메일을 정상적으로 입력시 등록된 이메일 주소로 인증번호가 발송되는지 확인
B42: 3 | C42: A-RT | D42: IT-MB-005-003 | E42: ID 찾기 | F42: FO | G42: 상 | H42: 이메일 주소로 찾기 | I42: 1. ID 찾기 > 이메일 주소로 찾기 2. 일치하지 않는 이름, 이메일주소 입력 후 인증번호 요청 선택 | J42: 이름, 이메일주소 입력 | K42: 이름, 이메일을 비정상적으로 입력시 실패페이지 팝업 노출
B43: 4 | C43: A-RT | D43: IT-MB-005-004 | E43: ID 찾기 | F43: FO | G43: 상 | H43: 이메일 주소로 찾기 | I43: 1. ID 찾기 > 이메일 주소로 찾기 2. 탈퇴후 14일 미만인 이름, 이메일주소 입력 후 인증번호 요청 선택 | J43: 이름, 이메일주소 입력 | K43: 탈퇴후 14일 미만인 이름, 이메일을 비정상적으로 입력시 실패페이지 팝업 노출(탈퇴 회원안내 페이지 삭제됨)
B44: 5 | C44: A-RT | D44: IT-MB-005-005 | E44: ID 찾기 | F44: FO | G44: 상 | H44: 이메일 주소로 찾기 인증번호 입력 | I44: 1. ID 찾기 페이지 > 이메일 주소로 찾기 > 인증번호 입력 2. 인증번호 입력 후 확인 버튼 선택 | J44: 인증번호 입력 | K44: 인증번호가 일치할 경우 성공페이지 팝업 노출 - 이름, 이메일이 일치하는 아이디가 노출 되는지 확인
B45: 6 | C45: A-RT | D45: IT-MB-005-006 | E45: ID 찾기 | F45: FO | G45: 상 | H45: 휴대폰 번호로 찾기 | I45: 1. ID 찾기 > 휴대폰 번호로 찾기 2. 이름, 휴대폰 번호 입력 후 인증번호 요청 선택 | J45: 이름, 휴대폰 번호 입력 | K45: 이름, 휴대폰 번호를 정상적으로 입력시 등록된 휴대폰 번호로 인증번호가 발송되는지 확인
B46: 7 | C46: A-RT | D46: IT-MB-005-007 | E46: ID 찾기 | F46: FO | G46: 상 | H46: 휴대폰 번호로 찾기 | I46: 1. ID 찾기 > 휴대폰 번호로 찾기 2. 일치하지 않는 이름, 휴대폰 번호 입력 후 인증번호 요청 선택 | J46: 이름, 휴대폰 번호 입력 | K46: 이름, 휴대폰 번호를 비정상적으로 입력시 실패페이지 팝업 노출
B47: 8 | C47: A-RT | D47: IT-MB-005-008 | E47: ID 찾기 | F47: FO | G47: 상 | H47: 휴대폰 번호로 찾기 | I47: 1. ID 찾기 > 휴대폰 번호로 찾기 2. 탈퇴후 14일 미만인 이름, 휴대폰 번호 입력 후 인증번호 요청 선택 | J47: 이름, 휴대폰 번호 입력 | K47: 탈퇴후 14일 미만인 이름, 휴대폰 번호를 비정상적으로 입력시 실패페이지 팝업 노출(탈퇴 회원안내 페이지 삭제됨)
B48: 9 | C48: A-RT | D48: IT-MB-005-009 | E48: ID 찾기 | F48: FO | G48: 상 | H48: 휴대폰 번호로 찾기 인증번호 입력 | I48: 1. ID 찾기 페이지 > 휴대폰 번호로 찾기 > 인증번호 입력 2. 인증번호 입력 후 확인 버튼 선택 | J48: 인증번호 입력 | K48: 인증번호가 일치할 경우 성공페이지 팝업 노출 - 이름, 휴대폰 번호가 일치하는 아이디가 노출 되는지 확인
B49: 10 | C49: A-RT | D49: IT-MB-005-010 | E49: ID 찾기 | F49: FO | G49: 하 | H49: ID 찾기 성공 | I49: 1. ID 찾기 페이지 > ID찾기 성공 2. 로그인, 비밀번호 찾기 버튼 선택 | K49: 각 페이지로 정상적으로 이동되는지 확인
B50: 11 | C50: A-RT | D50: IT-MB-005-011 | E50: ID 찾기 | F50: MO | G50: 상 | H50: ID 찾기 페이지 | I50: 1. ID 찾기 페이지 2. 휴대폰 번호로 찾기, 이메일 주소로 찾기, 회원가입 버튼 선택 | K50: 각 버튼의 링크가 정확하게 이동되는지 확인
B51: 12 | C51: A-RT | D51: IT-MB-005-012 | E51: ID 찾기 | F51: MO | G51: 상 | H51: 이메일 주소로 찾기 | I51: 1. ID 찾기 > 이메일 주소로 찾기 2. 이름, 이메일주소 입력 후 인증번호 요청 선택 | J51: 이름, 이메일주소 입력 | K51: 이름, 이메일을 정상적으로 입력시 등록된 이메일 주소로 인증번호가 발송되는지 확인
B52: 13 | C52: A-RT | D52: IT-MB-005-013 | E52: ID 찾기 | F52: MO | G52: 상 | H52: 이메일 주소로 찾기 | I52: 1. ID 찾기 > 이메일 주소로 찾기 2. 일치하지 않는 이름, 이메일주소 입력 후 인증번호 요청 선택 | J52: 이름, 이메일주소 입력 | K52: 이름, 이메일을 비정상적으로 입력시 실패페이지 팝업 노출
B53: 14 | C53: A-RT | D53: IT-MB-005-014 | E53: ID 찾기 | F53: MO | G53: 상 | H53: 이메일 주소로 찾기 | I53: 1. ID 찾기 > 이메일 주소로 찾기 2. 탈퇴후 14일 미만인 이름, 이메일주소 입력 후 인증번호 요청 선택 | J53: 이름, 이메일주소 입력 | K53: 탈퇴후 14일 미만인 이름, 이메일을 비정상적으로 입력시 실패페이지 팝업 노출(탈퇴 회원안내 페이지 삭제됨)
B54: 15 | C54: A-RT | D54: IT-MB-005-015 | E54: ID 찾기 | F54: MO | G54: 상 | H54: 이메일 주소로 찾기 인증번호 입력 | I54: 1. ID 찾기 페이지 > 이메일 주소로 찾기 > 인증번호 입력 2. 인증번호 입력 후 확인 버튼 선택 | J54: 인증번호 입력 | K54: 인증번호가 일치할 경우 성공페이지 팝업 노출 - 이름, 이메일이 일치하는 아이디가 노출 되는지 확인
B55: 16 | C55: A-RT | D55: IT-MB-005-016 | E55: ID 찾기 | F55: MO | G55: 상 | H55: 휴대폰 번호로 찾기 | I55: 1. ID 찾기 > 휴대폰 번호로 찾기 2. 이름, 휴대폰 번호 입력 후 인증번호 요청 선택 | J55: 이름, 휴대폰 번호 입력 | K55: 이름, 휴대폰 번호를 정상적으로 입력시 등록된 휴대폰 번호로 인증번호가 발송되는지 확인
B56: 17 | C56: A-RT | D56: IT-MB-005-017 | E56: ID 찾기 | F56: MO | G56: 상 | H56: 휴대폰 번호로 찾기 | I56: 1. ID 찾기 > 휴대폰 번호로 찾기 2. 일치하지 않는 이름, 휴대폰 번호 입력 후 인증번호 요청 선택 | J56: 이름, 휴대폰 번호 입력 | K56: 이름, 휴대폰 번호를 비정상적으로 입력시 실패페이지 팝업 노출
B57: 18 | C57: A-RT | D57: IT-MB-005-018 | E57: ID 찾기 | F57: MO | G57: 상 | H57: 휴대폰 번호로 찾기 | I57: 1. ID 찾기 > 휴대폰 번호로 찾기 2. 탈퇴후 14일 미만인 이름, 휴대폰 번호 입력 후 인증번호 요청 선택 | J57: 이름, 휴대폰 번호 입력 | K57: 탈퇴후 14일 미만인 이름, 휴대폰 번호를 비정상적으로 입력시 실패페이지 팝업 노출(탈퇴 회원안내 페이지 삭제됨)
B58: 19 | C58: A-RT | D58: IT-MB-005-019 | E58: ID 찾기 | F58: MO | G58: 상 | H58: 휴대폰 번호로 찾기 인증번호 입력 | I58: 1. ID 찾기 페이지 > 휴대폰 번호로 찾기 > 인증번호 입력 2. 인증번호 입력 후 확인 버튼 선택 | J58: 인증번호 입력 | K58: 인증번호가 일치할 경우 성공페이지 팝업 노출 - 이름, 휴대폰 번호가 일치하는 아이디가 노출 되는지 확인
B59: 20 | C59: A-RT | D59: IT-MB-005-020 | E59: ID 찾기 | F59: MO | G59: 하 | H59: ID 찾기 성공 | I59: 1. ID 찾기 페이지 > ID찾기 성공 2. 로그인, 비밀번호 찾기 버튼 선택 | K59: 각 페이지로 정상적으로 이동되는지 확인
B60: 21 | C60: OTS | D60: IT-MB-005-021 | E60: ID 찾기 | F60: FO | G60: 상 | H60: ID 찾기 페이지 | I60: 1. ID 찾기 페이지 2. 휴대폰 번호로 찾기, 이메일 주소로 찾기, 회원가입 버튼 선택 | K60: 각 버튼의 링크가 정확하게 이동되는지 확인
B61: 22 | C61: OTS | D61: IT-MB-005-022 | E61: ID 찾기 | F61: FO | G61: 상 | H61: 이메일 주소로 찾기 | I61: 1. ID 찾기 > 이메일 주소로 찾기 2. 이름, 이메일주소 입력 후 인증번호 요청 선택 | J61: 이름, 이메일주소 입력 | K61: 이름, 이메일을 정상적으로 입력시 등록된 이메일 주소로 인증번호가 발송되는지 확인
B62: 23 | C62: OTS | D62: IT-MB-005-023 | E62: ID 찾기 | F62: FO | G62: 상 | H62: 이메일 주소로 찾기 | I62: 1. ID 찾기 > 이메일 주소로 찾기 2. 일치하지 않는 이름, 이메일주소 입력 후 인증번호 요청 선택 | J62: 이름, 이메일주소 입력 | K62: 이름, 이메일을 비정상적으로 입력시 실패페이지 팝업 노출
B63: 24 | C63: OTS | D63: IT-MB-005-024 | E63: ID 찾기 | F63: FO | G63: 상 | H63: 이메일 주소로 찾기 | I63: 1. ID 찾기 > 이메일 주소로 찾기 2. 탈퇴후 14일 미만인 이름, 이메일주소 입력 후 인증번호 요청 선택 | J63: 이름, 이메일주소 입력 | K63: 탈퇴후 14일 미만인 이름, 이메일을 비정상적으로 입력시 실패페이지 팝업 노출(탈퇴 회원안내 페이지 삭제됨)
B64: 25 | C64: OTS | D64: IT-MB-005-025 | E64: ID 찾기 | F64: FO | G64: 상 | H64: 이메일 주소로 찾기 인증번호 입력 | I64: 1. ID 찾기 페이지 > 이메일 주소로 찾기 > 인증번호 입력 2. 인증번호 입력 후 확인 버튼 선택 | J64: 인증번호 입력 | K64: 인증번호가 일치할 경우 성공페이지 팝업 노출 - 이름, 이메일이 일치하는 아이디가 노출 되는지 확인
B65: 26 | C65: OTS | D65: IT-MB-005-026 | E65: ID 찾기 | F65: FO | G65: 상 | H65: 휴대폰 번호로 찾기 | I65: 1. ID 찾기 > 휴대폰 번호로 찾기 2. 이름, 휴대폰 번호 입력 후 인증번호 요청 선택 | J65: 이름, 휴대폰 번호 입력 | K65: 이름, 휴대폰 번호를 정상적으로 입력시 등록된 휴대폰 번호로 인증번호가 발송되는지 확인
B66: 27 | C66: OTS | D66: IT-MB-005-027 | E66: ID 찾기 | F66: FO | G66: 상 | H66: 휴대폰 번호로 찾기 | I66: 1. ID 찾기 > 휴대폰 번호로 찾기 2. 일치하지 않는 이름, 휴대폰 번호 입력 후 인증번호 요청 선택 | J66: 이름, 휴대폰 번호 입력 | K66: 이름, 휴대폰 번호를 비정상적으로 입력시 실패페이지 팝업 노출
B67: 28 | C67: OTS | D67: IT-MB-005-028 | E67: ID 찾기 | F67: FO | G67: 상 | H67: 휴대폰 번호로 찾기 | I67: 1. ID 찾기 > 휴대폰 번호로 찾기 2. 탈퇴후 14일 미만인 이름, 휴대폰 번호 입력 후 인증번호 요청 선택 | J67: 이름, 휴대폰 번호 입력 | K67: 탈퇴후 14일 미만인 이름, 휴대폰 번호를 비정상적으로 입력시 실패페이지 팝업 노출(탈퇴 회원안내 페이지 삭제됨)
B68: 29 | C68: OTS | D68: IT-MB-005-029 | E68: ID 찾기 | F68: FO | G68: 상 | H68: 휴대폰 번호로 찾기 인증번호 입력 | I68: 1. ID 찾기 페이지 > 휴대폰 번호로 찾기 > 인증번호 입력 2. 인증번호 입력 후 확인 버튼 선택 | J68: 인증번호 입력 | K68: 인증번호가 일치할 경우 성공페이지 팝업 노출 - 이름, 휴대폰 번호가 일치하는 아이디가 노출 되는지 확인
B69: 30 | C69: OTS | D69: IT-MB-005-030 | E69: ID 찾기 | F69: FO | G69: 하 | H69: ID 찾기 성공 | I69: 1. ID 찾기 페이지 > ID찾기 성공 2. 로그인, 비밀번호 찾기 버튼 선택 | K69: 각 페이지로 정상적으로 이동되는지 확인
B70: 31 | C70: OTS | D70: IT-MB-005-031 | E70: ID 찾기 | F70: MO | G70: 상 | H70: ID 찾기 페이지 | I70: 1. ID 찾기 페이지 2. 휴대폰 번호로 찾기, 이메일 주소로 찾기, 회원가입 버튼 선택 | K70: 각 버튼의 링크가 정확하게 이동되는지 확인
B71: 32 | C71: OTS | D71: IT-MB-005-032 | E71: ID 찾기 | F71: MO | G71: 상 | H71: 이메일 주소로 찾기 | I71: 1. ID 찾기 > 이메일 주소로 찾기 2. 이름, 이메일주소 입력 후 인증번호 요청 선택 | J71: 이름, 이메일주소 입력 | K71: 이름, 이메일을 정상적으로 입력시 등록된 이메일 주소로 인증번호가 발송되는지 확인
B72: 33 | C72: OTS | D72: IT-MB-005-033 | E72: ID 찾기 | F72: MO | G72: 상 | H72: 이메일 주소로 찾기 | I72: 1. ID 찾기 > 이메일 주소로 찾기 2. 일치하지 않는 이름, 이메일주소 입력 후 인증번호 요청 선택 | J72: 이름, 이메일주소 입력 | K72: 이름, 이메일을 비정상적으로 입력시 실패페이지 팝업 노출
...

Sheet 5_PW 찾기
B2: 참조 문서 | C2: ABC_04.설계_03.프로세스정의서_01.회원_20190425_v1.10.pptx ABC_04.설계_02.화면설계서_FO_02.회원_20190502_v1.10.pptx ABC_04.설계_02.화면설계서_MO_02.회원_20190502_v1.02.pptx ABC_04.설계_02.화면설계서_BO_01_회원_20190429_v2.02.pptx
B4: 프로세스
B34: 시나리오 순서
B35: 1. PW 찾기(IT-MB-006) - 이메일 주소로 찾기 : 1 > 2 > 3 > 4 > 5 > 6 - 휴대폰 번호로 찾기 : 7 > 8 > 9 > 10 > 11 > 12 - 본인 인증으로 찾기 : 13 > 14 > 15 > 16
B36: 테스트 사전 준비사항
B37: 통합멤버십회원, 온라인회원 계정별 휴대폰번호, 이메일이 정상적으로 등록된 계정
B39: No. | C39: 사이트 | D39: ID | E39: 시나리오명 | F39: SYS | G39: 중요도 | H39: 테스트 항목 | I39: 수행 절차 | J39: 입력값 | K39: 기대 결과 | L39: 수행일자 | M39: 수행자 | N39: 테스트결과 | O39: 결함사항 | P39: 수정여부 | Q39: 비고
B40: 1 | C40: A-RT | D40: IT-MB-006-001 | E40: PW 찾기 | F40: FO | G40: 상 | H40: 비밀번호 찾기 페이지 | I40: 1. PW 찾기 페이지 2. 휴대폰 번호로 찾기, 이메일 주소로 찾기, 본인인증으로 찾기, 아이디 찾기, 회원가입 버튼 선택 | K40: 각 버튼의 링크가 정확하게 이동되는지 확인
B41: 2 | C41: A-RT | D41: IT-MB-006-002 | E41: PW 찾기 | F41: FO | G41: 상 | H41: 휴대폰 번호로 찾기 | I41: 1. PW 찾기 > 휴대폰 번호로 찾기 2. 아이디, 이름, 휴대폰 번호 입력 후 인증번호 요청 선택 | K41: 아이디, 이름, 휴대폰 번호를 정상적으로 입력시 등록된 휴대폰 번호로 인증번호가 발송되는지 확인
B42: 3 | C42: A-RT | D42: IT-MB-006-003 | E42: PW 찾기 | F42: FO | G42: 상 | H42: 휴대폰 번호로 찾기 | I42: 1. PW 찾기 > 휴대폰 번호로 찾기 2. 일치하지 않는 아이디, 이름, 휴대폰 번호 입력 후 인증번호 요청 선택 | J42: 이름, 휴대폰 번호 입력 | K42: 아이디, 이름, 휴대폰 번호를 비정상적으로 입력시 실패페이지 팝업 노출
B43: 4 | C43: A-RT | D43: IT-MB-006-004 | E43: PW 찾기 | F43: FO | G43: 상 | H43: 휴대폰 번호로 찾기 | I43: 1. PW 찾기 > 휴대폰 번호로 찾기 2. 탈퇴후 14일 미만인 아이디, 이름, 휴대폰 번호 입력 후 인증번호 요청 선택 | J43: 이름, 휴대폰 번호 입력 | K43: 탈퇴후 14일 미만인 아이디, 이름, 휴대폰 번호를 비정상적으로 입력시 실패페이지 팝업 노출(탈퇴 회원안내 페이지 삭제됨)
B44: 5 | C44: A-RT | D44: IT-MB-006-005 | E44: PW 찾기 | F44: FO | G44: 상 | H44: 휴대폰 번호로 찾기 인증번호 입력 | I44: 1. PW 찾기 > 휴대폰 번호로 찾기 > 인증번호 입력 2. 인증번호 입력 후 확인 버튼 선택 | J44: 인증번호 입력 | K44: 인증번호가 일치할 경우 새비밀번호 입력 페이지가 노출 되는지 확인
B45: 6 | C45: A-RT | D45: IT-MB-006-006 | E45: PW 찾기 | F45: FO | G45: 상 | H45: 이메일 주소로 찾기 | I45: 1. PW 찾기 > 이메일 주소로 찾기 2. 아이디, 이름, 이메일주소 입력 후 인증번호 요청 선택 | J45: 아이디, 이름, 이메일주소 입력 | K45: 아이디, 이름, 이메일을 정상적으로 입력시 등록된 이메일 주소로 인증번호가 발송되는지 확인
B46: 7 | C46: A-RT | D46: IT-MB-006-007 | E46: PW 찾기 | F46: FO | G46: 상 | H46: 이메일 주소로 찾기 | I46: 1. PW 찾기 > 이메일 주소로 찾기 2. 일치하지 않는 아이디, 이름, 이메일주소 입력 후 인증번호 요청 선택 | J46: 아이디, 이름, 이메일주소 입력 | K46: 아이디, 이름, 이메일을 비정상적으로 입력시 실패페이지 팝업 노출(SB 없음)
B47: 8 | C47: A-RT | D47: IT-MB-006-008 | E47: PW 찾기 | F47: FO | G47: 상 | H47: 이메일 주소로 찾기 | I47: 1. PW 찾기 > 이메일 주소로 찾기 2. 탈퇴후 14일 미만인 아이디, 이름, 이메일주소 입력 후 인증번호 요청 선택 | J47: 아이디, 이름, 이메일주소 입력 | K47: 탈퇴후 14일 미만인 아이디, 이름, 이메일을 비정상적으로 입력시 실패페이지 팝업 노출(탈퇴 회원안내 페이지 삭제됨)(SB 없음)
B48: 9 | C48: A-RT | D48: IT-MB-006-009 | E48: PW 찾기 | F48: FO | G48: 상 | H48: 이메일 주소로 찾기 인증번호 입력 | I48: 1. PW 찾기 > 이메일 주소로 찾기 > 인증번호 입력 2. 인증번호 입력 후 확인 버튼 선택 | J48: 인증번호 입력 | K48: 인증번호가 일치할 경우 새비밀번호 입력 페이지가 노출 되는지 확인
B49: 10 | C49: A-RT | D49: IT-MB-006-010 | E49: PW 찾기 | F49: FO | G49: 상 | H49: 본인인증으로 찾기 | I49: 1. PW 찾기 > 본인인증으로 찾기 2. 아이디입력 후 휴대폰 인증 선택 | J49: 아이디입력 | K49: 본인인증 성공시 새비밀번호 입력 페이지가 노출 되는지 확인 - 본인인증 실패시 실패얼럿 노출
B50: 11 | C50: A-RT | D50: IT-MB-006-011 | E50: PW 찾기 | F50: FO | G50: 상 | H50: 본인인증으로 찾기 | I50: 1. PW 찾기 > 본인인증으로 찾기 2. 아이디입력 후 아이핀(I-PIN)본인인증 선택 | J50: 아이디입력 | K50: 본인인증 성공시 새비밀번호 입력 페이지가 노출 되는지 확인 - 본인인증 실패시 실패얼럿 노출
B51: 12 | C51: A-RT | D51: IT-MB-006-012 | E51: PW 찾기 | F51: FO | G51: 상 | H51: 비밀번호 찾기 성공 | I51: 1. PW 찾기 > PW 찾기 성공 2. 새비밀번호, 새비밀번호 확인 입력 후 확인 버튼 선택 | K51: 새로운 비밀번호로 로그인 확인
B52: 13 | C52: A-RT | D52: IT-MB-006-013 | E52: PW 찾기 | F52: MO | G52: 상 | H52: 비밀번호 찾기 페이지 | I52: 1. PW 찾기 페이지 2. 휴대폰 번호로 찾기, 이메일 주소로 찾기, 본인인증으로 찾기, 아이디 찾기, 회원가입 버튼 선택 | K52: 각 버튼의 링크가 정확하게 이동되는지 확인
